File: Acadmics/4 semester/DESIGN LAB/UTM csv/M G tensile.csv
Force (N)	Position (mm)	Stress (MPa)	Strain (%)	Time (min)
0.00	0.00	0.00	0.00	0.00284
21.0	0.00300	2.05	0.0150	0.0107
54.2	0.00700	5.27	0.0350	0.0186
84.5	0.0110	8.22	0.0550	0.0264
114	0.0150	11.0	0.0750	0.0343
143	0.0190	13.9	0.0950	0.0421
170	0.0230	16.5	0.115	0.0500
197	0.0270	19.1	0.135	0.0578
224	0.0310	21.8	0.155	0.0657
249	0.0350	24.2	0.175	0.0736
272	0.0390	26.4	0.195	0.0814
288	0.0430	28.0	0.215	0.0893
301	0.0470	29.3	0.235	0.0971
309	0.0510	30.1	0.255	0.105
312	0.0540	30.4	0.270	0.113
313	0.0580	30.5	0.290	0.121
313	0.0621	30.4	0.311	0.129
310	0.0660	30.2	0.330	0.136
309	0.0700	30.0	0.350	0.144
306	0.0740	29.7	0.370	0.152
305	0.0780	29.7	0.390	0.160
304	0.0820	29.6	0.410	0.168
302	0.0860	29.3	0.430	0.176
302	0.0900	29.3	0.450	0.184
300	0.0940	29.2	0.470	0.191
299	0.0980	29.1	0.490	0.199
299	0.102	29.0	0.510	0.207
298	0.105	28.9	0.525	0.215
297	0.109	28.9	0.545	0.223
297	0.113	28.9	0.565	0.231
295	0.117	28.7	0.585	0.239
295	0.121	28.7	0.605	0.246
293	0.125	28.5	0.625	0.254
293	0.129	28.5	0.645	0.262
292	0.133	28.4	0.665	0.270
290	0.137	28.2	0.685	0.278
290	0.141	28.2	0.705	0.286
288	0.145	28.0	0.725	0.294
287	0.149	27.9	0.745	0.301
287	0.153	27.9	0.765	0.309
285	0.157	27.7	0.785	0.317
285	0.161	27.7	0.804	0.325
284	0.164	27.6	0.820	0.333
282	0.168	27.4	0.840	0.341
281	0.172	27.3	0.860	0.349
279	0.176	27.2	0.880	0.356
278	0.180	27.1	0.900	0.364
278	0.184	27.1	0.920	0.372
277	0.188	26.9	0.940	0.380
276	0.192	26.8	0.960	0.388
275	0.196	26.7	0.980	0.396
273	0.200	26.6	1.00	0.404
272	0.204	26.4	1.02	0.411
270	0.208	26.3	1.04	0.419
269	0.212	26.2	1.06	0.427
268	0.216	26.1	1.08	0.435
266	0.219	25.9	1.10	0.443
266	0.223	25.9	1.12	0.451
264	0.227	25.7	1.14	0.459
263	0.231	25.6	1.16	0.467
263	0.235	25.5	1.18	0.474
262	0.239	25.5	1.20	0.482
262	0.243	25.5	1.22	0.490
260	0.247	25.3	1.24	0.498
260	0.251	25.3	1.26	0.506
261	0.255	25.4	1.28	0.514
259	0.259	25.2	1.30	0.522
259	0.263	25.2	1.32	0.529
258	0.267	25.1	1.34	0.537
258	0.271	25.0	1.36	0.545
258	0.274	25.0	1.37	0.553
256	0.278	24.9	1.39	0.561
254	0.282	24.7	1.41	0.569
253	0.286	24.6	1.43	0.577
253	0.290	24.6	1.45	0.584
253	0.294	24.6	1.47	0.592
251	0.298	24.4	1.49	0.600
250	0.302	24.3	1.51	0.608
249	0.306	24.2	1.53	0.616
248	0.310	24.1	1.55	0.624
248	0.314	24.1	1.57	0.632
247	0.318	24.0	1.59	0.639
245	0.322	23.8	1.61	0.647
245	0.326	23.8	1.63	0.655
243	0.330	23.6	1.65	0.663
243	0.333	23.6	1.67	0.671
242	0.337	23.5	1.69	0.679
241	0.341	23.4	1.71	0.687
241	0.345	23.4	1.73	0.694
240	0.349	23.3	1.75	0.702
240	0.353	23.3	1.77	0.710
241	0.357	23.4	1.79	0.718
242	0.361	23.5	1.81	0.726
243	0.365	23.7	1.83	0.734
244	0.369	23.7	1.85	0.742
245	0.373	23.8	1.87	0.749
249	0.377	24.2	1.89	0.757
254	0.381	24.7	1.90	0.765
263	0.385	25.5	1.92	0.773
272	0.389	26.5	1.94	0.781
282	0.392	27.4	1.96	0.789
293	0.396	28.5	1.98	0.797
301	0.400	29.3	2.00	0.804
310	0.404	30.1	2.02	0.812
318	0.408	31.0	2.04	0.820
325	0.412	31.6	2.06	0.828
334	0.416	32.5	2.08	0.836
342	0.420	33.3	2.10	0.844
351	0.424	34.1	2.12	0.852
361	0.428	35.1	2.14	0.859
369	0.431	35.9	2.16	0.867
380	0.436	36.9	2.18	0.875
390	0.440	37.9	2.20	0.883
398	0.443	38.8	2.22	0.891
409	0.447	39.8	2.24	0.899
418	0.451	40.7	2.26	0.907
428	0.455	41.6	2.28	0.914
436	0.459	42.4	2.30	0.922
443	0.463	43.1	2.32	0.930
452	0.467	44.0	2.34	0.938
461	0.471	44.8	2.36	0.946
468	0.475	45.6	2.38	0.954
477	0.479	46.4	2.40	0.962
484	0.483	47.1	2.42	0.969
493	0.487	47.9	2.44	0.977
501	0.491	48.7	2.46	0.985
383	0.494	37.2	2.47	0.993
354	0.498	34.4	2.49	1.00
378	0.502	36.8	2.51	1.01
402	0.506	39.1	2.53	1.02
408	0.510	39.6	2.55	1.02
418	0.514	40.6	2.57	1.03
429	0.518	41.7	2.59	1.04
433	0.522	42.1	2.61	1.05
437	0.526	42.5	2.63	1.06
444	0.530	43.2	2.65	1.06
449	0.534	43.7	2.67	1.07
455	0.538	44.3	2.69	1.08
460	0.542	44.7	2.71	1.09
463	0.546	45.0	2.73	1.10
468	0.550	45.6	2.75	1.10
471	0.553	45.8	2.77	1.11
474	0.557	46.1	2.79	1.12
477	0.561	46.4	2.81	1.13
481	0.565	46.8	2.82	1.13
484	0.569	47.1	2.85	1.14
486	0.573	47.3	2.87	1.15
489	0.577	47.6	2.89	1.16
493	0.581	48.0	2.91	1.17
497	0.585	48.3	2.93	1.17
501	0.589	48.7	2.95	1.18
503	0.593	48.9	2.97	1.19
505	0.597	49.1	2.98	1.20
509	0.601	49.5	3.01	1.21
512	0.604	49.8	3.02	1.21
514	0.608	50.0	3.04	1.22
518	0.613	50.3	3.06	1.23
520	0.616	50.6	3.08	1.24
523	0.620	50.9	3.10	1.24
525	0.624	51.0	3.12	1.25
527	0.628	51.2	3.14	1.26
530	0.632	51.6	3.16	1.27
533	0.636	51.8	3.18	1.28
537	0.640	52.2	3.20	1.28
539	0.644	52.4	3.22	1.29
540	0.648	52.5	3.24	1.30
543	0.652	52.8	3.26	1.31
547	0.656	53.2	3.28	1.32
551	0.660	53.6	3.30	1.32
553	0.664	53.8	3.32	1.33
555	0.667	54.0	3.34	1.34
558	0.671	54.3	3.36	1.35
559	0.675	54.4	3.38	1.35
561	0.679	54.6	3.40	1.36
564	0.683	54.9	3.42	1.37
565	0.687	55.0	3.44	1.38
569	0.691	55.4	3.46	1.39
570	0.695	55.4	3.48	1.39
572	0.699	55.6	3.50	1.40
577	0.703	56.1	3.52	1.41
579	0.707	56.3	3.54	1.42
582	0.711	56.6	3.56	1.43
583	0.715	56.7	3.58	1.43
586	0.718	57.0	3.59	1.44
590	0.722	57.4	3.61	1.45
593	0.726	57.6	3.63	1.46
597	0.730	58.0	3.65	1.46
599	0.734	58.3	3.67	1.47
601	0.738	58.4	3.69	1.48
605	0.742	58.8	3.71	1.49
608	0.746	59.1	3.73	1.50
611	0.750	59.4	3.75	1.50
615	0.754	59.8	3.77	1.51
618	0.758	60.1	3.79	1.52
622	0.762	60.5	3.81	1.53
625	0.766	60.8	3.83	1.54
628	0.770	61.1	3.85	1.54
633	0.774	61.6	3.87	1.55
636	0.777	61.8	3.89	1.56
641	0.781	62.3	3.91	1.57
645	0.785	62.7	3.93	1.57
650	0.789	63.2	3.95	1.58
658	0.793	64.0	3.97	1.59
663	0.797	64.5	3.99	1.60
670	0.801	65.1	4.01	1.61
677	0.805	65.8	4.03	1.61
682	0.809	66.3	4.05	1.62
688	0.813	67.0	4.07	1.63
693	0.817	67.4	4.09	1.64
698	0.821	67.9	4.11	1.65
705	0.825	68.6	4.13	1.65
709	0.828	69.0	4.14	1.66
715	0.833	69.5	4.16	1.67
720	0.836	70.0	4.18	1.68
724	0.840	70.4	4.20	1.68
731	0.844	71.1	4.22	1.69
735	0.848	71.5	4.24	1.70
741	0.852	72.1	4.26	1.71
746	0.856	72.5	4.28	1.72
750	0.860	72.9	4.30	1.72
756	0.864	73.5	4.32	1.73
760	0.868	73.9	4.34	1.74
764	0.872	74.3	4.36	1.75
769	0.876	74.8	4.38	1.76
773	0.880	75.2	4.40	1.76
778	0.884	75.7	4.42	1.77
783	0.887	76.2	4.44	1.78
788	0.891	76.6	4.46	1.79
793	0.895	77.2	4.48	1.79
798	0.899	77.6	4.50	1.80
803	0.903	78.1	4.52	1.81
809	0.907	78.7	4.54	1.82
813	0.911	79.1	4.56	1.83
820	0.915	79.8	4.58	1.83
824	0.919	80.2	4.60	1.84
829	0.923	80.7	4.62	1.85
835	0.927	81.2	4.64	1.86
839	0.931	81.6	4.66	1.87
844	0.935	82.1	4.68	1.87
849	0.939	82.6	4.69	1.88
853	0.942	83.0	4.71	1.89
858	0.946	83.5	4.73	1.90
862	0.950	83.8	4.75	1.90
867	0.954	84.3	4.77	1.91
871	0.958	84.7	4.79	1.92
875	0.962	85.1	4.81	1.93
880	0.966	85.6	4.83	1.94
884	0.970	86.0	4.85	1.94
890	0.974	86.6	4.87	1.95
894	0.978	87.0	4.89	1.96
898	0.982	87.3	4.91	1.97
903	0.986	87.8	4.93	1.98
906	0.990	88.1	4.95	1.98
909	0.993	88.5	4.97	1.99
913	0.998	88.8	4.99	2.00
918	1.00	89.2	5.01	2.01
922	1.00	89.6	5.02	2.01
926	1.01	90.1	5.05	2.02
930	1.01	90.5	5.07	2.03
934	1.02	90.9	5.09	2.04
937	1.02	91.1	5.11	2.05
941	1.03	91.5	5.13	2.05
944	1.03	91.8	5.15	2.06
947	1.03	92.1	5.16	2.07
951	1.04	92.5	5.19	2.08
953	1.04	92.7	5.21	2.09
957	1.04	93.1	5.22	2.09
961	1.05	93.5	5.24	2.10
963	1.05	93.7	5.26	2.11
968	1.06	94.2	5.28	2.12
971	1.06	94.5	5.30	2.12
974	1.06	94.8	5.32	2.13
978	1.07	95.1	5.34	2.14
980	1.07	95.3	5.36	2.15
983	1.08	95.6	5.38	2.16
987	1.08	96.0	5.40	2.16
990	1.08	96.3	5.42	2.17
995	1.09	96.8	5.44	2.18
998	1.09	97.1	5.46	2.19
1000	1.10	97.4	5.48	2.20
1010	1.10	97.8	5.50	2.20
1010	1.10	98.2	5.52	2.21
1010	1.11	98.7	5.54	2.22
1020	1.11	99.1	5.56	2.23
1020	1.12	99.6	5.58	2.23
1030	1.12	100	5.60	2.24
1030	1.12	101	5.62	2.25
1040	1.13	101	5.64	2.26
1040	1.13	101	5.66	2.27
1050	1.14	102	5.68	2.27
1050	1.14	102	5.70	2.28
1060	1.14	103	5.72	2.29
1060	1.15	103	5.74	2.30
1070	1.15	104	5.76	2.31
1070	1.16	104	5.78	2.31
1070	1.16	104	5.80	2.32
1080	1.16	105	5.81	2.33
1080	1.17	105	5.83	2.34
1080	1.17	105	5.85	2.34
1090	1.17	106	5.87	2.35
1090	1.18	106	5.89	2.36
1100	1.18	107	5.91	2.37
1100	1.19	107	5.93	2.38
1110	1.19	108	5.95	2.38
1110	1.19	108	5.97	2.39
1120	1.20	108	5.99	2.40
1120	1.20	109	6.01	2.41
1120	1.21	109	6.03	2.42
1130	1.21	110	6.05	2.42
1130	1.21	110	6.07	2.43
1140	1.22	111	6.09	2.44
1140	1.22	111	6.11	2.45
1150	1.23	111	6.13	2.45
1150	1.23	112	6.15	2.46
1160	1.23	112	6.17	2.47
1160	1.24	113	6.19	2.48
1160	1.24	113	6.21	2.49
1170	1.25	113	6.23	2.49
1170	1.25	114	6.25	2.50
1170	1.25	114	6.27	2.51
1180	1.26	114	6.29	2.52
1180	1.26	115	6.31	2.53
1180	1.27	115	6.33	2.53
1190	1.27	116	6.34	2.54
1190	1.27	116	6.36	2.55
1200	1.28	116	6.38	2.56
1200	1.28	117	6.40	2.56
1200	1.28	117	6.42	2.57
1210	1.29	117	6.44	2.58
1210	1.29	118	6.46	2.59
1210	1.30	118	6.48	2.60
1220	1.30	118	6.50	2.60
1220	1.30	119	6.52	2.61
1220	1.31	119	6.54	2.62
1230	1.31	119	6.56	2.63
1230	1.32	120	6.58	2.64
1240	1.32	120	6.60	2.64
1240	1.32	121	6.62	2.65
1240	1.33	121	6.64	2.66
1250	1.33	121	6.66	2.67
1250	1.34	122	6.68	2.67
1250	1.34	122	6.70	2.68
1260	1.34	122	6.72	2.69
1260	1.35	122	6.74	2.70
1260	1.35	123	6.76	2.71
1270	1.36	123	6.78	2.71
1270	1.36	123	6.80	2.72
1270	1.36	124	6.82	2.73
1270	1.37	124	6.84	2.74
1280	1.37	124	6.86	2.75
1280	1.38	124	6.88	2.75
1280	1.38	125	6.90	2.76
1290	1.38	125	6.92	2.77
1290	1.39	125	6.93	2.78
1290	1.39	126	6.95	2.78
1290	1.39	126	6.97	2.79
1300	1.40	126	6.99	2.80
1300	1.40	126	7.01	2.81
1300	1.41	127	7.03	2.82
1310	1.41	127	7.05	2.82
1310	1.41	127	7.07	2.83
1310	1.42	127	7.09	2.84
1310	1.42	128	7.11	2.85
1320	1.43	128	7.13	2.86
1320	1.43	128	7.15	2.86
1320	1.43	128	7.17	2.87
1320	1.44	129	7.19	2.88
1320	1.44	129	7.21	2.89
1330	1.45	129	7.23	2.89
1330	1.45	129	7.25	2.90
1330	1.45	129	7.27	2.91
1330	1.46	129	7.29	2.92
1330	1.46	130	7.31	2.93
1340	1.47	130	7.33	2.93
1340	1.47	130	7.35	2.94
1340	1.47	130	7.37	2.95
1340	1.48	130	7.39	2.96
1340	1.48	130	7.41	2.97
1340	1.49	131	7.43	2.97
1340	1.49	131	7.45	2.98
1350	1.49	131	7.47	2.99
1350	1.50	131	7.48	3.00
1350	1.50	131	7.50	3.00
1350	1.50	131	7.52	3.01
1350	1.51	131	7.54	3.02
1350	1.51	131	7.56	3.03
1350	1.52	132	7.58	3.04
1350	1.52	132	7.60	3.04
1360	1.52	132	7.62	3.05
1360	1.53	132	7.64	3.06
1360	1.53	132	7.66	3.07
1360	1.54	132	7.68	3.08
1360	1.54	132	7.70	3.08
1360	1.54	132	7.72	3.09
1360	1.55	132	7.74	3.10
1360	1.55	132	7.76	3.11
1360	1.56	132	7.78	3.11
1360	1.56	132	7.80	3.12
1360	1.56	132	7.82	3.13
1360	1.57	132	7.84	3.14
1360	1.57	133	7.86	3.15
1360	1.58	133	7.88	3.15
1370	1.58	133	7.90	3.16
1370	1.58	133	7.92	3.17
1370	1.59	133	7.94	3.18
1370	1.59	133	7.96	3.19
1370	1.60	133	7.98	3.19
1370	1.60	134	8.00	3.20
1370	1.60	134	8.01	3.21
1380	1.61	134	8.04	3.22
1380	1.61	134	8.05	3.22
1380	1.61	134	8.07	3.23
1380	1.62	134	8.09	3.24
1380	1.62	134	8.11	3.25
1380	1.63	135	8.13	3.26
1380	1.63	135	8.15	3.26
1390	1.63	135	8.17	3.27
1390	1.64	135	8.19	3.28
1390	1.64	135	8.21	3.29
1390	1.65	136	8.23	3.30
1390	1.65	136	8.25	3.30
1400	1.65	136	8.27	3.31
1400	1.66	136	8.29	3.32
1400	1.66	136	8.31	3.33
1400	1.67	136	8.33	3.33
1400	1.67	137	8.35	3.34
1410	1.67	137	8.37	3.35
1410	1.68	137	8.39	3.36
1410	1.68	137	8.41	3.37
1410	1.69	137	8.43	3.37
1410	1.69	137	8.45	3.38
1420	1.69	138	8.47	3.39
1420	1.70	138	8.49	3.40
1420	1.70	138	8.51	3.41
1420	1.71	138	8.53	3.41
1420	1.71	138	8.55	3.42
1420	1.71	138	8.57	3.43
1430	1.72	139	8.59	3.44
1430	1.72	139	8.60	3.44
1430	1.72	139	8.62	3.45
1430	1.73	139	8.64	3.46
1430	1.73	139	8.66	3.47
1430	1.74	139	8.68	3.48
1440	1.74	140	8.70	3.48
1440	1.74	140	8.72	3.49
1440	1.75	140	8.74	3.50
1440	1.75	140	8.76	3.51
1440	1.76	140	8.78	3.52
1440	1.76	140	8.80	3.52
1450	1.76	141	8.82	3.53
1450	1.77	141	8.84	3.54
1450	1.77	141	8.86	3.55
1450	1.78	141	8.88	3.56
1450	1.78	141	8.90	3.56
1450	1.78	141	8.92	3.57
1460	1.79	142	8.94	3.58
1460	1.79	142	8.96	3.59
1460	1.80	142	8.98	3.59
1460	1.80	142	9.00	3.60
1460	1.80	142	9.02	3.61
1470	1.81	143	9.04	3.62
1470	1.81	143	9.06	3.63
1470	1.82	143	9.08	3.63
1470	1.82	143	9.10	3.64
1470	1.82	143	9.12	3.65
1480	1.83	143	9.14	3.66
1480	1.83	144	9.16	3.67
1480	1.83	144	9.17	3.67
1480	1.84	144	9.19	3.68
1480	1.84	144	9.21	3.69
1480	1.85	144	9.23	3.70
1490	1.85	144	9.25	3.70
1490	1.85	145	9.27	3.71
1490	1.86	145	9.29	3.72
1490	1.86	145	9.31	3.73
1490	1.87	145	9.33	3.74
1490	1.87	145	9.35	3.74
1490	1.87	145	9.37	3.75
1500	1.88	145	9.39	3.76
1500	1.88	146	9.41	3.77
1500	1.89	146	9.43	3.78
1500	1.89	146	9.45	3.78
1500	1.89	146	9.47	3.79
1510	1.90	146	9.49	3.80
1510	1.90	147	9.51	3.81
1510	1.91	147	9.53	3.81
1510	1.91	147	9.55	3.82
1510	1.91	147	9.57	3.83
1510	1.92	147	9.59	3.84
1520	1.92	147	9.61	3.85
1520	1.93	147	9.63	3.85
1520	1.93	148	9.65	3.86
1520	1.93	148	9.67	3.87
1520	1.94	148	9.69	3.88
1520	1.94	148	9.71	3.89
1520	1.94	148	9.72	3.89
1530	1.95	149	9.74	3.90
1530	1.95	149	9.76	3.91
1530	1.96	149	9.78	3.92
1530	1.96	149	9.80	3.92
1530	1.96	149	9.82	3.93
1540	1.97	149	9.84	3.94
1540	1.97	149	9.86	3.95
1540	1.98	150	9.88	3.96
1540	1.98	150	9.90	3.96
1540	1.98	150	9.92	3.97
1540	1.99	150	9.94	3.98
1550	1.99	150	9.96	3.99
1550	2.00	150	9.98	4.00
1550	2.00	151	10.0	4.00
1550	2.00	151	10.0	4.01
1550	2.01	151	10.0	4.02
1550	2.01	151	10.1	4.03
1560	2.02	151	10.1	4.03
1560	2.02	151	10.1	4.04
1560	2.02	152	10.1	4.05
1560	2.03	152	10.1	4.06
1560	2.03	152	10.2	4.07
1560	2.04	152	10.2	4.07
1570	2.04	152	10.2	4.08
1570	2.04	152	10.2	4.09
1570	2.05	153	10.2	4.10
1570	2.05	153	10.3	4.11
1570	2.06	153	10.3	4.11
1570	2.06	153	10.3	4.12
1580	2.06	153	10.3	4.13
1580	2.07	153	10.3	4.14
1580	2.07	154	10.4	4.14
1580	2.07	154	10.4	4.15
1580	2.08	154	10.4	4.16
1580	2.08	154	10.4	4.17
1590	2.09	154	10.4	4.18
1590	2.09	154	10.5	4.18
1590	2.09	154	10.5	4.19
1590	2.10	155	10.5	4.20
1590	2.10	155	10.5	4.21
1590	2.11	155	10.5	4.22
1600	2.11	155	10.5	4.22
1600	2.11	155	10.6	4.23
1600	2.12	155	10.6	4.24
1600	2.12	156	10.6	4.25
1600	2.13	156	10.6	4.25
1600	2.13	156	10.6	4.26
1600	2.13	156	10.7	4.27
1610	2.14	156	10.7	4.28
1610	2.14	156	10.7	4.29
1610	2.15	156	10.7	4.29
1610	2.15	157	10.7	4.30
1610	2.15	157	10.8	4.31
1610	2.16	157	10.8	4.32
1620	2.16	157	10.8	4.33
1620	2.17	157	10.8	4.33
1620	2.17	157	10.8	4.34
1620	2.17	158	10.9	4.35
1620	2.18	158	10.9	4.36
1620	2.18	158	10.9	4.36
1630	2.18	158	10.9	4.37
1630	2.19	158	10.9	4.38
1630	2.19	158	11.0	4.39
1630	2.20	159	11.0	4.40
1630	2.20	159	11.0	4.40
1630	2.20	159	11.0	4.41
1630	2.21	159	11.0	4.42
1640	2.21	159	11.1	4.43
1640	2.22	159	11.1	4.44
1640	2.22	159	11.1	4.44
1640	2.22	160	11.1	4.45
1640	2.23	160	11.1	4.46
1640	2.23	160	11.2	4.47
1650	2.24	160	11.2	4.47
1650	2.24	160	11.2	4.48
1650	2.24	160	11.2	4.49
1650	2.25	160	11.2	4.50
1650	2.25	161	11.3	4.51
1650	2.26	161	11.3	4.51
1650	2.26	161	11.3	4.52
1660	2.26	161	11.3	4.53
1660	2.27	161	11.3	4.54
1660	2.27	161	11.4	4.55
1660	2.28	162	11.4	4.55
1660	2.28	162	11.4	4.56
1660	2.28	162	11.4	4.57
1670	2.29	162	11.4	4.58
1670	2.29	162	11.5	4.58
1670	2.29	162	11.5	4.59
1670	2.30	162	11.5	4.60
1670	2.30	163	11.5	4.61
1670	2.31	163	11.5	4.62
1670	2.31	163	11.6	4.62
1680	2.31	163	11.6	4.63
1680	2.32	163	11.6	4.64
1680	2.32	163	11.6	4.65
1680	2.33	163	11.6	4.66
1680	2.33	164	11.6	4.66
1680	2.33	164	11.7	4.67
1690	2.34	164	11.7	4.68
1690	2.34	164	11.7	4.69
1690	2.35	164	11.7	4.69
1690	2.35	164	11.7	4.70
1690	2.35	164	11.8	4.71
1690	2.36	165	11.8	4.72
1690	2.36	165	11.8	4.73
1700	2.37	165	11.8	4.73
1700	2.37	165	11.8	4.74
1700	2.37	165	11.9	4.75
1700	2.38	165	11.9	4.76
1700	2.38	165	11.9	4.77
1700	2.39	166	11.9	4.77
1700	2.39	166	11.9	4.78
1710	2.39	166	12.0	4.79
1710	2.40	166	12.0	4.80
1710	2.40	166	12.0	4.80
1710	2.40	166	12.0	4.81
1710	2.41	167	12.0	4.82
1710	2.41	167	12.1	4.83
1720	2.42	167	12.1	4.84
1720	2.42	167	12.1	4.84
1720	2.42	167	12.1	4.85
1720	2.43	167	12.1	4.86
1720	2.43	167	12.2	4.87
1720	2.44	167	12.2	4.88
1720	2.44	168	12.2	4.88
1720	2.44	168	12.2	4.89
1730	2.45	168	12.2	4.90
1730	2.45	168	12.3	4.91
1730	2.46	168	12.3	4.91
1730	2.46	168	12.3	4.92
1730	2.46	168	12.3	4.93
1730	2.47	169	12.3	4.94
1740	2.47	169	12.4	4.95
1740	2.48	169	12.4	4.95
1740	2.48	169	12.4	4.96
1740	2.48	169	12.4	4.97
1740	2.49	169	12.4	4.98
1740	2.49	169	12.5	4.99
1740	2.49	170	12.5	4.99
1750	2.50	170	12.5	5.00
1750	2.50	170	12.5	5.01
1750	2.51	170	12.5	5.02
1750	2.51	170	12.6	5.02
1750	2.51	170	12.6	5.03
1750	2.52	170	12.6	5.04
1750	2.52	171	12.6	5.05
1760	2.53	171	12.6	5.06
1760	2.53	171	12.7	5.06
1760	2.53	171	12.7	5.07
1760	2.54	171	12.7	5.08
1760	2.54	171	12.7	5.09
1760	2.55	171	12.7	5.10
1760	2.55	172	12.8	5.10
1770	2.55	172	12.8	5.11
1770	2.56	172	12.8	5.12
1770	2.56	172	12.8	5.13
1770	2.57	172	12.8	5.13
1770	2.57	172	12.8	5.14
1770	2.57	172	12.9	5.15
1770	2.58	172	12.9	5.16
1780	2.58	173	12.9	5.17
1780	2.59	173	12.9	5.17
1780	2.59	173	12.9	5.18
1780	2.59	173	13.0	5.19
1780	2.60	173	13.0	5.20
1780	2.60	173	13.0	5.21
1780	2.61	173	13.0	5.21
1780	2.61	174	13.0	5.22
1790	2.61	174	13.1	5.23
1790	2.62	174	13.1	5.24
1790	2.62	174	13.1	5.24
1790	2.62	174	13.1	5.25
1790	2.63	174	13.1	5.26
1790	2.63	174	13.2	5.27
1790	2.64	174	13.2	5.28
1800	2.64	175	13.2	5.28
1800	2.64	175	13.2	5.29
1800	2.65	175	13.2	5.30
1800	2.65	175	13.3	5.31
1800	2.66	175	13.3	5.32
1800	2.66	175	13.3	5.32
1800	2.66	175	13.3	5.33
1800	2.67	175	13.3	5.34
1810	2.67	176	13.4	5.35
1810	2.68	176	13.4	5.35
1810	2.68	176	13.4	5.36
1810	2.68	176	13.4	5.37
1810	2.69	176	13.4	5.38
1810	2.69	176	13.5	5.39
1810	2.70	176	13.5	5.39
1810	2.70	176	13.5	5.40
1820	2.70	177	13.5	5.41
1820	2.71	177	13.5	5.42
1820	2.71	177	13.6	5.43
1820	2.72	177	13.6	5.43
1820	2.72	177	13.6	5.44
1820	2.72	177	13.6	5.45
1820	2.73	177	13.6	5.46
1830	2.73	178	13.7	5.46
1830	2.73	178	13.7	5.47
1830	2.74	178	13.7	5.48
1830	2.74	178	13.7	5.49
1830	2.75	178	13.7	5.50
1830	2.75	178	13.8	5.50
1830	2.75	178	13.8	5.51
1830	2.76	178	13.8	5.52
1840	2.76	178	13.8	5.53
1840	2.77	178	13.8	5.54
1840	2.77	179	13.9	5.54
1840	2.77	179	13.9	5.55
1840	2.78	179	13.9	5.56
1840	2.78	179	13.9	5.57
1840	2.79	179	13.9	5.57
1840	2.79	179	13.9	5.58
1850	2.79	179	14.0	5.59
1850	2.80	179	14.0	5.60
1850	2.80	180	14.0	5.61
1850	2.81	180	14.0	5.61
1850	2.81	180	14.0	5.62
1850	2.81	180	14.1	5.63
1850	2.82	180	14.1	5.64
1850	2.82	180	14.1	5.65
1860	2.83	180	14.1	5.65
1860	2.83	180	14.1	5.66
1860	2.83	181	14.2	5.67
1860	2.84	181	14.2	5.68
1860	2.84	181	14.2	5.68
1860	2.84	181	14.2	5.69
1860	2.85	181	14.2	5.70
1860	2.85	181	14.3	5.71
1860	2.86	181	14.3	5.72
1860	2.86	181	14.3	5.72
1870	2.86	182	14.3	5.73
1870	2.87	182	14.3	5.74
1870	2.87	182	14.4	5.75
1870	2.88	182	14.4	5.76
1870	2.88	182	14.4	5.76
1870	2.88	182	14.4	5.77
1870	2.89	182	14.4	5.78
1870	2.89	182	14.5	5.79
1880	2.90	182	14.5	5.79
1880	2.90	183	14.5	5.80
1880	2.90	183	14.5	5.81
1880	2.91	183	14.5	5.82
1880	2.91	183	14.6	5.83
1880	2.92	183	14.6	5.83
1880	2.92	183	14.6	5.84
1880	2.92	183	14.6	5.85
1890	2.93	183	14.6	5.86
1890	2.93	183	14.7	5.87
1890	2.94	184	14.7	5.87
1890	2.94	184	14.7	5.88
1890	2.94	184	14.7	5.89
1890	2.95	184	14.7	5.90
1890	2.95	184	14.8	5.90
1890	2.95	184	14.8	5.91
1890	2.96	184	14.8	5.92
1890	2.96	184	14.8	5.93
1900	2.97	184	14.8	5.94
1900	2.97	184	14.9	5.94
1900	2.97	185	14.9	5.95
1900	2.98	185	14.9	5.96
1900	2.98	185	14.9	5.97
1900	2.99	185	14.9	5.98
1900	2.99	185	15.0	5.98
1900	2.99	185	15.0	5.99
1910	3.00	185	15.0	6.00
1910	3.00	185	15.0	6.01
1910	3.01	186	15.0	6.01
1910	3.01	186	15.0	6.02
1910	3.01	186	15.1	6.03
1910	3.02	186	15.1	6.04
1910	3.02	186	15.1	6.05
1910	3.03	186	15.1	6.05
1910	3.03	186	15.1	6.06
1910	3.03	186	15.2	6.07
1920	3.04	186	15.2	6.08
1920	3.04	186	15.2	6.09
1920	3.05	186	15.2	6.09
1920	3.05	187	15.2	6.10
1920	3.05	187	15.3	6.11
1920	3.06	187	15.3	6.12
1920	3.06	187	15.3	6.12
1920	3.06	187	15.3	6.13
1920	3.07	187	15.3	6.14
1920	3.07	187	15.4	6.15
1930	3.08	187	15.4	6.16
1930	3.08	187	15.4	6.16
1930	3.08	187	15.4	6.17
1930	3.09	188	15.4	6.18
1930	3.09	188	15.5	6.19
1930	3.10	188	15.5	6.20
1930	3.10	188	15.5	6.20
1930	3.10	188	15.5	6.21
1930	3.11	188	15.5	6.22
1940	3.11	188	15.6	6.23
1940	3.12	188	15.6	6.23
1940	3.12	188	15.6	6.24
1940	3.12	188	15.6	6.25
1940	3.13	189	15.6	6.26
1940	3.13	189	15.7	6.27
1940	3.14	189	15.7	6.27
1940	3.14	189	15.7	6.28
1940	3.14	189	15.7	6.29
1940	3.15	189	15.7	6.30
1950	3.15	189	15.8	6.31
1950	3.16	189	15.8	6.31
1950	3.16	189	15.8	6.32
1950	3.16	189	15.8	6.33
1950	3.17	190	15.8	6.34
1950	3.17	190	15.9	6.34
1950	3.17	190	15.9	6.35
1950	3.18	190	15.9	6.36
1950	3.18	190	15.9	6.37
1950	3.19	190	15.9	6.38
1960	3.19	190	16.0	6.38
1960	3.19	190	16.0	6.39
1960	3.20	190	16.0	6.40
1960	3.20	190	16.0	6.41
1960	3.21	190	16.0	6.42
1960	3.21	191	16.1	6.42
1960	3.21	191	16.1	6.43
1960	3.22	191	16.1	6.44
1960	3.22	191	16.1	6.45
1960	3.23	191	16.1	6.45
1960	3.23	191	16.1	6.46
1970	3.23	191	16.2	6.47
1970	3.24	191	16.2	6.48
1970	3.24	191	16.2	6.49
1970	3.25	191	16.2	6.49
1970	3.25	192	16.2	6.50
1970	3.25	192	16.3	6.51
1970	3.26	192	16.3	6.52
1970	3.26	192	16.3	6.53
1970	3.27	192	16.3	6.53
1970	3.27	192	16.3	6.54
1980	3.27	192	16.4	6.55
1980	3.28	192	16.4	6.56
1980	3.28	192	16.4	6.56
1980	3.28	192	16.4	6.57
1980	3.29	192	16.4	6.58
1980	3.29	193	16.5	6.59
1980	3.30	193	16.5	6.60
1980	3.30	193	16.5	6.60
1980	3.30	193	16.5	6.61
1980	3.31	193	16.5	6.62
1980	3.31	193	16.6	6.63
1980	3.32	193	16.6	6.64
1990	3.32	193	16.6	6.64
1990	3.32	193	16.6	6.65
1990	3.33	193	16.6	6.66
1990	3.33	193	16.7	6.67
1990	3.34	193	16.7	6.67
1990	3.34	193	16.7	6.68
1990	3.34	194	16.7	6.69
1990	3.35	194	16.7	6.70
1990	3.35	194	16.8	6.71
1990	3.36	194	16.8	6.71
1990	3.36	194	16.8	6.72
2000	3.36	194	16.8	6.73
2000	3.37	194	16.8	6.74
2000	3.37	194	16.9	6.75
2000	3.38	194	16.9	6.75
2000	3.38	194	16.9	6.76
2000	3.38	194	16.9	6.77
2000	3.39	194	16.9	6.78
2000	3.39	194	17.0	6.78
2000	3.39	195	17.0	6.79
2000	3.40	195	17.0	6.80
2000	3.40	195	17.0	6.81
2000	3.41	195	17.0	6.82
2000	3.41	195	17.1	6.82
2010	3.41	195	17.1	6.83
2010	3.42	195	17.1	6.84
2010	3.42	195	17.1	6.85
2010	3.43	195	17.1	6.86
2010	3.43	195	17.2	6.86
2010	3.43	196	17.2	6.87
2010	3.44	196	17.2	6.88
2010	3.44	196	17.2	6.89
2010	3.45	196	17.2	6.89
2010	3.45	196	17.2	6.90
2010	3.45	196	17.3	6.91
2020	3.46	196	17.3	6.92
2020	3.46	196	17.3	6.93
2020	3.47	196	17.3	6.93
2020	3.47	196	17.3	6.94
2020	3.47	196	17.4	6.95
2020	3.48	196	17.4	6.96
2020	3.48	196	17.4	6.97
2020	3.49	196	17.4	6.97
2020	3.49	196	17.4	6.98
2020	3.49	197	17.5	6.99
2020	3.50	197	17.5	7.00
2020	3.50	197	17.5	7.01
2020	3.50	197	17.5	7.01
2020	3.51	197	17.5	7.02
2020	3.51	197	17.6	7.03
2030	3.52	197	17.6	7.04
2030	3.52	197	17.6	7.04
2030	3.52	197	17.6	7.05
2030	3.53	197	17.6	7.06
2030	3.53	197	17.7	7.07
2030	3.54	197	17.7	7.08
2030	3.54	197	17.7	7.08
2030	3.54	198	17.7	7.09
2030	3.55	198	17.7	7.10
2030	3.55	198	17.8	7.11
2030	3.56	198	17.8	7.12
2030	3.56	198	17.8	7.12
2030	3.56	198	17.8	7.13
2040	3.57	198	17.8	7.14
2040	3.57	198	17.9	7.15
2040	3.58	198	17.9	7.15
2040	3.58	198	17.9	7.16
2040	3.58	198	17.9	7.17
2040	3.59	198	17.9	7.18
2040	3.59	198	18.0	7.19
2040	3.60	198	18.0	7.19
2040	3.60	199	18.0	7.20
2040	3.60	199	18.0	7.21
2040	3.61	199	18.0	7.22
2040	3.61	199	18.1	7.23
2040	3.61	199	18.1	7.23
2040	3.62	199	18.1	7.24
2040	3.62	199	18.1	7.25
2040	3.63	199	18.1	7.26
2040	3.63	199	18.2	7.26
2040	3.63	199	18.2	7.27
2040	3.64	199	18.2	7.28
2040	3.64	199	18.2	7.29
2040	3.65	199	18.2	7.30
2030	3.65	198	18.3	7.30
2010	3.65	195	18.3	7.31
1920	3.66	187	18.3	7.32
1900	3.66	185	18.3	7.33
1910	3.67	186	18.3	7.34
1920	3.67	186	18.4	7.34
1930	3.67	187	18.4	7.35
1940	3.68	189	18.4	7.36
1950	3.68	190	18.4	7.37
1960	3.69	191	18.4	7.37
1970	3.69	192	18.4	7.38
1980	3.69	193	18.5	7.39
1990	3.70	194	18.5	7.40
2000	3.70	195	18.5	7.41
2010	3.71	196	18.5	7.41
2020	3.71	196	18.5	7.42
2030	3.71	197	18.6	7.43
2030	3.72	198	18.6	7.44
2040	3.72	198	18.6	7.45
2040	3.72	198	18.6	7.45
2040	3.73	199	18.6	7.46
2050	3.73	199	18.7	7.47
2050	3.74	199	18.7	7.48
2050	3.74	200	18.7	7.48
2050	3.74	200	18.7	7.49
2060	3.75	200	18.7	7.50
2060	3.75	200	18.8	7.51
2060	3.76	200	18.8	7.52
2060	3.76	200	18.8	7.52
2060	3.76	200	18.8	7.53
2060	3.77	200	18.8	7.54
2060	3.77	201	18.9	7.55
2060	3.78	201	18.9	7.56
2060	3.78	201	18.9	7.56
2060	3.78	201	18.9	7.57
2060	3.79	201	18.9	7.58
2060	3.79	201	19.0	7.59
2060	3.80	201	19.0	7.59
2070	3.80	201	19.0	7.60
2070	3.80	201	19.0	7.61
2070	3.81	201	19.0	7.62
2070	3.81	201	19.1	7.63
2070	3.82	201	19.1	7.63
2070	3.82	201	19.1	7.64
2070	3.82	201	19.1	7.65
2070	3.83	201	19.1	7.66
2070	3.83	201	19.2	7.67
2070	3.83	201	19.2	7.67
2070	3.84	201	19.2	7.68
2070	3.84	202	19.2	7.69
2070	3.85	202	19.2	7.70
2070	3.85	202	19.3	7.70
2070	3.85	202	19.3	7.71
2070	3.86	202	19.3	7.72
2080	3.86	202	19.3	7.73
2070	3.87	202	19.3	7.74
2080	3.87	202	19.4	7.74
2080	3.87	202	19.4	7.75
2080	3.88	202	19.4	7.76
2080	3.88	202	19.4	7.77
2080	3.89	202	19.4	7.78
2080	3.89	202	19.5	7.78
2080	3.89	202	19.5	7.79
2080	3.90	202	19.5	7.80
2080	3.90	202	19.5	7.81
2080	3.91	202	19.5	7.81
2080	3.91	202	19.5	7.82
2080	3.91	203	19.6	7.83
2080	3.92	202	19.6	7.84
2080	3.92	203	19.6	7.85
2080	3.93	203	19.6	7.85
2080	3.93	203	19.6	7.86
2090	3.93	203	19.7	7.87
2090	3.94	203	19.7	7.88
2090	3.94	203	19.7	7.89
2090	3.95	203	19.7	7.89
2090	3.95	203	19.7	7.90
2090	3.95	203	19.8	7.91
2090	3.96	203	19.8	7.92
2090	3.96	203	19.8	7.92
2090	3.96	203	19.8	7.93
2090	3.97	203	19.8	7.94
2090	3.97	203	19.9	7.95
2090	3.98	203	19.9	7.96
2090	3.98	203	19.9	7.96
2090	3.98	204	19.9	7.97
2090	3.99	203	19.9	7.98
2090	3.99	204	20.0	7.99
2090	4.00	204	20.0	8.00
2090	4.00	204	20.0	8.00
2090	4.00	204	20.0	8.01
2090	4.01	204	20.0	8.02
2100	4.01	204	20.1	8.03
2100	4.02	204	20.1	8.03
2100	4.02	204	20.1	8.04
2100	4.02	204	20.1	8.05
2100	4.03	204	20.1	8.06
2100	4.03	204	20.2	8.07
2100	4.04	204	20.2	8.07
2100	4.04	204	20.2	8.08
2100	4.04	204	20.2	8.09
2100	4.05	204	20.2	8.10
2100	4.05	204	20.3	8.11
2100	4.06	204	20.3	8.11
2100	4.06	204	20.3	8.12
2100	4.06	204	20.3	8.13
2100	4.07	204	20.3	8.14
2100	4.07	204	20.4	8.14
2100	4.07	205	20.4	8.15
2100	4.08	205	20.4	8.16
2100	4.08	205	20.4	8.17
2110	4.09	205	20.4	8.18
2110	4.09	205	20.5	8.18
2110	4.09	205	20.5	8.19
2110	4.10	205	20.5	8.20
2110	4.10	205	20.5	8.21
2110	4.11	205	20.5	8.22
2110	4.11	205	20.5	8.22
2110	4.11	205	20.6	8.23
2110	4.12	205	20.6	8.24
2110	4.12	205	20.6	8.25
2110	4.13	205	20.6	8.25
2110	4.13	205	20.6	8.26
2110	4.13	205	20.7	8.27
2110	4.14	205	20.7	8.28
2110	4.14	205	20.7	8.29
2110	4.14	205	20.7	8.29
2110	4.15	205	20.7	8.30
2110	4.15	205	20.8	8.31
2110	4.16	206	20.8	8.32
2110	4.16	205	20.8	8.33
2110	4.16	206	20.8	8.33
2110	4.17	206	20.8	8.34
2110	4.17	206	20.9	8.35
2120	4.18	206	20.9	8.36
2120	4.18	206	20.9	8.36
2120	4.18	206	20.9	8.37
2120	4.19	206	20.9	8.38
2120	4.19	206	21.0	8.39
2120	4.20	206	21.0	8.40
2120	4.20	206	21.0	8.40
2120	4.20	206	21.0	8.41
2120	4.21	206	21.0	8.42
2120	4.21	206	21.1	8.43
2120	4.22	206	21.1	8.44
2120	4.22	206	21.1	8.44
2120	4.22	206	21.1	8.45
2120	4.23	206	21.1	8.46
2120	4.23	206	21.2	8.47
2120	4.24	206	21.2	8.47
2120	4.24	206	21.2	8.48
2120	4.24	206	21.2	8.49
2120	4.25	206	21.2	8.50
2120	4.25	206	21.3	8.51
2120	4.26	206	21.3	8.51
2120	4.26	207	21.3	8.52
2120	4.26	207	21.3	8.53
2120	4.27	207	21.3	8.54
2120	4.27	207	21.4	8.55
2120	4.27	207	21.4	8.55
2130	4.28	207	21.4	8.56
2130	4.28	207	21.4	8.57
2130	4.29	207	21.4	8.58
2130	4.29	207	21.5	8.58
2130	4.29	207	21.5	8.59
2130	4.30	207	21.5	8.60
2130	4.30	207	21.5	8.61
2130	4.31	207	21.5	8.62
2130	4.31	207	21.6	8.62
2130	4.31	207	21.6	8.63
2130	4.32	207	21.6	8.64
2130	4.32	207	21.6	8.65
2130	4.33	207	21.6	8.66
2130	4.33	207	21.7	8.66
2130	4.33	207	21.7	8.67
2130	4.34	207	21.7	8.68
2130	4.34	207	21.7	8.69
2130	4.35	207	21.7	8.69
2130	4.35	207	21.7	8.70
2130	4.35	207	21.8	8.71
2130	4.36	207	21.8	8.72
2130	4.36	207	21.8	8.73
2130	4.37	207	21.8	8.73
2130	4.37	208	21.8	8.74
2130	4.37	208	21.9	8.75
2130	4.38	208	21.9	8.76
2140	4.38	208	21.9	8.77
2130	4.39	208	21.9	8.77
2140	4.39	208	21.9	8.78
2140	4.39	208	22.0	8.79
2140	4.40	208	22.0	8.80
2140	4.40	208	22.0	8.80
2140	4.40	208	22.0	8.81
2140	4.41	208	22.0	8.82
2140	4.41	208	22.1	8.83
2140	4.42	208	22.1	8.84
2140	4.42	208	22.1	8.84
2140	4.42	208	22.1	8.85
2140	4.43	208	22.1	8.86
2140	4.43	208	22.2	8.87
2140	4.44	208	22.2	8.88
2140	4.44	208	22.2	8.88
2140	4.44	208	22.2	8.89
2140	4.45	208	22.2	8.90
2140	4.45	208	22.3	8.91
2140	4.46	208	22.3	8.91
2140	4.46	208	22.3	8.92
2140	4.46	208	22.3	8.93
2140	4.47	208	22.3	8.94
2140	4.47	208	22.4	8.95
2140	4.48	208	22.4	8.95
2140	4.48	208	22.4	8.96
2140	4.48	208	22.4	8.97
2140	4.49	208	22.4	8.98
2140	4.49	208	22.5	8.99
2140	4.50	208	22.5	8.99
2140	4.50	208	22.5	9.00
2140	4.50	208	22.5	9.01
2140	4.51	208	22.5	9.02
2140	4.51	208	22.6	9.02
2140	4.51	208	22.6	9.03
2140	4.52	208	22.6	9.04
2140	4.52	209	22.6	9.05
2140	4.53	209	22.6	9.06
2150	4.53	209	22.7	9.06
2150	4.53	209	22.7	9.07
2140	4.54	209	22.7	9.08
2150	4.54	209	22.7	9.09
2150	4.55	209	22.7	9.10
2150	4.55	209	22.8	9.10
2150	4.55	209	22.8	9.11
2150	4.56	209	22.8	9.12
2150	4.56	209	22.8	9.13
2150	4.57	209	22.8	9.13
2150	4.57	209	22.8	9.14
2150	4.57	209	22.9	9.15
2150	4.58	209	22.9	9.16
2150	4.58	209	22.9	9.17
2150	4.59	209	22.9	9.17
2150	4.59	209	22.9	9.18
2150	4.59	209	23.0	9.19
2150	4.60	209	23.0	9.20
2150	4.60	209	23.0	9.21
2150	4.61	209	23.0	9.21
2150	4.61	209	23.0	9.22
2150	4.61	209	23.1	9.23
2150	4.62	209	23.1	9.24
2150	4.62	209	23.1	9.24
2150	4.62	209	23.1	9.25
2150	4.63	209	23.1	9.26
2150	4.63	209	23.2	9.27
2150	4.64	209	23.2	9.28
2150	4.64	209	23.2	9.28
2150	4.64	209	23.2	9.29
2150	4.65	209	23.2	9.30
2150	4.65	209	23.3	9.31
2150	4.66	209	23.3	9.32
2150	4.66	209	23.3	9.32
2150	4.66	209	23.3	9.33
2150	4.67	209	23.3	9.34
2150	4.67	209	23.4	9.35
2150	4.68	209	23.4	9.35
2150	4.68	209	23.4	9.36
2150	4.68	209	23.4	9.37
2150	4.69	209	23.4	9.38
2150	4.69	209	23.5	9.39
2150	4.70	209	23.5	9.39
2150	4.70	209	23.5	9.40
2150	4.70	209	23.5	9.41
2150	4.71	209	23.5	9.42
2150	4.71	209	23.6	9.43
2150	4.72	209	23.6	9.43
2150	4.72	209	23.6	9.44
2150	4.72	209	23.6	9.45
2150	4.73	209	23.6	9.46
2150	4.73	209	23.7	9.46
2150	4.73	209	23.7	9.47
2150	4.74	209	23.7	9.48
2150	4.74	209	23.7	9.49
2150	4.75	210	23.7	9.50
2150	4.75	209	23.8	9.50
2150	4.75	210	23.8	9.51
2150	4.76	210	23.8	9.52
2150	4.76	209	23.8	9.53
2150	4.77	210	23.8	9.54
2150	4.77	210	23.9	9.54
2150	4.77	210	23.9	9.55
2150	4.78	210	23.9	9.56
2150	4.78	210	23.9	9.57
2150	4.79	210	23.9	9.57
2150	4.79	210	23.9	9.58
2150	4.79	209	24.0	9.59
2150	4.80	210	24.0	9.60
2150	4.80	210	24.0	9.61
2150	4.81	209	24.0	9.61
2150	4.81	210	24.0	9.62
2150	4.81	209	24.1	9.63
2150	4.82	210	24.1	9.64
2150	4.82	210	24.1	9.65
2150	4.83	209	24.1	9.65
2150	4.83	210	24.1	9.66
2150	4.83	209	24.2	9.67
2150	4.84	210	24.2	9.68
2150	4.84	209	24.2	9.68
2150	4.84	209	24.2	9.69
2150	4.85	209	24.2	9.70
2150	4.85	209	24.3	9.71
2150	4.86	209	24.3	9.72
2150	4.86	209	24.3	9.72
2150	4.86	209	24.3	9.73
2150	4.87	209	24.3	9.74
2150	4.87	209	24.4	9.75
2150	4.88	209	24.4	9.76
2150	4.88	209	24.4	9.76
2150	4.88	209	24.4	9.77
2150	4.89	209	24.4	9.78
1300	4.89	126	24.5	9.79
-203	4.90	-19.7	24.5	9.79
-203	4.90	-19.8	24.5	9.80
-203	4.90	-19.8	24.5	9.81
-203	4.91	-19.8	24.5	9.82
-203	4.91	-19.8	24.6	9.83