File: Acadmics/4 semester/DESIGN LAB/UTM csv/poly. tensile.csv
Force (N)	Position (mm)	Stress (MPa)	Strain (%)	Time (min)
0.00	0.00	0.00	0.00	0.00398
0.00	0.0340	0.00	0.113	0.0112
0.00	0.0700	0.00	0.233	0.0183
0.00	0.106	0.00	0.354	0.0255
0.833	0.142	0.0339	0.473	0.0327
0.833	0.178	0.0339	0.593	0.0398
0.833	0.214	0.0339	0.713	0.0470
0.833	0.250	0.0339	0.832	0.0542
0.833	0.285	0.0339	0.951	0.0613
0.833	0.321	0.0339	1.07	0.0685
0.833	0.357	0.0339	1.19	0.0757
0.833	0.393	0.0339	1.31	0.0828
0.833	0.429	0.0339	1.43	0.0900
0.833	0.464	0.0339	1.55	0.0972
0.833	0.500	0.0339	1.67	0.104
0.833	0.536	0.0339	1.79	0.112
1.67	0.572	0.0678	1.91	0.119
1.67	0.608	0.0678	2.03	0.126
1.67	0.644	0.0678	2.15	0.133
1.67	0.679	0.0678	2.26	0.140
1.67	0.716	0.0678	2.39	0.147
1.67	0.751	0.0678	2.50	0.155
1.67	0.787	0.0678	2.62	0.162
1.67	0.822	0.0678	2.74	0.169
1.67	0.859	0.0678	2.86	0.176
2.50	0.895	0.102	2.98	0.183
1.67	0.930	0.0678	3.10	0.190
1.67	0.966	0.0678	3.22	0.198
2.50	1.00	0.102	3.34	0.205
2.50	1.04	0.102	3.46	0.212
2.50	1.07	0.102	3.58	0.219
2.50	1.11	0.102	3.70	0.226
2.50	1.15	0.102	3.82	0.233
2.50	1.18	0.102	3.94	0.241
2.50	1.22	0.102	4.06	0.248
2.50	1.25	0.102	4.18	0.255
2.50	1.29	0.102	4.30	0.262
2.50	1.32	0.102	4.42	0.269
2.50	1.36	0.102	4.54	0.276
2.50	1.40	0.102	4.65	0.284
3.33	1.43	0.136	4.77	0.291
3.33	1.47	0.136	4.89	0.298
3.33	1.50	0.136	5.01	0.305
3.33	1.54	0.136	5.13	0.312
3.33	1.58	0.136	5.25	0.319
3.33	1.61	0.136	5.37	0.327
3.33	1.65	0.136	5.49	0.334
3.33	1.68	0.136	5.61	0.341
4.17	1.72	0.170	5.73	0.348
4.17	1.75	0.170	5.85	0.355
4.17	1.79	0.170	5.97	0.362
4.17	1.83	0.170	6.09	0.370
4.17	1.86	0.170	6.21	0.377
4.17	1.90	0.170	6.33	0.384
4.17	1.93	0.170	6.45	0.391
4.17	1.97	0.170	6.57	0.398
4.17	2.01	0.170	6.69	0.405
4.17	2.04	0.170	6.80	0.413
4.17	2.08	0.170	6.92	0.420
4.17	2.11	0.170	7.04	0.427
5.00	2.15	0.203	7.16	0.434
5.00	2.19	0.203	7.28	0.441
4.17	2.22	0.170	7.40	0.448
5.00	2.26	0.203	7.52	0.456
5.00	2.29	0.203	7.64	0.463
5.00	2.33	0.203	7.76	0.470
5.00	2.36	0.203	7.88	0.477
5.00	2.40	0.203	8.00	0.484
5.00	2.44	0.203	8.12	0.491
5.00	2.47	0.203	8.24	0.499
5.00	2.51	0.203	8.36	0.506
5.60	2.54	0.228	8.48	0.513
5.83	2.58	0.237	8.60	0.520
5.83	2.61	0.237	8.72	0.527
5.83	2.65	0.237	8.84	0.534
5.83	2.69	0.237	8.96	0.542
5.83	2.72	0.237	9.08	0.549
5.83	2.76	0.237	9.19	0.556
5.83	2.79	0.237	9.32	0.563
5.83	2.83	0.237	9.43	0.570
5.83	2.87	0.237	9.55	0.577
5.83	2.90	0.237	9.67	0.585
5.83	2.94	0.237	9.79	0.592
5.83	2.97	0.237	9.91	0.599
5.83	3.01	0.237	10.0	0.606
6.67	3.05	0.271	10.2	0.613
6.67	3.08	0.271	10.3	0.620
6.67	3.12	0.271	10.4	0.628
6.67	3.15	0.271	10.5	0.635
6.67	3.19	0.271	10.6	0.642
6.67	3.22	0.271	10.7	0.649
6.67	3.26	0.271	10.9	0.656
6.67	3.30	0.271	11.0	0.663
6.67	3.33	0.271	11.1	0.671
6.67	3.37	0.271	11.2	0.678
6.67	3.40	0.271	11.3	0.685
7.50	3.44	0.305	11.5	0.692
7.50	3.48	0.305	11.6	0.699
7.50	3.51	0.305	11.7	0.706
7.50	3.55	0.305	11.8	0.714
7.50	3.58	0.305	11.9	0.721
7.50	3.62	0.305	12.1	0.728
7.50	3.65	0.305	12.2	0.735
7.50	3.69	0.305	12.3	0.742
7.50	3.73	0.305	12.4	0.749
7.50	3.76	0.305	12.5	0.757
7.50	3.80	0.305	12.7	0.764
7.50	3.83	0.305	12.8	0.771
8.33	3.87	0.339	12.9	0.778
8.33	3.91	0.339	13.0	0.785
8.33	3.94	0.339	13.1	0.792
8.33	3.98	0.339	13.3	0.800
8.33	4.01	0.339	13.4	0.807
8.33	4.05	0.339	13.5	0.814
8.33	4.08	0.339	13.6	0.821
8.33	4.12	0.339	13.7	0.828
8.33	4.16	0.339	13.9	0.836
9.14	4.19	0.372	14.0	0.843
8.33	4.23	0.339	14.1	0.850
8.33	4.26	0.339	14.2	0.857
9.17	4.30	0.373	14.3	0.864
9.17	4.34	0.373	14.5	0.871
9.17	4.37	0.373	14.6	0.879
9.17	4.41	0.373	14.7	0.886
9.17	4.44	0.373	14.8	0.893
9.17	4.48	0.373	14.9	0.900
9.17	4.52	0.373	15.1	0.907
9.17	4.55	0.373	15.2	0.914
9.17	4.59	0.373	15.3	0.922
9.17	4.62	0.373	15.4	0.929
9.17	4.66	0.373	15.5	0.936
10.0	4.69	0.407	15.6	0.943
10.0	4.73	0.407	15.8	0.950
10.0	4.77	0.407	15.9	0.957
10.0	4.80	0.407	16.0	0.965
10.0	4.84	0.407	16.1	0.972
10.0	4.87	0.407	16.2	0.979
10.0	4.91	0.407	16.4	0.986
10.0	4.94	0.407	16.5	0.993
10.0	4.98	0.407	16.6	1.00
10.8	5.02	0.441	16.7	1.01
10.3	5.05	0.418	16.8	1.01
10.8	5.09	0.441	17.0	1.02
10.8	5.12	0.441	17.1	1.03
10.8	5.16	0.441	17.2	1.04
10.8	5.20	0.441	17.3	1.04
10.8	5.23	0.441	17.4	1.05
10.8	5.27	0.441	17.6	1.06
11.7	5.30	0.475	17.7	1.06
10.8	5.34	0.441	17.8	1.07
11.0	5.37	0.447	17.9	1.08
11.7	5.41	0.475	18.0	1.09
11.7	5.45	0.475	18.2	1.09
11.7	5.48	0.475	18.3	1.10
11.7	5.52	0.475	18.4	1.11
11.7	5.55	0.475	18.5	1.12
11.7	5.59	0.475	18.6	1.12
11.7	5.63	0.475	18.8	1.13
11.7	5.66	0.475	18.9	1.14
11.7	5.70	0.475	19.0	1.14
12.5	5.73	0.509	19.1	1.15
11.7	5.77	0.475	19.2	1.16
12.5	5.80	0.509	19.3	1.17
12.5	5.84	0.509	19.5	1.17
12.5	5.88	0.509	19.6	1.18
12.5	5.91	0.509	19.7	1.19
12.5	5.95	0.509	19.8	1.19
12.5	5.98	0.509	19.9	1.20
12.5	6.02	0.509	20.1	1.21
12.5	6.06	0.509	20.2	1.22
12.5	6.09	0.509	20.3	1.22
13.2	6.13	0.536	20.4	1.23
13.3	6.16	0.543	20.5	1.24
13.3	6.20	0.543	20.7	1.24
13.3	6.24	0.543	20.8	1.25
13.3	6.27	0.543	20.9	1.26
13.3	6.31	0.543	21.0	1.27
13.3	6.34	0.543	21.1	1.27
13.3	6.38	0.543	21.3	1.28
13.3	6.41	0.543	21.4	1.29
13.3	6.45	0.543	21.5	1.29
13.3	6.49	0.543	21.6	1.30
14.2	6.52	0.576	21.7	1.31
13.3	6.56	0.543	21.9	1.32
14.2	6.59	0.576	22.0	1.32
14.2	6.63	0.576	22.1	1.33
14.2	6.67	0.576	22.2	1.34
14.2	6.70	0.576	22.3	1.34
14.2	6.74	0.576	22.5	1.35
14.2	6.77	0.576	22.6	1.36
14.2	6.81	0.576	22.7	1.37
14.2	6.84	0.576	22.8	1.37
14.2	6.88	0.576	22.9	1.38
14.5	6.92	0.589	23.1	1.39
14.2	6.95	0.576	23.2	1.39
14.2	6.99	0.576	23.3	1.40
14.2	7.02	0.576	23.4	1.41
15.0	7.06	0.610	23.5	1.42
15.0	7.10	0.610	23.7	1.42
15.0	7.13	0.610	23.8	1.43
15.0	7.17	0.610	23.9	1.44
15.0	7.20	0.610	24.0	1.44
15.0	7.24	0.610	24.1	1.45
15.0	7.27	0.610	24.2	1.46
15.0	7.31	0.610	24.4	1.47
15.0	7.35	0.610	24.5	1.47
15.0	7.38	0.610	24.6	1.48
15.8	7.42	0.644	24.7	1.49
15.0	7.45	0.610	24.8	1.49
15.3	7.49	0.621	25.0	1.50
15.1	7.53	0.613	25.1	1.51
15.0	7.56	0.610	25.2	1.52
15.8	7.60	0.644	25.3	1.52
15.8	7.63	0.644	25.4	1.53
15.8	7.67	0.644	25.6	1.54
15.8	7.70	0.644	25.7	1.55
15.8	7.74	0.644	25.8	1.55
15.8	7.78	0.644	25.9	1.56
15.8	7.81	0.644	26.0	1.57
15.8	7.85	0.644	26.2	1.57
15.8	7.88	0.644	26.3	1.58
15.8	7.92	0.644	26.4	1.59
16.7	7.96	0.678	26.5	1.60
16.7	7.99	0.678	26.6	1.60
16.7	8.03	0.678	26.8	1.61
16.7	8.06	0.678	26.9	1.62
16.7	8.10	0.678	27.0	1.62
16.7	8.13	0.678	27.1	1.63
16.7	8.17	0.678	27.2	1.64
16.7	8.21	0.678	27.4	1.65
16.7	8.24	0.678	27.5	1.65
16.7	8.28	0.678	27.6	1.66
16.7	8.31	0.678	27.7	1.67
16.7	8.35	0.678	27.8	1.67
16.7	8.39	0.678	28.0	1.68
16.7	8.42	0.678	28.1	1.69
16.7	8.46	0.678	28.2	1.70
16.7	8.49	0.678	28.3	1.70
17.4	8.53	0.710	28.4	1.71
17.5	8.56	0.712	28.5	1.72
17.5	8.60	0.712	28.7	1.72
17.5	8.64	0.712	28.8	1.73
17.5	8.67	0.712	28.9	1.74
17.5	8.71	0.712	29.0	1.75
17.5	8.74	0.712	29.1	1.75
17.5	8.78	0.712	29.3	1.76
17.5	8.82	0.712	29.4	1.77
17.5	8.85	0.712	29.5	1.77
18.3	8.89	0.746	29.6	1.78
18.3	8.92	0.746	29.7	1.79
18.3	8.96	0.746	29.9	1.80
18.3	8.99	0.746	30.0	1.80
18.3	9.03	0.746	30.1	1.81
18.3	9.07	0.746	30.2	1.82
18.3	9.10	0.746	30.3	1.82
18.3	9.14	0.746	30.5	1.83
18.3	9.17	0.746	30.6	1.84
19.2	9.21	0.780	30.7	1.85
18.3	9.25	0.746	30.8	1.85
19.2	9.28	0.780	30.9	1.86
19.2	9.32	0.780	31.1	1.87
19.2	9.35	0.780	31.2	1.87
19.2	9.39	0.780	31.3	1.88
19.2	9.43	0.780	31.4	1.89
19.2	9.46	0.780	31.5	1.90
19.2	9.50	0.780	31.7	1.90
19.2	9.53	0.780	31.8	1.91
19.2	9.57	0.780	31.9	1.92
19.2	9.60	0.780	32.0	1.93
19.2	9.64	0.780	32.1	1.93
20.0	9.68	0.814	32.3	1.94
20.0	9.71	0.814	32.4	1.95
20.0	9.75	0.814	32.5	1.95
20.0	9.78	0.814	32.6	1.96
20.0	9.82	0.814	32.7	1.97
20.0	9.86	0.814	32.9	1.98
20.0	9.89	0.814	33.0	1.98
20.0	9.93	0.814	33.1	1.99
20.0	9.96	0.814	33.2	2.00
20.0	10.0	0.814	33.3	2.00
20.8	10.0	0.847	33.4	2.01
20.0	10.1	0.814	33.6	2.02
20.8	10.1	0.848	33.7	2.03
20.0	10.1	0.814	33.8	2.03
20.8	10.2	0.848	33.9	2.04
20.8	10.2	0.848	34.0	2.05
20.8	10.2	0.848	34.2	2.05
20.8	10.3	0.848	34.3	2.06
20.8	10.3	0.848	34.4	2.07
20.8	10.4	0.848	34.5	2.08
20.8	10.4	0.848	34.6	2.08
20.8	10.4	0.848	34.8	2.09
21.6	10.5	0.877	34.9	2.10
21.7	10.5	0.882	35.0	2.10
20.8	10.5	0.848	35.1	2.11
21.7	10.6	0.882	35.2	2.12
21.7	10.6	0.882	35.4	2.13
21.7	10.6	0.882	35.5	2.13
21.7	10.7	0.882	35.6	2.14
21.7	10.7	0.882	35.7	2.15
21.7	10.8	0.882	35.8	2.15
21.7	10.8	0.882	36.0	2.16
22.5	10.8	0.916	36.1	2.17
22.5	10.9	0.916	36.2	2.18
22.5	10.9	0.916	36.3	2.18
22.5	10.9	0.916	36.4	2.19
22.5	11.0	0.916	36.6	2.20
22.5	11.0	0.916	36.7	2.20
22.5	11.0	0.916	36.8	2.21
22.5	11.1	0.916	36.9	2.22
22.5	11.1	0.916	37.0	2.23
22.5	11.1	0.916	37.2	2.23
22.5	11.2	0.916	37.3	2.24
23.3	11.2	0.949	37.4	2.25
22.5	11.3	0.916	37.5	2.25
23.3	11.3	0.949	37.6	2.26
23.3	11.3	0.949	37.7	2.27
23.3	11.4	0.949	37.9	2.28
23.3	11.4	0.949	38.0	2.28
23.3	11.4	0.949	38.1	2.29
23.3	11.5	0.949	38.2	2.30
23.8	11.5	0.969	38.3	2.31
23.3	11.5	0.949	38.5	2.31
24.2	11.6	0.983	38.6	2.32
24.2	11.6	0.983	38.7	2.33
23.9	11.6	0.974	38.8	2.33
24.2	11.7	0.983	38.9	2.34
24.2	11.7	0.983	39.1	2.35
24.2	11.8	0.983	39.2	2.36
24.2	11.8	0.983	39.3	2.36
24.6	11.8	1.00	39.4	2.37
24.2	11.9	0.983	39.5	2.38
25.0	11.9	1.02	39.7	2.38
25.0	11.9	1.02	39.8	2.39
25.0	12.0	1.02	39.9	2.40
25.0	12.0	1.02	40.0	2.41
25.0	12.0	1.02	40.1	2.41
25.0	12.1	1.02	40.3	2.42
25.0	12.1	1.02	40.4	2.43
25.0	12.1	1.02	40.5	2.43
25.0	12.2	1.02	40.6	2.44
25.0	12.2	1.02	40.7	2.45
25.8	12.3	1.05	40.9	2.46
25.8	12.3	1.05	41.0	2.46
25.8	12.3	1.05	41.1	2.47
25.8	12.4	1.05	41.2	2.48
25.8	12.4	1.05	41.3	2.48
25.8	12.4	1.05	41.5	2.49
25.8	12.5	1.05	41.6	2.50
25.8	12.5	1.05	41.7	2.51
25.8	12.5	1.05	41.8	2.51
25.8	12.6	1.05	41.9	2.52
25.8	12.6	1.05	42.1	2.53
25.8	12.7	1.05	42.2	2.53
25.8	12.7	1.05	42.3	2.54
26.7	12.7	1.09	42.4	2.55
26.7	12.8	1.09	42.5	2.56
26.7	12.8	1.09	42.6	2.56
26.7	12.8	1.09	42.8	2.57
26.7	12.9	1.09	42.9	2.58
26.7	12.9	1.09	43.0	2.58
26.7	12.9	1.09	43.1	2.59
26.7	13.0	1.09	43.2	2.60
26.7	13.0	1.09	43.4	2.61
26.7	13.0	1.09	43.5	2.61
26.7	13.1	1.09	43.6	2.62
26.7	13.1	1.09	43.7	2.63
26.7	13.2	1.09	43.8	2.63
26.7	13.2	1.09	44.0	2.64
27.5	13.2	1.12	44.1	2.65
27.5	13.3	1.12	44.2	2.66
27.5	13.3	1.12	44.3	2.66
27.5	13.3	1.12	44.4	2.67
27.5	13.4	1.12	44.6	2.68
27.5	13.4	1.12	44.7	2.68
27.5	13.4	1.12	44.8	2.69
27.5	13.5	1.12	44.9	2.70
27.5	13.5	1.12	45.0	2.71
27.5	13.5	1.12	45.2	2.71
27.5	13.6	1.12	45.3	2.72
27.5	13.6	1.12	45.4	2.73
27.5	13.7	1.12	45.5	2.74
28.1	13.7	1.14	45.6	2.74
28.3	13.7	1.15	45.8	2.75
27.5	13.8	1.12	45.9	2.76
27.5	13.8	1.12	46.0	2.76
28.3	13.8	1.15	46.1	2.77
28.3	13.9	1.15	46.2	2.78
28.3	13.9	1.15	46.4	2.79
28.3	13.9	1.15	46.5	2.79
28.3	14.0	1.15	46.6	2.80
28.3	14.0	1.15	46.7	2.81
28.3	14.0	1.15	46.8	2.81
28.3	14.1	1.15	46.9	2.82
28.4	14.1	1.16	47.1	2.83
29.2	14.2	1.19	47.2	2.84
29.2	14.2	1.19	47.3	2.84
29.2	14.2	1.19	47.4	2.85
29.2	14.3	1.19	47.5	2.86
29.2	14.3	1.19	47.7	2.86
29.2	14.3	1.19	47.8	2.87
29.2	14.4	1.19	47.9	2.88
29.2	14.4	1.19	48.0	2.89
29.2	14.4	1.19	48.1	2.89
29.2	14.5	1.19	48.3	2.90
29.2	14.5	1.19	48.4	2.91
29.2	14.5	1.19	48.5	2.91
29.2	14.6	1.19	48.6	2.92
29.2	14.6	1.19	48.7	2.93
29.2	14.7	1.19	48.9	2.94
30.0	14.7	1.22	49.0	2.94
30.0	14.7	1.22	49.1	2.95
30.0	14.8	1.22	49.2	2.96
30.0	14.8	1.22	49.3	2.96
30.0	14.8	1.22	49.5	2.97
30.0	14.9	1.22	49.6	2.98
30.0	14.9	1.22	49.7	2.99
30.0	14.9	1.22	49.8	2.99
30.0	15.0	1.22	49.9	3.00
30.5	15.0	1.24	50.1	3.01
30.0	15.1	1.22	50.2	3.01
30.5	15.1	1.24	50.3	3.02
30.0	15.1	1.22	50.4	3.03
30.8	15.2	1.25	50.5	3.04
30.8	15.2	1.25	50.7	3.04
30.8	15.2	1.25	50.8	3.05
30.8	15.3	1.25	50.9	3.06
30.8	15.3	1.25	51.0	3.06
31.3	15.3	1.28	51.1	3.07
30.8	15.4	1.25	51.3	3.08
30.8	15.4	1.25	51.4	3.09
31.4	15.4	1.28	51.5	3.09
30.8	15.5	1.25	51.6	3.10
31.3	15.5	1.27	51.7	3.11
30.8	15.6	1.25	51.8	3.12
31.7	15.6	1.29	52.0	3.12
31.7	15.6	1.29	52.1	3.13
31.7	15.7	1.29	52.2	3.14
31.7	15.7	1.29	52.3	3.14
31.7	15.7	1.29	52.4	3.15
31.7	15.8	1.29	52.6	3.16
31.7	15.8	1.29	52.7	3.17
31.7	15.8	1.29	52.8	3.17
31.7	15.9	1.29	52.9	3.18
32.5	15.9	1.32	53.0	3.19
31.7	15.9	1.29	53.2	3.19
31.7	16.0	1.29	53.3	3.20
31.7	16.0	1.29	53.4	3.21
32.5	16.1	1.32	53.5	3.22
32.5	16.1	1.32	53.6	3.22
32.5	16.1	1.32	53.8	3.23
32.5	16.2	1.32	53.9	3.24
32.5	16.2	1.32	54.0	3.24
32.5	16.2	1.32	54.1	3.25
32.5	16.3	1.32	54.2	3.26
33.3	16.3	1.36	54.4	3.27
32.5	16.3	1.32	54.5	3.27
32.5	16.4	1.32	54.6	3.28
33.3	16.4	1.36	54.7	3.29
33.3	16.4	1.36	54.8	3.29
33.3	16.5	1.36	55.0	3.30
33.3	16.5	1.36	55.1	3.31
33.3	16.6	1.36	55.2	3.32
33.3	16.6	1.36	55.3	3.32
33.3	16.6	1.36	55.4	3.33
33.3	16.7	1.36	55.5	3.34
33.3	16.7	1.36	55.7	3.34
33.3	16.7	1.36	55.8	3.35
33.3	16.8	1.36	55.9	3.36
33.3	16.8	1.36	56.0	3.37
34.2	16.8	1.39	56.1	3.37
34.2	16.9	1.39	56.3	3.38
33.9	16.9	1.38	56.4	3.39
34.2	17.0	1.39	56.5	3.39
34.2	17.0	1.39	56.6	3.40
34.2	17.0	1.39	56.7	3.41
34.2	17.1	1.39	56.9	3.42
34.2	17.1	1.39	57.0	3.42
34.2	17.1	1.39	57.1	3.43
34.2	17.2	1.39	57.2	3.44
34.2	17.2	1.39	57.3	3.44
34.2	17.2	1.39	57.5	3.45
35.0	17.3	1.42	57.6	3.46
35.0	17.3	1.42	57.7	3.47
35.0	17.3	1.42	57.8	3.47
35.0	17.4	1.42	57.9	3.48
35.0	17.4	1.42	58.1	3.49
35.0	17.5	1.42	58.2	3.49
35.0	17.5	1.42	58.3	3.50
35.0	17.5	1.42	58.4	3.51
35.0	17.6	1.42	58.5	3.52
35.0	17.6	1.42	58.7	3.52
35.0	17.6	1.42	58.8	3.53
35.0	17.7	1.42	58.9	3.54
35.0	17.7	1.42	59.0	3.55
35.8	17.7	1.46	59.1	3.55
35.8	17.8	1.46	59.3	3.56
35.8	17.8	1.46	59.4	3.57
35.8	17.8	1.46	59.5	3.57
35.8	17.9	1.46	59.6	3.58
35.8	17.9	1.46	59.7	3.59
35.8	18.0	1.46	59.9	3.60
35.8	18.0	1.46	60.0	3.60
35.8	18.0	1.46	60.1	3.61
35.8	18.1	1.46	60.2	3.62
35.8	18.1	1.46	60.3	3.62
35.8	18.1	1.46	60.5	3.63
35.8	18.2	1.46	60.6	3.64
36.7	18.2	1.49	60.7	3.65
36.5	18.2	1.49	60.8	3.65
36.7	18.3	1.49	60.9	3.66
36.7	18.3	1.49	61.0	3.67
36.7	18.3	1.49	61.2	3.67
36.7	18.4	1.49	61.3	3.68
36.7	18.4	1.49	61.4	3.69
36.7	18.5	1.49	61.5	3.70
36.7	18.5	1.49	61.6	3.70
36.7	18.5	1.49	61.8	3.71
37.5	18.6	1.53	61.9	3.72
37.5	18.6	1.53	62.0	3.72
37.5	18.6	1.53	62.1	3.73
36.7	18.7	1.49	62.2	3.74
37.5	18.7	1.53	62.4	3.75
37.5	18.7	1.53	62.5	3.75
37.5	18.8	1.53	62.6	3.76
37.5	18.8	1.53	62.7	3.77
37.5	18.9	1.53	62.8	3.77
37.5	18.9	1.53	63.0	3.78
37.5	18.9	1.53	63.1	3.79
37.5	19.0	1.53	63.2	3.80
37.7	19.0	1.53	63.3	3.80
38.0	19.0	1.55	63.4	3.81
38.3	19.1	1.56	63.6	3.82
37.9	19.1	1.54	63.7	3.82
38.3	19.1	1.56	63.8	3.83
38.3	19.2	1.56	63.9	3.84
38.3	19.2	1.56	64.0	3.85
38.3	19.2	1.56	64.1	3.85
38.3	19.3	1.56	64.3	3.86
38.3	19.3	1.56	64.4	3.87
38.3	19.4	1.56	64.5	3.87
38.3	19.4	1.56	64.6	3.88
38.3	19.4	1.56	64.7	3.89
38.3	19.5	1.56	64.9	3.90
39.2	19.5	1.59	65.0	3.90
38.3	19.5	1.56	65.1	3.91
39.2	19.6	1.59	65.2	3.92
39.2	19.6	1.59	65.3	3.93
39.2	19.6	1.59	65.5	3.93
39.2	19.7	1.59	65.6	3.94
39.2	19.7	1.59	65.7	3.95
39.2	19.7	1.59	65.8	3.95
39.2	19.8	1.59	65.9	3.96
39.2	19.8	1.59	66.1	3.97
39.2	19.9	1.59	66.2	3.98
40.0	19.9	1.63	66.3	3.98
39.7	19.9	1.62	66.4	3.99
40.0	20.0	1.63	66.5	4.00
40.0	20.0	1.63	66.7	4.00
40.0	20.0	1.63	66.8	4.01
40.0	20.1	1.63	66.9	4.02
40.0	20.1	1.63	67.0	4.03
40.0	20.1	1.63	67.1	4.03
40.0	20.2	1.63	67.3	4.04
40.0	20.2	1.63	67.4	4.05
40.0	20.2	1.63	67.5	4.05
40.0	20.3	1.63	67.6	4.06
40.0	20.3	1.63	67.7	4.07
40.0	20.4	1.63	67.9	4.08
40.8	20.4	1.66	68.0	4.08
40.8	20.4	1.66	68.1	4.09
40.0	20.5	1.63	68.2	4.10
40.8	20.5	1.66	68.3	4.10
40.8	20.5	1.66	68.5	4.11
40.8	20.6	1.66	68.6	4.12
40.8	20.6	1.66	68.7	4.13
40.8	20.6	1.66	68.8	4.13
40.8	20.7	1.66	68.9	4.14
40.8	20.7	1.66	69.1	4.15
40.8	20.8	1.66	69.2	4.15
40.8	20.8	1.66	69.3	4.16
40.9	20.8	1.66	69.4	4.17
41.7	20.9	1.70	69.5	4.18
40.8	20.9	1.66	69.6	4.18
41.7	20.9	1.70	69.8	4.19
41.7	21.0	1.70	69.9	4.20
41.7	21.0	1.70	70.0	4.20
41.7	21.0	1.70	70.1	4.21
41.7	21.1	1.70	70.2	4.22
42.1	21.1	1.71	70.4	4.23
41.7	21.1	1.70	70.5	4.23
41.7	21.2	1.70	70.6	4.24
42.4	21.2	1.73	70.7	4.25
42.5	21.3	1.73	70.8	4.25
42.2	21.3	1.72	71.0	4.26
42.5	21.3	1.73	71.1	4.27
42.5	21.4	1.73	71.2	4.28
42.5	21.4	1.73	71.3	4.28
42.5	21.4	1.73	71.4	4.29
42.5	21.5	1.73	71.6	4.30
42.5	21.5	1.73	71.7	4.30
42.5	21.5	1.73	71.8	4.31
42.5	21.6	1.73	71.9	4.32
42.5	21.6	1.73	72.0	4.33
42.5	21.6	1.73	72.2	4.33
42.5	21.7	1.73	72.3	4.34
42.7	21.7	1.74	72.4	4.35
43.1	21.8	1.76	72.5	4.36
43.3	21.8	1.76	72.6	4.36
43.3	21.8	1.76	72.8	4.37
43.3	21.9	1.76	72.9	4.38
43.3	21.9	1.76	73.0	4.38
43.3	21.9	1.76	73.1	4.39
43.3	22.0	1.76	73.2	4.40
43.3	22.0	1.76	73.4	4.41
43.3	22.0	1.76	73.5	4.41
43.3	22.1	1.76	73.6	4.42
43.3	22.1	1.76	73.7	4.43
43.3	22.1	1.76	73.8	4.43
43.3	22.2	1.76	73.9	4.44
44.2	22.2	1.80	74.1	4.45
44.2	22.3	1.80	74.2	4.46
43.3	22.3	1.76	74.3	4.46
44.2	22.3	1.80	74.4	4.47
44.2	22.4	1.80	74.5	4.48
44.2	22.4	1.80	74.7	4.48
44.2	22.4	1.80	74.8	4.49
44.2	22.5	1.80	74.9	4.50
44.2	22.5	1.80	75.0	4.51
44.2	22.5	1.80	75.1	4.51
44.2	22.6	1.80	75.3	4.52
45.0	22.6	1.83	75.4	4.53
45.0	22.7	1.83	75.5	4.53
45.0	22.7	1.83	75.6	4.54
45.0	22.7	1.83	75.7	4.55
45.0	22.8	1.83	75.9	4.56
45.0	22.8	1.83	76.0	4.56
45.0	22.8	1.83	76.1	4.57
45.0	22.9	1.83	76.2	4.58
45.0	22.9	1.83	76.3	4.58
45.0	22.9	1.83	76.5	4.59
45.0	23.0	1.83	76.6	4.60
45.8	23.0	1.86	76.7	4.61
45.3	23.0	1.84	76.8	4.61
45.8	23.1	1.86	76.9	4.62
45.8	23.1	1.86	77.1	4.63
45.8	23.2	1.86	77.2	4.63
45.8	23.2	1.86	77.3	4.64
45.8	23.2	1.86	77.4	4.65
45.8	23.3	1.86	77.5	4.66
45.8	23.3	1.86	77.7	4.66
45.8	23.3	1.86	77.8	4.67
45.8	23.4	1.86	77.9	4.68
45.9	23.4	1.87	78.0	4.68
46.3	23.4	1.89	78.1	4.69
45.8	23.5	1.86	78.3	4.70
45.8	23.5	1.86	78.4	4.71
46.7	23.5	1.90	78.5	4.71
46.7	23.6	1.90	78.6	4.72
46.7	23.6	1.90	78.7	4.73
46.7	23.7	1.90	78.8	4.74
46.7	23.7	1.90	79.0	4.74
46.7	23.7	1.90	79.1	4.75
46.7	23.8	1.90	79.2	4.76
47.2	23.8	1.92	79.3	4.76
46.7	23.8	1.90	79.4	4.77
47.5	23.9	1.93	79.6	4.78
47.5	23.9	1.93	79.7	4.79
46.7	23.9	1.90	79.8	4.79
47.5	24.0	1.93	79.9	4.80
47.5	24.0	1.93	80.0	4.81
47.5	24.0	1.93	80.2	4.81
47.5	24.1	1.93	80.3	4.82
47.5	24.1	1.93	80.4	4.83
47.5	24.2	1.93	80.5	4.84
47.5	24.2	1.93	80.6	4.84
47.5	24.2	1.93	80.8	4.85
47.5	24.3	1.93	80.9	4.86
48.1	24.3	1.96	81.0	4.86
47.5	24.3	1.93	81.1	4.87
48.3	24.4	1.97	81.2	4.88
48.3	24.4	1.97	81.4	4.89
48.3	24.4	1.97	81.5	4.89
48.3	24.5	1.97	81.6	4.90
48.3	24.5	1.97	81.7	4.91
48.3	24.6	1.97	81.8	4.91
48.3	24.6	1.97	82.0	4.92
48.3	24.6	1.97	82.1	4.93
48.3	24.7	1.97	82.2	4.94
48.3	24.7	1.97	82.3	4.94
48.3	24.7	1.97	82.4	4.95
48.3	24.8	1.97	82.6	4.96
49.2	24.8	2.00	82.7	4.96
49.2	24.8	2.00	82.8	4.97
49.2	24.9	2.00	82.9	4.98
49.2	24.9	2.00	83.0	4.99
49.2	24.9	2.00	83.1	4.99
49.2	25.0	2.00	83.3	5.00
49.2	25.0	2.00	83.4	5.01
49.2	25.1	2.00	83.5	5.01
49.2	25.1	2.00	83.6	5.02
49.2	25.1	2.00	83.7	5.03
49.2	25.2	2.00	83.9	5.04
50.0	25.2	2.03	84.0	5.04
50.0	25.2	2.03	84.1	5.05
50.0	25.3	2.03	84.2	5.06
50.0	25.3	2.03	84.3	5.06
50.0	25.3	2.03	84.5	5.07
50.0	25.4	2.03	84.6	5.08
50.0	25.4	2.03	84.7	5.09
50.0	25.4	2.03	84.8	5.09
50.0	25.5	2.03	84.9	5.10
50.0	25.5	2.03	85.1	5.11
50.0	25.6	2.03	85.2	5.11
50.0	25.6	2.03	85.3	5.12
50.8	25.6	2.07	85.4	5.13
50.8	25.7	2.07	85.5	5.14
50.8	25.7	2.07	85.7	5.14
50.8	25.7	2.07	85.8	5.15
50.8	25.8	2.07	85.9	5.16
50.8	25.8	2.07	86.0	5.17
51.6	25.8	2.10	86.1	5.17
50.8	25.9	2.07	86.3	5.18
50.8	25.9	2.07	86.4	5.19
50.8	25.9	2.07	86.5	5.19
51.7	26.0	2.10	86.6	5.20
51.7	26.0	2.10	86.7	5.21
51.7	26.1	2.10	86.9	5.22
51.7	26.1	2.10	87.0	5.22
51.7	26.1	2.10	87.1	5.23
51.7	26.2	2.10	87.2	5.24
51.7	26.2	2.10	87.3	5.24
51.7	26.2	2.10	87.4	5.25
51.7	26.3	2.10	87.6	5.26
52.5	26.3	2.14	87.7	5.27
52.5	26.3	2.14	87.8	5.27
52.5	26.4	2.14	87.9	5.28
52.5	26.4	2.14	88.0	5.29
52.5	26.4	2.14	88.2	5.29
52.5	26.5	2.14	88.3	5.30
52.5	26.5	2.14	88.4	5.31
52.5	26.6	2.14	88.5	5.32
52.5	26.6	2.14	88.6	5.32
52.5	26.6	2.14	88.8	5.33
52.5	26.7	2.14	88.9	5.34
52.5	26.7	2.14	89.0	5.34
52.5	26.7	2.14	89.1	5.35
53.1	26.8	2.16	89.2	5.36
52.5	26.8	2.14	89.4	5.37
53.2	26.8	2.17	89.5	5.37
53.3	26.9	2.17	89.6	5.38
53.3	26.9	2.17	89.7	5.39
53.3	27.0	2.17	89.8	5.39
53.3	27.0	2.17	90.0	5.40
53.3	27.0	2.17	90.1	5.41
53.3	27.1	2.17	90.2	5.42
53.3	27.1	2.17	90.3	5.42
53.3	27.1	2.17	90.4	5.43
53.3	27.2	2.17	90.6	5.44
54.2	27.2	2.20	90.7	5.44
54.2	27.2	2.20	90.8	5.45
53.3	27.3	2.17	90.9	5.46
54.2	27.3	2.20	91.0	5.47
54.2	27.3	2.20	91.2	5.47
54.2	27.4	2.20	91.3	5.48
54.2	27.4	2.20	91.4	5.49
54.2	27.5	2.20	91.5	5.49
54.2	27.5	2.20	91.6	5.50
54.2	27.5	2.20	91.7	5.51
54.2	27.6	2.20	91.9	5.52
54.2	27.6	2.20	92.0	5.52
55.0	27.6	2.24	92.1	5.53
54.2	27.7	2.20	92.2	5.54
54.2	27.7	2.20	92.3	5.55
55.0	27.7	2.24	92.5	5.55
55.0	27.8	2.24	92.6	5.56
55.0	27.8	2.24	92.7	5.57
55.0	27.8	2.24	92.8	5.57
55.0	27.9	2.24	92.9	5.58
55.0	27.9	2.24	93.1	5.59
55.0	28.0	2.24	93.2	5.60
55.0	28.0	2.24	93.3	5.60
55.0	28.0	2.24	93.4	5.61
55.0	28.1	2.24	93.5	5.62
55.8	28.1	2.27	93.7	5.62
55.8	28.1	2.27	93.8	5.63
55.0	28.2	2.24	93.9	5.64
55.8	28.2	2.27	94.0	5.65
55.8	28.2	2.27	94.1	5.65
55.8	28.3	2.27	94.3	5.66
55.8	28.3	2.27	94.4	5.67
55.8	28.3	2.27	94.5	5.67
55.8	28.4	2.27	94.6	5.68
55.8	28.4	2.27	94.7	5.69
55.8	28.5	2.27	94.9	5.70
55.8	28.5	2.27	95.0	5.70
55.8	28.5	2.27	95.1	5.71
56.4	28.6	2.30	95.2	5.72
55.8	28.6	2.27	95.3	5.72
56.7	28.6	2.31	95.5	5.73
56.7	28.7	2.31	95.6	5.74
56.7	28.7	2.31	95.7	5.75
56.7	28.7	2.31	95.8	5.75
56.7	28.8	2.31	95.9	5.76
56.7	28.8	2.31	96.1	5.77
56.7	28.9	2.31	96.2	5.77
56.7	28.9	2.31	96.3	5.78
56.7	28.9	2.31	96.4	5.79
56.7	29.0	2.31	96.5	5.80
56.7	29.0	2.31	96.6	5.80
57.5	29.0	2.34	96.8	5.81
56.7	29.1	2.31	96.9	5.82
56.7	29.1	2.31	97.0	5.82
57.5	29.1	2.34	97.1	5.83
57.5	29.2	2.34	97.2	5.84
57.5	29.2	2.34	97.4	5.85
57.5	29.2	2.34	97.5	5.85
57.5	29.3	2.34	97.6	5.86
57.5	29.3	2.34	97.7	5.87
57.5	29.4	2.34	97.8	5.87
57.5	29.4	2.34	98.0	5.88
57.5	29.4	2.34	98.1	5.89
57.5	29.5	2.34	98.2	5.90
57.5	29.5	2.34	98.3	5.90
58.3	29.5	2.37	98.4	5.91
58.3	29.6	2.37	98.6	5.92
57.5	29.6	2.34	98.7	5.93
58.3	29.6	2.37	98.8	5.93
58.3	29.7	2.37	98.9	5.94
58.3	29.7	2.37	99.0	5.95
58.3	29.7	2.37	99.2	5.95
58.3	29.8	2.37	99.3	5.96
58.3	29.8	2.37	99.4	5.97
58.3	29.9	2.37	99.5	5.98
59.2	29.9	2.41	99.6	5.98
58.3	29.9	2.37	99.8	5.99
59.2	30.0	2.41	99.9	6.00
59.2	30.0	2.41	100	6.00
59.2	30.0	2.41	100	6.01
59.2	30.1	2.41	100	6.02
59.2	30.1	2.41	100	6.03
59.2	30.1	2.41	100	6.03
59.2	30.2	2.41	101	6.04
59.2	30.2	2.41	101	6.05
59.9	30.2	2.44	101	6.05
59.2	30.3	2.41	101	6.06
60.0	30.3	2.44	101	6.07
60.0	30.4	2.44	101	6.08
60.0	30.4	2.44	101	6.08
59.2	30.4	2.41	101	6.09
60.0	30.5	2.44	102	6.10
60.0	30.5	2.44	102	6.10
60.0	30.5	2.44	102	6.11
60.0	30.6	2.44	102	6.12
60.0	30.6	2.44	102	6.13
60.0	30.6	2.44	102	6.13
60.0	30.7	2.44	102	6.14
60.0	30.7	2.44	102	6.15
60.0	30.8	2.44	103	6.15
60.0	30.8	2.44	103	6.16
60.6	30.8	2.47	103	6.17
60.8	30.9	2.48	103	6.18
60.8	30.9	2.48	103	6.18
60.8	30.9	2.48	103	6.19
60.8	31.0	2.48	103	6.20
60.8	31.0	2.48	103	6.20
60.8	31.0	2.48	103	6.21
60.8	31.1	2.48	104	6.22
60.8	31.1	2.48	104	6.23
60.8	31.1	2.48	104	6.23
60.8	31.2	2.48	104	6.24
60.8	31.2	2.48	104	6.25
61.7	31.3	2.51	104	6.25
60.8	31.3	2.48	104	6.26
61.7	31.3	2.51	104	6.27
61.7	31.4	2.51	105	6.28
61.7	31.4	2.51	105	6.28
61.7	31.4	2.51	105	6.29
61.7	31.5	2.51	105	6.30
61.7	31.5	2.51	105	6.30
61.7	31.5	2.51	105	6.31
61.7	31.6	2.51	105	6.32
61.7	31.6	2.51	105	6.33
61.7	31.6	2.51	105	6.33
62.5	31.7	2.54	106	6.34
62.5	31.7	2.54	106	6.35
62.5	31.8	2.54	106	6.36
62.5	31.8	2.54	106	6.36
62.5	31.8	2.54	106	6.37
62.5	31.9	2.54	106	6.38
62.5	31.9	2.54	106	6.38
62.5	31.9	2.54	106	6.39
62.5	32.0	2.54	107	6.40
62.5	32.0	2.54	107	6.41
63.3	32.0	2.58	107	6.41
62.5	32.1	2.54	107	6.42
62.5	32.1	2.54	107	6.43
62.5	32.1	2.54	107	6.43
63.3	32.2	2.58	107	6.44
63.3	32.2	2.58	107	6.45
63.3	32.3	2.58	108	6.46
62.5	32.3	2.54	108	6.46
63.3	32.3	2.58	108	6.47
63.3	32.4	2.58	108	6.48
63.3	32.4	2.58	108	6.48
63.3	32.4	2.58	108	6.49
63.3	32.5	2.58	108	6.50
64.2	32.5	2.61	108	6.51
63.3	32.5	2.58	108	6.51
64.2	32.6	2.61	109	6.52
64.2	32.6	2.61	109	6.53
64.2	32.7	2.61	109	6.53
64.2	32.7	2.61	109	6.54
64.2	32.7	2.61	109	6.55
64.2	32.8	2.61	109	6.56
64.2	32.8	2.61	109	6.56
64.2	32.8	2.61	109	6.57
64.2	32.9	2.61	110	6.58
64.2	32.9	2.61	110	6.58
64.2	32.9	2.61	110	6.59
65.0	33.0	2.64	110	6.60
64.2	33.0	2.61	110	6.61
65.0	33.0	2.64	110	6.61
65.0	33.1	2.64	110	6.62
65.0	33.1	2.64	110	6.63
65.0	33.2	2.64	111	6.63
65.0	33.2	2.64	111	6.64
65.0	33.2	2.64	111	6.65
65.0	33.3	2.64	111	6.66
65.0	33.3	2.64	111	6.66
65.0	33.3	2.64	111	6.67
65.0	33.4	2.64	111	6.68
65.8	33.4	2.68	111	6.68
65.8	33.4	2.68	111	6.69
65.8	33.5	2.68	112	6.70
65.8	33.5	2.68	112	6.71
65.8	33.5	2.68	112	6.71
65.8	33.6	2.68	112	6.72
65.8	33.6	2.68	112	6.73
65.8	33.7	2.68	112	6.74
65.8	33.7	2.68	112	6.74
65.8	33.7	2.68	112	6.75
65.8	33.8	2.68	113	6.76
66.1	33.8	2.69	113	6.76
66.7	33.8	2.71	113	6.77
66.7	33.9	2.71	113	6.78
66.7	33.9	2.71	113	6.79
66.7	33.9	2.71	113	6.79
66.7	34.0	2.71	113	6.80
66.7	34.0	2.71	113	6.81
66.7	34.0	2.71	113	6.81
66.7	34.1	2.71	114	6.82
66.7	34.1	2.71	114	6.83
66.7	34.2	2.71	114	6.84
66.7	34.2	2.71	114	6.84
66.7	34.2	2.71	114	6.85
66.7	34.3	2.71	114	6.86
66.7	34.3	2.71	114	6.86
66.7	34.3	2.71	114	6.87
67.5	34.4	2.75	115	6.88
67.5	34.4	2.75	115	6.89
67.5	34.4	2.75	115	6.89
67.5	34.5	2.75	115	6.90
67.5	34.5	2.75	115	6.91
67.5	34.6	2.75	115	6.91
67.5	34.6	2.75	115	6.92
67.5	34.6	2.75	115	6.93
67.5	34.7	2.75	116	6.94
67.5	34.7	2.75	116	6.94
67.5	34.7	2.75	116	6.95
67.5	34.8	2.75	116	6.96
68.3	34.8	2.78	116	6.96
68.3	34.8	2.78	116	6.97
67.5	34.9	2.75	116	6.98
68.3	34.9	2.78	116	6.99
68.3	34.9	2.78	116	6.99
68.3	35.0	2.78	117	7.00
68.3	35.0	2.78	117	7.01
68.3	35.1	2.78	117	7.01
68.3	35.1	2.78	117	7.02
68.3	35.1	2.78	117	7.03
68.3	35.2	2.78	117	7.04
69.2	35.2	2.81	117	7.04
69.2	35.2	2.81	117	7.05
69.2	35.3	2.81	118	7.06
69.2	35.3	2.81	118	7.06
69.2	35.3	2.81	118	7.07
69.2	35.4	2.81	118	7.08
69.2	35.4	2.81	118	7.09
69.2	35.4	2.81	118	7.09
69.2	35.5	2.81	118	7.10
69.2	35.5	2.81	118	7.11
69.2	35.6	2.81	119	7.11
69.2	35.6	2.81	119	7.12
69.2	35.6	2.81	119	7.13
69.2	35.7	2.81	119	7.14
70.0	35.7	2.85	119	7.14
69.6	35.7	2.83	119	7.15
69.9	35.8	2.85	119	7.16
70.0	35.8	2.85	119	7.17
70.0	35.8	2.85	119	7.17
70.0	35.9	2.85	120	7.18
70.0	35.9	2.85	120	7.19
70.0	35.9	2.85	120	7.19
70.0	36.0	2.85	120	7.20
70.0	36.0	2.85	120	7.21
70.0	36.1	2.85	120	7.22
70.0	36.1	2.85	120	7.22
70.0	36.1	2.85	120	7.23
70.0	36.2	2.85	121	7.24
70.0	36.2	2.85	121	7.24
70.8	36.2	2.88	121	7.25
70.8	36.3	2.88	121	7.26
70.8	36.3	2.88	121	7.27
70.8	36.3	2.88	121	7.27
70.2	36.4	2.86	121	7.28
70.8	36.4	2.88	121	7.29
70.8	36.4	2.88	121	7.29
70.8	36.5	2.88	122	7.30
70.8	36.5	2.88	122	7.31
70.8	36.6	2.88	122	7.32
70.8	36.6	2.88	122	7.32
71.7	36.6	2.92	122	7.33
71.7	36.7	2.92	122	7.34
71.7	36.7	2.92	122	7.34
71.3	36.7	2.90	122	7.35
71.7	36.8	2.92	123	7.36
71.7	36.8	2.92	123	7.37
71.7	36.8	2.92	123	7.37
71.7	36.9	2.92	123	7.38
71.7	36.9	2.92	123	7.39
71.7	37.0	2.92	123	7.39
71.7	37.0	2.92	123	7.40
71.7	37.0	2.92	123	7.41
71.7	37.1	2.92	124	7.42
71.7	37.1	2.92	124	7.42
72.5	37.1	2.95	124	7.43
72.5	37.2	2.95	124	7.44
71.7	37.2	2.92	124	7.44
72.5	37.2	2.95	124	7.45
72.5	37.3	2.95	124	7.46
72.5	37.3	2.95	124	7.47
72.5	37.3	2.95	124	7.47
72.5	37.4	2.95	125	7.48
72.5	37.4	2.95	125	7.49
72.5	37.5	2.95	125	7.49
72.5	37.5	2.95	125	7.50
73.3	37.5	2.98	125	7.51
73.3	37.6	2.98	125	7.52
73.3	37.6	2.98	125	7.52
73.3	37.6	2.98	125	7.53
73.3	37.7	2.98	126	7.54
73.3	37.7	2.98	126	7.55
73.3	37.7	2.98	126	7.55
73.3	37.8	2.98	126	7.56
73.3	37.8	2.98	126	7.57
73.3	37.8	2.98	126	7.57
73.5	37.9	2.99	126	7.58
73.3	37.9	2.98	126	7.59
73.3	38.0	2.98	127	7.60
74.2	38.0	3.02	127	7.60
73.3	38.0	2.98	127	7.61
74.2	38.1	3.02	127	7.62
74.2	38.1	3.02	127	7.62
74.2	38.1	3.02	127	7.63
74.2	38.2	3.02	127	7.64
74.2	38.2	3.02	127	7.65
74.2	38.2	3.02	127	7.65
74.2	38.3	3.02	128	7.66
74.2	38.3	3.02	128	7.67
74.2	38.3	3.02	128	7.67
75.0	38.4	3.05	128	7.68
75.0	38.4	3.05	128	7.69
75.0	38.5	3.05	128	7.70
75.0	38.5	3.05	128	7.70
75.0	38.5	3.05	128	7.71
75.0	38.6	3.05	129	7.72
75.0	38.6	3.05	129	7.72
75.0	38.6	3.05	129	7.73
75.0	38.7	3.05	129	7.74
75.0	38.7	3.05	129	7.75
75.0	38.7	3.05	129	7.75
75.8	38.8	3.09	129	7.76
75.0	38.8	3.05	129	7.77
75.8	38.9	3.09	130	7.77
75.8	38.9	3.09	130	7.78
75.8	38.9	3.09	130	7.79
75.8	39.0	3.09	130	7.80
75.8	39.0	3.09	130	7.80
75.8	39.0	3.09	130	7.81
75.8	39.1	3.09	130	7.82
75.8	39.1	3.09	130	7.82
75.8	39.1	3.09	130	7.83
76.7	39.2	3.12	131	7.84
76.6	39.2	3.12	131	7.85
76.7	39.2	3.12	131	7.85
76.7	39.3	3.12	131	7.86
76.7	39.3	3.12	131	7.87
76.7	39.4	3.12	131	7.87
76.7	39.4	3.12	131	7.88
76.7	39.4	3.12	131	7.89
76.7	39.5	3.12	132	7.90
76.7	39.5	3.12	132	7.90
76.7	39.5	3.12	132	7.91
76.7	39.6	3.12	132	7.92
76.7	39.6	3.12	132	7.92
76.7	39.6	3.12	132	7.93
77.5	39.7	3.15	132	7.94
77.5	39.7	3.15	132	7.95
77.5	39.7	3.15	132	7.95
77.5	39.8	3.15	133	7.96
77.5	39.8	3.15	133	7.97
77.5	39.9	3.15	133	7.98
77.5	39.9	3.15	133	7.98
77.5	39.9	3.15	133	7.99
77.5	40.0	3.15	133	8.00
78.3	40.0	3.19	133	8.00
77.5	40.0	3.15	133	8.01
78.3	40.1	3.19	134	8.02
78.3	40.1	3.19	134	8.03
78.3	40.1	3.19	134	8.03
78.3	40.2	3.19	134	8.04
78.3	40.2	3.19	134	8.05
78.3	40.2	3.19	134	8.05
78.3	40.3	3.19	134	8.06
78.3	40.3	3.19	134	8.07
78.3	40.4	3.19	135	8.08
78.3	40.4	3.19	135	8.08
78.9	40.4	3.21	135	8.09
78.3	40.5	3.19	135	8.10
78.3	40.5	3.19	135	8.10
79.2	40.5	3.22	135	8.11
78.3	40.6	3.19	135	8.12
79.2	40.6	3.22	135	8.13
79.2	40.6	3.22	135	8.13
79.2	40.7	3.22	136	8.14
79.2	40.7	3.22	136	8.15
79.2	40.8	3.22	136	8.15
79.2	40.8	3.22	136	8.16
79.2	40.8	3.22	136	8.17
79.2	40.9	3.22	136	8.18
79.2	40.9	3.22	136	8.18
79.2	40.9	3.22	136	8.19
80.0	41.0	3.26	137	8.20
79.2	41.0	3.22	137	8.20
80.0	41.0	3.26	137	8.21
80.0	41.1	3.26	137	8.22
80.0	41.1	3.26	137	8.23
80.0	41.1	3.26	137	8.23
80.0	41.2	3.26	137	8.24
80.0	41.2	3.26	137	8.25
80.0	41.3	3.26	138	8.25
80.0	41.3	3.26	138	8.26
80.0	41.3	3.26	138	8.27
80.0	41.4	3.26	138	8.28
80.0	41.4	3.26	138	8.28
80.0	41.4	3.26	138	8.29
80.8	41.5	3.29	138	8.30
80.8	41.5	3.29	138	8.30
80.0	41.5	3.26	138	8.31
80.8	41.6	3.29	139	8.32
80.8	41.6	3.29	139	8.33
80.8	41.6	3.29	139	8.33
80.8	41.7	3.29	139	8.34
80.8	41.7	3.29	139	8.35
80.8	41.8	3.29	139	8.36
80.8	41.8	3.29	139	8.36
80.8	41.8	3.29	139	8.37
80.8	41.9	3.29	140	8.38
80.8	41.9	3.29	140	8.38
81.7	41.9	3.32	140	8.39
81.7	42.0	3.32	140	8.40
81.7	42.0	3.32	140	8.41
81.7	42.0	3.32	140	8.41
81.7	42.1	3.32	140	8.42
81.7	42.1	3.32	140	8.43
81.7	42.1	3.32	140	8.43
81.7	42.2	3.32	141	8.44
81.7	42.2	3.32	141	8.45
81.7	42.3	3.32	141	8.46
81.7	42.3	3.32	141	8.46
81.7	42.3	3.32	141	8.47
81.7	42.4	3.32	141	8.48
82.5	42.4	3.36	141	8.48
82.5	42.4	3.36	141	8.49
82.5	42.5	3.36	142	8.50
82.5	42.5	3.36	142	8.51
82.5	42.5	3.36	142	8.51
82.5	42.6	3.36	142	8.52
82.5	42.6	3.36	142	8.53
82.5	42.7	3.36	142	8.53
82.5	42.7	3.36	142	8.54
82.5	42.7	3.36	142	8.55
82.5	42.8	3.36	143	8.56
82.5	42.8	3.36	143	8.56
82.5	42.8	3.36	143	8.57
82.5	42.9	3.36	143	8.58
82.5	42.9	3.36	143	8.58
83.3	42.9	3.39	143	8.59
83.3	43.0	3.39	143	8.60
82.5	43.0	3.36	143	8.61
83.3	43.0	3.39	143	8.61
83.3	43.1	3.39	144	8.62
83.3	43.1	3.39	144	8.63
83.3	43.2	3.39	144	8.63
83.3	43.2	3.39	144	8.64
83.3	43.2	3.39	144	8.65
83.7	43.3	3.40	144	8.66
83.3	43.3	3.39	144	8.66
84.2	43.3	3.42	144	8.67
84.2	43.4	3.42	145	8.68
83.3	43.4	3.39	145	8.68
84.1	43.4	3.42	145	8.69
84.2	43.5	3.42	145	8.70
84.2	43.5	3.42	145	8.71
84.2	43.5	3.42	145	8.71
84.2	43.6	3.42	145	8.72
84.2	43.6	3.42	145	8.73
84.2	43.7	3.42	146	8.73
84.2	43.7	3.42	146	8.74
84.2	43.7	3.42	146	8.75
84.2	43.8	3.42	146	8.76
85.0	43.8	3.46	146	8.76
85.0	43.8	3.46	146	8.77
84.2	43.9	3.42	146	8.78
84.7	43.9	3.45	146	8.79
84.4	43.9	3.43	146	8.79
85.0	44.0	3.46	147	8.80
85.0	44.0	3.46	147	8.81
85.0	44.0	3.46	147	8.81
85.0	44.1	3.46	147	8.82
85.0	44.1	3.46	147	8.83
85.0	44.2	3.46	147	8.84
85.0	44.2	3.46	147	8.84
85.0	44.2	3.46	147	8.85
85.0	44.3	3.46	148	8.86
85.0	44.3	3.46	148	8.86
85.0	44.3	3.46	148	8.87
85.8	44.4	3.49	148	8.88
85.8	44.4	3.49	148	8.89
85.8	44.4	3.49	148	8.89
-6.67	44.5	-0.271	148	8.90
-6.67	44.5	-0.271	148	8.91
-6.67	44.6	-0.271	149	8.91
-6.67	44.6	-0.271	149	8.92
-7.50	44.6	-0.305	149	8.93
-6.67	44.7	-0.271	149	8.94
-6.67	44.7	-0.271	149	8.94
-6.67	44.7	-0.271	149	8.95
-6.67	44.8	-0.271	149	8.96
-6.67	44.8	-0.271	149	8.96