File: Acadmics/4 semester/DESIGN LAB/UTM csv/pvc comp.csv
Force (N),Position (mm),Strain (%),Stress (MPa)
-0.833,0.00,0.00,-0.000620
25.0,0.0110,0.0110,0.0186
44.2,0.0220,0.0220,0.0329
62.5,0.0330,0.0330,0.0465
80.0,0.0440,0.0440,0.0595
100,0.0550,0.0550,0.0744
118,0.0660,0.0660,0.0880
138,0.0760,0.0760,0.103
162,0.0870,0.0870,0.120
186,0.0980,0.0980,0.138
212,0.109,0.109,0.157
239,0.120,0.120,0.178
268,0.131,0.131,0.199
297,0.142,0.142,0.221
328,0.153,0.153,0.244
359,0.164,0.164,0.267
392,0.175,0.175,0.291
426,0.186,0.186,0.317
463,0.197,0.197,0.344
498,0.208,0.208,0.370
534,0.218,0.218,0.397
570,0.229,0.229,0.424
603,0.240,0.240,0.449
637,0.251,0.251,0.474
669,0.262,0.262,0.498
704,0.273,0.273,0.524
741,0.284,0.284,0.551
778,0.295,0.295,0.578
817,0.306,0.306,0.608
857,0.317,0.317,0.637
893,0.328,0.328,0.665
930,0.338,0.338,0.692
966,0.350,0.350,0.719
1000,0.360,0.360,0.744
1030,0.371,0.371,0.768
1060,0.382,0.382,0.791
1090,0.393,0.393,0.814
1130,0.404,0.404,0.842
1170,0.415,0.415,0.874
1220,0.425,0.425,0.906
1260,0.436,0.436,0.941
1310,0.447,0.447,0.977
1360,0.458,0.458,1.02
1420,0.469,0.469,1.05
1470,0.480,0.480,1.10
1530,0.491,0.491,1.14
1600,0.501,0.501,1.19
1660,0.512,0.512,1.24
1730,0.523,0.523,1.29
1810,0.534,0.534,1.34
1880,0.545,0.545,1.40
1950,0.556,0.556,1.45
2030,0.567,0.567,1.51
2110,0.578,0.578,1.57
2180,0.588,0.588,1.63
2270,0.600,0.600,1.69
2350,0.610,0.610,1.75
2430,0.621,0.621,1.81
2520,0.632,0.632,1.87
2610,0.643,0.643,1.94
2690,0.654,0.654,2.00
2780,0.665,0.665,2.07
2870,0.676,0.676,2.14
2960,0.687,0.687,2.20
3050,0.698,0.698,2.27
3150,0.709,0.709,2.34
3240,0.720,0.720,2.41
3330,0.730,0.730,2.48
3430,0.741,0.741,2.55
3520,0.752,0.752,2.62
3620,0.763,0.763,2.69
3720,0.774,0.774,2.77
3820,0.785,0.785,2.84
3920,0.796,0.796,2.92
4020,0.807,0.807,2.99
4130,0.818,0.818,3.07
4230,0.828,0.828,3.14
4330,0.839,0.839,3.22
4430,0.850,0.850,3.30
4540,0.861,0.861,3.38
4650,0.872,0.872,3.46
4750,0.883,0.883,3.53
4860,0.894,0.894,3.61
4960,0.905,0.905,3.69
5070,0.915,0.915,3.77
5180,0.926,0.926,3.85
5290,0.937,0.937,3.93
5390,0.948,0.948,4.01
5500,0.959,0.959,4.09
5610,0.970,0.970,4.17
5720,0.981,0.981,4.25
5820,0.992,0.992,4.33
5930,1.00,1.00,4.42
6040,1.01,1.01,4.49
6150,1.02,1.02,4.57
6260,1.04,1.04,4.66
6370,1.05,1.05,4.74
6470,1.06,1.06,4.82
6580,1.07,1.07,4.90
6690,1.08,1.08,4.98
6800,1.09,1.09,5.06
6900,1.10,1.10,5.14
7010,1.11,1.11,5.21
7120,1.12,1.12,5.30
7240,1.14,1.14,5.39
7340,1.15,1.15,5.46
7450,1.16,1.16,5.54
7560,1.17,1.17,5.62
7670,1.18,1.18,5.70
7770,1.19,1.19,5.78
7880,1.20,1.20,5.86
7980,1.21,1.21,5.94
8090,1.22,1.22,6.02
8190,1.23,1.23,6.09
8300,1.24,1.24,6.17
8400,1.26,1.26,6.25
8500,1.27,1.27,6.33
8600,1.28,1.28,6.40
8710,1.29,1.29,6.48
8810,1.30,1.30,6.55
8900,1.31,1.31,6.62
9000,1.32,1.32,6.70
9090,1.33,1.33,6.77
9190,1.34,1.34,6.84
9280,1.35,1.35,6.91
9380,1.36,1.36,6.98
9470,1.37,1.37,7.04
9560,1.39,1.39,7.11
9650,1.40,1.40,7.18
9730,1.41,1.41,7.24
9820,1.42,1.42,7.31
9900,1.43,1.43,7.37
9990,1.44,1.44,7.43
10100,1.45,1.45,7.49
10200,1.46,1.46,7.56
10200,1.47,1.47,7.62
10300,1.48,1.48,7.67
10400,1.49,1.49,7.73
10500,1.51,1.51,7.79
10500,1.52,1.52,7.84
10600,1.53,1.53,7.89
10700,1.54,1.54,7.95
10800,1.55,1.55,8.00
10800,1.56,1.56,8.05
10900,1.57,1.57,8.10
11000,1.58,1.58,8.15
11000,1.59,1.59,8.20
11100,1.60,1.60,8.25
11100,1.61,1.61,8.29
11200,1.63,1.63,8.34
11300,1.64,1.64,8.38
11300,1.65,1.65,8.43
11400,1.66,1.66,8.47
11400,1.67,1.67,8.51
11500,1.68,1.68,8.55
11500,1.69,1.69,8.59
11600,1.70,1.70,8.63
11600,1.71,1.71,8.66
11700,1.72,1.72,8.70
11700,1.73,1.73,8.73
11800,1.75,1.75,8.76
11800,1.76,1.76,8.80
11900,1.77,1.77,8.83
11900,1.78,1.78,8.86
11900,1.79,1.79,8.89
12000,1.80,1.80,8.91
12000,1.81,1.81,8.94
12000,1.82,1.82,8.96
12100,1.83,1.83,8.99
12100,1.84,1.84,9.01
12100,1.85,1.85,9.04
12200,1.86,1.86,9.06
12200,1.88,1.88,9.08
12200,1.89,1.89,9.10
12300,1.90,1.90,9.12
12300,1.91,1.91,9.14
12300,1.92,1.92,9.15
12300,1.93,1.93,9.17
12300,1.94,1.94,9.18
12400,1.95,1.95,9.20
12400,1.96,1.96,9.21
12400,1.97,1.97,9.23
12400,1.98,1.98,9.24
12400,1.99,1.99,9.25
12400,2.01,2.01,9.26
12500,2.02,2.02,9.27
12500,2.03,2.03,9.28
12500,2.04,2.04,9.29
12500,2.05,2.05,9.30
12500,2.06,2.06,9.30
12500,2.07,2.07,9.31
12500,2.08,2.08,9.31
12500,2.09,2.09,9.32
12500,2.10,2.10,9.33
12500,2.11,2.11,9.33
12500,2.13,2.13,9.33
12600,2.14,2.14,9.34
12600,2.15,2.15,9.34
12600,2.16,2.16,9.34
12600,2.17,2.17,9.34
12600,2.18,2.18,9.34
12600,2.19,2.19,9.35
12600,2.20,2.20,9.35
12600,2.21,2.21,9.35
12600,2.22,2.22,9.35
12600,2.23,2.23,9.34
12600,2.25,2.25,9.34
12600,2.26,2.26,9.34
12600,2.27,2.27,9.34
12600,2.28,2.28,9.34
12500,2.29,2.29,9.34
12500,2.30,2.30,9.33
12500,2.31,2.31,9.33
12500,2.32,2.32,9.32
12500,2.33,2.33,9.32
12500,2.34,2.34,9.32
12500,2.35,2.35,9.31
12500,2.37,2.37,9.31
12500,2.38,2.38,9.30
12500,2.39,2.39,9.30
12500,2.40,2.40,9.29
12500,2.41,2.41,9.29
12500,2.42,2.42,9.28
12500,2.43,2.43,9.28
12500,2.44,2.44,9.27
12500,2.45,2.45,9.26
12400,2.46,2.46,9.26
12400,2.47,2.47,9.26
12400,2.48,2.48,9.25
12400,2.50,2.50,9.24
12400,2.51,2.51,9.24
12400,2.52,2.52,9.23
12400,2.53,2.53,9.22
12400,2.54,2.54,9.22
12400,2.55,2.55,9.21
12400,2.56,2.56,9.21
12400,2.57,2.57,9.20
12400,2.58,2.58,9.19
12300,2.59,2.59,9.19
12300,2.60,2.60,9.18
12300,2.62,2.62,9.17
12300,2.63,2.63,9.17
12300,2.64,2.64,9.16
12300,2.65,2.65,9.16
12300,2.66,2.66,9.15
12300,2.67,2.67,9.14
12300,2.68,2.68,9.14
12300,2.69,2.69,9.13
12300,2.70,2.70,9.12
12300,2.71,2.71,9.12
12200,2.72,2.72,9.11
12200,2.73,2.73,9.10
12200,2.75,2.75,9.10
12200,2.76,2.76,9.09
12200,2.77,2.77,9.09
12200,2.78,2.78,9.08
12200,2.79,2.79,9.07
12200,2.80,2.80,9.07
12200,2.81,2.81,9.06
12200,2.82,2.82,9.06
12200,2.83,2.83,9.05
12200,2.84,2.84,9.05
12200,2.85,2.85,9.04
12100,2.86,2.86,9.04
12100,2.88,2.88,9.03
12100,2.89,2.89,9.02
12100,2.90,2.90,9.02
12100,2.91,2.91,9.01
12100,2.92,2.92,9.01
12100,2.93,2.93,9.00
12100,2.94,2.94,9.00
12100,2.95,2.95,8.99
12100,2.96,2.96,8.99
12100,2.97,2.97,8.98
12100,2.98,2.98,8.98
12100,3.00,3.00,8.98
12100,3.01,3.01,8.97
12100,3.02,3.02,8.97
12000,3.03,3.03,8.96
12000,3.04,3.04,8.96
12000,3.05,3.05,8.96
12000,3.06,3.06,8.95
12000,3.07,3.07,8.95
12000,3.08,3.08,8.94
12000,3.09,3.09,8.94
12000,3.10,3.10,8.93
12000,3.11,3.11,8.93
12000,3.13,3.13,8.93
12000,3.14,3.14,8.92
12000,3.15,3.15,8.92
12000,3.16,3.16,8.91
12000,3.17,3.17,8.91
12000,3.18,3.18,8.91
12000,3.19,3.19,8.90
12000,3.20,3.20,8.90
12000,3.21,3.21,8.90
12000,3.22,3.22,8.89
11900,3.23,3.23,8.89
11900,3.25,3.25,8.89
11900,3.26,3.26,8.88
11900,3.27,3.27,8.88
11900,3.28,3.28,8.88
11900,3.29,3.29,8.87
11900,3.30,3.30,8.87
11900,3.31,3.31,8.87
11900,3.32,3.32,8.86
11900,3.33,3.33,8.86
11900,3.34,3.34,8.86
11900,3.35,3.35,8.86
11900,3.37,3.37,8.85
11900,3.38,3.38,8.85
11900,3.39,3.39,8.85
11900,3.40,3.40,8.85
11900,3.41,3.41,8.84
11900,3.42,3.42,8.84
11900,3.43,3.43,8.84
11900,3.44,3.44,8.84
11900,3.45,3.45,8.83
11900,3.46,3.46,8.83
11900,3.47,3.47,8.83
11900,3.48,3.48,8.83
11900,3.50,3.50,8.83
11900,3.51,3.51,8.82
11900,3.52,3.52,8.82
11900,3.53,3.53,8.82
11900,3.54,3.54,8.82
11800,3.55,3.55,8.82
11800,3.56,3.56,8.81
11800,3.57,3.57,8.81
11800,3.58,3.58,8.81
11800,3.59,3.59,8.81
11800,3.60,3.60,8.80
11800,3.61,3.61,8.80
11800,3.63,3.63,8.80
11800,3.64,3.64,8.80
11800,3.65,3.65,8.80
11800,3.66,3.66,8.80
11800,3.67,3.67,8.79
11800,3.68,3.68,8.79
11800,3.69,3.69,8.79
11800,3.70,3.70,8.79
11800,3.71,3.71,8.79
11800,3.72,3.72,8.79
11800,3.73,3.73,8.79
11800,3.75,3.75,8.78
11800,3.76,3.76,8.78
11800,3.77,3.77,8.78
11800,3.78,3.78,8.78
11800,3.79,3.79,8.78
11800,3.80,3.80,8.78
11800,3.81,3.81,8.78
11800,3.82,3.82,8.78
11800,3.83,3.83,8.78
11800,3.84,3.84,8.78
11800,3.85,3.85,8.77
11800,3.86,3.86,8.77
11800,3.88,3.88,8.77
11800,3.89,3.89,8.77
11800,3.90,3.90,8.77
11800,3.91,3.91,8.77
11800,3.92,3.92,8.77
11800,3.93,3.93,8.76
11800,3.94,3.94,8.76
11800,3.95,3.95,8.77
11800,3.96,3.96,8.76
11800,3.97,3.97,8.76
11800,3.98,3.98,8.76
11800,3.99,3.99,8.76
11800,4.01,4.01,8.76
11800,4.02,4.02,8.76
11800,4.03,4.03,8.76
11800,4.04,4.04,8.76
11800,4.05,4.05,8.76
11800,4.06,4.06,8.76
11800,4.07,4.07,8.76
11800,4.08,4.08,8.75
11800,4.09,4.09,8.75
11800,4.10,4.10,8.75
11800,4.11,4.11,8.75
11800,4.13,4.13,8.75
11800,4.14,4.14,8.75
11800,4.15,4.15,8.75
11800,4.16,4.16,8.75
11800,4.17,4.17,8.75
11800,4.18,4.18,8.75
11800,4.19,4.19,8.75
11800,4.20,4.20,8.75
11800,4.21,4.21,8.75
11800,4.22,4.22,8.75
11800,4.23,4.23,8.75
11800,4.24,4.24,8.75
11800,4.26,4.26,8.75
11800,4.27,4.27,8.75
11800,4.28,4.28,8.75
11800,4.29,4.29,8.74
11800,4.30,4.30,8.74
11800,4.31,4.31,8.74
11800,4.32,4.32,8.74
11800,4.33,4.33,8.74
11800,4.34,4.34,8.74
11800,4.35,4.35,8.74
11700,4.36,4.36,8.74
11800,4.38,4.38,8.74
11800,4.39,4.39,8.74
11700,4.40,4.40,8.74
11800,4.41,4.41,8.74
11700,4.42,4.42,8.74
11700,4.43,4.43,8.74
11700,4.44,4.44,8.74
11700,4.45,4.45,8.74
11700,4.46,4.46,8.74
11700,4.47,4.47,8.74
11700,4.48,4.48,8.74
11700,4.49,4.49,8.74
11700,4.51,4.51,8.74
11700,4.52,4.52,8.74
11800,4.53,4.53,8.74
11700,4.54,4.54,8.74
11700,4.55,4.55,8.74
11700,4.56,4.56,8.74
11700,4.57,4.57,8.74
11700,4.58,4.58,8.74
11700,4.59,4.59,8.74
11700,4.60,4.60,8.74
11700,4.61,4.61,8.74
11700,4.62,4.62,8.74
11700,4.64,4.64,8.74
11700,4.65,4.65,8.74
11700,4.66,4.66,8.74
11800,4.67,4.67,8.74
11800,4.68,4.68,8.74
11800,4.69,4.69,8.74
11800,4.70,4.70,8.74
11800,4.71,4.71,8.74
11800,4.72,4.72,8.74
11800,4.73,4.73,8.74
11800,4.74,4.74,8.74
11800,4.76,4.76,8.74
11800,4.77,4.77,8.74
11800,4.78,4.78,8.74
11800,4.79,4.79,8.75
11800,4.80,4.80,8.75
11800,4.81,4.81,8.75
11800,4.82,4.82,8.75
11800,4.83,4.83,8.74
11800,4.84,4.84,8.75
11800,4.85,4.85,8.75
11800,4.86,4.86,8.75
11800,4.87,4.87,8.75
11800,4.89,4.89,8.75
11800,4.90,4.90,8.75
11800,4.91,4.91,8.75
11800,4.92,4.92,8.75
11800,4.93,4.93,8.75
11800,4.94,4.94,8.75
11800,4.95,4.95,8.75
11800,4.96,4.96,8.75
11800,4.97,4.97,8.75
11800,4.98,4.98,8.75
11800,4.99,4.99,8.75
11800,5.01,5.01,8.75
11800,5.02,5.02,8.75
11800,5.03,5.03,8.75
11800,5.04,5.04,8.75
11800,5.05,5.05,8.75
11800,5.06,5.06,8.75
11800,5.07,5.07,8.75
11800,5.08,5.08,8.75
11800,5.09,5.09,8.75
11800,5.10,5.10,8.75
11800,5.11,5.11,8.75
11800,5.12,5.12,8.75
11800,5.14,5.14,8.75
11800,5.15,5.15,8.75
11800,5.16,5.16,8.75
11800,5.17,5.17,8.75
11800,5.18,5.18,8.76
11800,5.19,5.19,8.75
11800,5.20,5.20,8.75
11800,5.21,5.21,8.75
11800,5.22,5.22,8.75
11800,5.23,5.23,8.75
11800,5.24,5.24,8.76
11800,5.25,5.25,8.76
11800,5.27,5.27,8.76
11800,5.28,5.28,8.75
11800,5.29,5.29,8.76
11800,5.30,5.30,8.76
11800,5.31,5.31,8.75
11800,5.32,5.32,8.76
11800,5.33,5.33,8.76
11800,5.34,5.34,8.76
11800,5.35,5.35,8.76
11800,5.36,5.36,8.76
11800,5.37,5.37,8.76
11800,5.39,5.39,8.76
11800,5.40,5.40,8.76
11800,5.41,5.41,8.76
11800,5.42,5.42,8.76
11800,5.43,5.43,8.76
11800,5.44,5.44,8.76
11800,5.45,5.45,8.76
11800,5.46,5.46,8.76
11800,5.47,5.47,8.76
11800,5.48,5.48,8.76
11800,5.49,5.49,8.76
11800,5.50,5.50,8.76
11800,5.52,5.52,8.76
11800,5.53,5.53,8.76
11800,5.54,5.54,8.76
11800,5.55,5.55,8.76
11800,5.56,5.56,8.76
11800,5.57,5.57,8.77
11800,5.58,5.58,8.77
11800,5.59,5.59,8.77
11800,5.60,5.60,8.77
11800,5.61,5.61,8.77
11800,5.62,5.62,8.77
11800,5.64,5.64,8.77
11800,5.65,5.65,8.77
11800,5.66,5.66,8.77
11800,5.67,5.67,8.77
11800,5.68,5.68,8.77
11800,5.69,5.69,8.77
11800,5.70,5.70,8.77
11800,5.71,5.71,8.77
11800,5.72,5.72,8.77
11800,5.73,5.73,8.77
11800,5.74,5.74,8.77
11800,5.75,5.75,8.77
11800,5.77,5.77,8.77
11800,5.78,5.78,8.77
11800,5.79,5.79,8.77
11800,5.80,5.80,8.77
11800,5.81,5.81,8.77
11800,5.82,5.82,8.77
11800,5.83,5.83,8.78
11800,5.84,5.84,8.77
11800,5.85,5.85,8.78
11800,5.86,5.86,8.78
11800,5.87,5.87,8.78
11800,5.88,5.88,8.78
11800,5.90,5.90,8.78
11800,5.91,5.91,8.78
11800,5.92,5.92,8.78
11800,5.93,5.93,8.78
11800,5.94,5.94,8.78
11800,5.95,5.95,8.78
11800,5.96,5.96,8.78
11800,5.97,5.97,8.78
11800,5.98,5.98,8.78
11800,5.99,5.99,8.78
11800,6.00,6.00,8.78
11800,6.02,6.02,8.78
11800,6.03,6.03,8.78
11800,6.04,6.04,8.79
11800,6.05,6.05,8.78
11800,6.06,6.06,8.79
11800,6.07,6.07,8.79
11800,6.08,6.08,8.79
11800,6.09,6.09,8.79
11800,6.10,6.10,8.79
11800,6.11,6.11,8.79
11800,6.12,6.12,8.79
11800,6.13,6.13,8.79
11800,6.15,6.15,8.79
11800,6.16,6.16,8.79
11800,6.17,6.17,8.79
11800,6.18,6.18,8.79
11800,6.19,6.19,8.79
11800,6.20,6.20,8.79
11800,6.21,6.21,8.79
11800,6.22,6.22,8.79
11800,6.23,6.23,8.79
11800,6.24,6.24,8.79
11800,6.25,6.25,8.79
11800,6.26,6.26,8.79
11800,6.28,6.28,8.79
11800,6.29,6.29,8.79
11800,6.30,6.30,8.79
11800,6.31,6.31,8.79
11800,6.32,6.32,8.80
11800,6.33,6.33,8.79
11800,6.34,6.34,8.80
11800,6.35,6.35,8.80
11800,6.36,6.36,8.80
11800,6.37,6.37,8.80
11800,6.38,6.38,8.80
11800,6.40,6.40,8.80
11800,6.41,6.41,8.80
11800,6.42,6.42,8.80
11800,6.43,6.43,8.80
11800,6.44,6.44,8.80
11800,6.45,6.45,8.80
11800,6.46,6.46,8.80
11800,6.47,6.47,8.80
11800,6.48,6.48,8.80
11800,6.49,6.49,8.80
11800,6.50,6.50,8.80
11800,6.51,6.51,8.80
11800,6.53,6.53,8.80
11800,6.54,6.54,8.80
11800,6.55,6.55,8.80
11800,6.56,6.56,8.80
11800,6.57,6.57,8.80
11800,6.58,6.58,8.80
11800,6.59,6.59,8.80
11800,6.60,6.60,8.80
11800,6.61,6.61,8.80
11800,6.62,6.62,8.80
11800,6.63,6.63,8.80
11800,6.65,6.65,8.80
11800,6.66,6.66,8.81
11800,6.67,6.67,8.81
11800,6.68,6.68,8.81
11800,6.69,6.69,8.81
11800,6.70,6.70,8.81
11800,6.71,6.71,8.81
11800,6.72,6.72,8.81
11800,6.73,6.73,8.81
11800,6.74,6.74,8.81
11800,6.75,6.75,8.81
11800,6.76,6.76,8.81
11800,6.78,6.78,8.81
11800,6.79,6.79,8.81
11800,6.80,6.80,8.81
11800,6.81,6.81,8.81
11800,6.82,6.82,8.81
11800,6.83,6.83,8.81
11800,6.84,6.84,8.81
11800,6.85,6.85,8.81
11800,6.86,6.86,8.81
11800,6.87,6.87,8.81
11800,6.88,6.88,8.81
11800,6.89,6.89,8.81
11800,6.91,6.91,8.81
11800,6.92,6.92,8.81
11800,6.93,6.93,8.81
11800,6.94,6.94,8.81
11800,6.95,6.95,8.81
11800,6.96,6.96,8.81
11800,6.97,6.97,8.81
11800,6.98,6.98,8.81
11800,6.99,6.99,8.81
11800,7.00,7.00,8.81
11800,7.01,7.01,8.81
11800,7.03,7.03,8.81
11800,7.04,7.04,8.81
11800,7.05,7.05,8.81
11800,7.06,7.06,8.81
11800,7.07,7.07,8.81
11800,7.08,7.08,8.81
11800,7.09,7.09,8.81
11800,7.10,7.10,8.81
11800,7.11,7.11,8.81
11800,7.12,7.12,8.81
11800,7.13,7.13,8.81
11800,7.14,7.14,8.81
11800,7.16,7.16,8.81
11800,7.17,7.17,8.81
11800,7.18,7.18,8.81
11800,7.19,7.19,8.81
11800,7.20,7.20,8.81
11800,7.21,7.21,8.81
11800,7.22,7.22,8.81
11800,7.23,7.23,8.81
11800,7.24,7.24,8.81
11800,7.25,7.25,8.81
11800,7.26,7.26,8.81
11800,7.27,7.27,8.81
11800,7.29,7.29,8.81
11800,7.30,7.30,8.81
11800,7.31,7.31,8.81
11800,7.32,7.32,8.81
11800,7.33,7.33,8.81
11800,7.34,7.34,8.81
11800,7.35,7.35,8.81
11800,7.36,7.36,8.81
11800,7.37,7.37,8.81
11800,7.38,7.38,8.80
11800,7.39,7.39,8.81
11800,7.41,7.41,8.81
11800,7.42,7.42,8.80
11800,7.43,7.43,8.80
11800,7.44,7.44,8.80
11800,7.45,7.45,8.80
11800,7.46,7.46,8.80
11800,7.47,7.47,8.80
11800,7.48,7.48,8.80
11800,7.49,7.49,8.80
11800,7.50,7.50,8.80
11800,7.51,7.51,8.80
11800,7.52,7.52,8.80
11800,7.54,7.54,8.80
11800,7.55,7.55,8.80
11800,7.56,7.56,8.80
11800,7.57,7.57,8.80
11800,7.58,7.58,8.80
11800,7.59,7.59,8.80
11800,7.60,7.60,8.80
11800,7.61,7.61,8.80
11800,7.62,7.62,8.80
11800,7.63,7.63,8.80
11800,7.64,7.64,8.80
11800,7.65,7.65,8.80
11800,7.67,7.67,8.79
11800,7.68,7.68,8.79
11800,7.69,7.69,8.79
11800,7.70,7.70,8.79
11800,7.71,7.71,8.79
11800,7.72,7.72,8.79
11800,7.73,7.73,8.79
11800,7.74,7.74,8.79
11800,7.75,7.75,8.79
11800,7.76,7.76,8.79
11800,7.77,7.77,8.79
11800,7.79,7.79,8.79
11800,7.80,7.80,8.79
11800,7.81,7.81,8.79
11800,7.82,7.82,8.79
11800,7.83,7.83,8.79
11800,7.84,7.84,8.78
11800,7.85,7.85,8.78
11800,7.86,7.86,8.78
11800,7.87,7.87,8.78
11800,7.88,7.88,8.78
11800,7.89,7.89,8.78
11800,7.90,7.90,8.78
11800,7.92,7.92,8.78
11800,7.93,7.93,8.78
11800,7.94,7.94,8.78
11800,7.95,7.95,8.78
11800,7.96,7.96,8.77
11800,7.97,7.97,8.77
11800,7.98,7.98,8.77
11800,7.99,7.99,8.77
11800,8.00,8.00,8.77
11800,8.01,8.01,8.77
11800,8.02,8.02,8.77
11800,8.04,8.04,8.77
11800,8.05,8.05,8.77
11800,8.06,8.06,8.77
11800,8.07,8.07,8.76
11800,8.08,8.08,8.76
11800,8.09,8.09,8.76
11800,8.10,8.10,8.76
11800,8.11,8.11,8.76
11800,8.12,8.12,8.76
11800,8.13,8.13,8.76
11800,8.14,8.14,8.76
11800,8.15,8.15,8.76
11800,8.16,8.16,8.76
11800,8.18,8.18,8.75
11800,8.19,8.19,8.75
11800,8.20,8.20,8.75
11800,8.21,8.21,8.75
11800,8.22,8.22,8.75
11800,8.23,8.23,8.75
11800,8.24,8.24,8.75
11800,8.25,8.25,8.75
11800,8.26,8.26,8.75
11800,8.27,8.27,8.74
11800,8.28,8.28,8.74
11700,8.30,8.30,8.74
11700,8.31,8.31,8.74
11700,8.32,8.32,8.74
11700,8.33,8.33,8.74
11700,8.34,8.34,8.74
11700,8.35,8.35,8.74
11700,8.36,8.36,8.73
11700,8.37,8.37,8.73
11700,8.38,8.38,8.73
11700,8.39,8.39,8.73
11700,8.40,8.40,8.73
11700,8.41,8.41,8.73
11700,8.43,8.43,8.73
11700,8.44,8.44,8.72
11700,8.45,8.45,8.72
11700,8.46,8.46,8.72
11700,8.47,8.47,8.72
11700,8.48,8.48,8.72
11700,8.49,8.49,8.72
11700,8.50,8.50,8.71
11700,8.51,8.51,8.71
11700,8.52,8.52,8.71
11700,8.53,8.53,8.71
11700,8.55,8.55,8.71
11700,8.56,8.56,8.71
11700,8.57,8.57,8.71
11700,8.58,8.58,8.70
11700,8.59,8.59,8.70
11700,8.60,8.60,8.70
11700,8.61,8.61,8.70
11700,8.62,8.62,8.70
11700,8.63,8.63,8.70
11700,8.64,8.64,8.69
11700,8.65,8.65,8.69
11700,8.66,8.66,8.69
11700,8.68,8.68,8.69
11700,8.69,8.69,8.69
11700,8.70,8.70,8.68
11700,8.71,8.71,8.68
11700,8.72,8.72,8.68
11700,8.73,8.73,8.68
11700,8.74,8.74,8.68
11700,8.75,8.75,8.68
11700,8.76,8.76,8.67
11700,8.77,8.77,8.67
11700,8.78,8.78,8.67
11600,8.80,8.80,8.67
11600,8.81,8.81,8.67
11600,8.82,8.82,8.66
11600,8.83,8.83,8.66
11600,8.84,8.84,8.66
11600,8.85,8.85,8.66
11600,8.86,8.86,8.65
11600,8.87,8.87,8.65
11600,8.88,8.88,8.65
11600,8.89,8.89,8.65
11600,8.90,8.90,8.65
11600,8.91,8.91,8.64
11600,8.93,8.93,8.64
11600,8.94,8.94,8.64
11600,8.95,8.95,8.64
11600,8.96,8.96,8.63
11600,8.97,8.97,8.63
11600,8.98,8.98,8.63
11600,8.99,8.99,8.63
11600,9.00,9.00,8.62
11600,9.01,9.01,8.62
11600,9.02,9.02,8.62
11600,9.03,9.03,8.62
11600,9.05,9.05,8.61
11600,9.06,9.06,8.61
11600,9.07,9.07,8.61
11600,9.08,9.08,8.61
11600,9.09,9.09,8.60
11600,9.10,9.10,8.60
11600,9.11,9.11,8.60
11600,9.12,9.12,8.60
11500,9.13,9.13,8.59
11500,9.14,9.14,8.59
11500,9.15,9.15,8.59
11500,9.16,9.16,8.58
11500,9.18,9.18,8.58
11500,9.19,9.19,8.58
11500,9.20,9.20,8.58
11500,9.21,9.21,8.57
11500,9.22,9.22,8.57
11500,9.23,9.23,8.57
11500,9.24,9.24,8.57
11500,9.25,9.25,8.56
11500,9.26,9.26,8.56
11500,9.27,9.27,8.56
11500,9.28,9.28,8.55
11500,9.29,9.29,8.55
11500,9.31,9.31,8.55
11500,9.32,9.32,8.54
11500,9.33,9.33,8.54
11500,9.34,9.34,8.54
11500,9.35,9.35,8.53
11500,9.36,9.36,8.53
11500,9.37,9.37,8.52
11500,9.38,9.38,8.52
11500,9.39,9.39,8.52
11400,9.40,9.40,8.52
11400,9.41,9.41,8.51
11400,9.43,9.43,8.51
11400,9.44,9.44,8.51
11400,9.45,9.45,8.50
11400,9.46,9.46,8.50
11400,9.47,9.47,8.50
11400,9.48,9.48,8.49
11400,9.49,9.49,8.49
11400,9.50,9.50,8.49
11400,9.51,9.51,8.48
11400,9.52,9.52,8.48
11400,9.53,9.53,8.47
11400,9.54,9.54,8.47
11400,9.56,9.56,8.47
11400,9.57,9.57,8.46
11400,9.58,9.58,8.46
11400,9.59,9.59,8.45
11400,9.60,9.60,8.45
11400,9.61,9.61,8.45
11300,9.62,9.62,8.44
11300,9.63,9.63,8.44
11300,9.64,9.64,8.44
11300,9.65,9.65,8.43
11300,9.66,9.66,8.43
11300,9.67,9.67,8.42
11300,9.69,9.69,8.42
11300,9.70,9.70,8.41
11300,9.71,9.71,8.41
11300,9.72,9.72,8.40
11300,9.73,9.73,8.40
11300,9.74,9.74,8.39
11300,9.75,9.75,8.39
11300,9.76,9.76,8.39
11300,9.77,9.77,8.38
11300,9.78,9.78,8.38
11300,9.79,9.79,8.37
11200,9.81,9.81,8.37
11200,9.82,9.82,8.36
11200,9.83,9.83,8.36
11200,9.84,9.84,8.35
11200,9.85,9.85,8.35
11200,9.86,9.86,8.34
11200,9.87,9.87,8.34
11200,9.88,9.88,8.33
11200,9.89,9.89,8.33
11200,9.90,9.90,8.32
11200,9.91,9.91,8.32
11200,9.92,9.92,8.31
11200,9.94,9.94,8.31
11200,9.95,9.95,8.30
11100,9.96,9.96,8.30
11100,9.97,9.97,8.29
11100,9.98,9.98,8.28
11100,9.99,9.99,8.28
11100,10.0,10.0,8.27
11100,10.0,10.0,8.27
11100,10.0,10.0,8.26
11100,10.0,10.0,8.26
11100,10.0,10.0,8.25
11100,10.1,10.1,8.25
11100,10.1,10.1,8.24
11100,10.1,10.1,8.23
11100,10.1,10.1,8.23
11100,10.1,10.1,8.22
11000,10.1,10.1,8.22
11000,10.1,10.1,8.21
11000,10.1,10.1,8.20
11000,10.1,10.1,8.20
11000,10.2,10.2,8.19
11000,10.2,10.2,8.19
11000,10.2,10.2,8.18
11000,10.2,10.2,8.17
11000,10.2,10.2,8.17
11000,10.2,10.2,8.16
11000,10.2,10.2,8.15
11000,10.2,10.2,8.15
10900,10.2,10.2,8.14
10900,10.3,10.3,8.13
10900,10.3,10.3,8.13
10900,10.3,10.3,8.12
10900,10.3,10.3,8.12
10900,10.3,10.3,8.11
10900,10.3,10.3,8.10
10900,10.3,10.3,8.10
10900,10.3,10.3,8.09
10900,10.3,10.3,8.08
10900,10.3,10.3,8.08
10800,10.4,10.4,8.07
10800,10.4,10.4,8.06
10800,10.4,10.4,8.06
10800,10.4,10.4,8.05
10800,10.4,10.4,8.04
10800,10.4,10.4,8.04
10800,10.4,10.4,8.03
10800,10.4,10.4,8.02
10800,10.4,10.4,8.01
10800,10.5,10.5,8.01
10700,10.5,10.5,8.00
10700,10.5,10.5,7.99
10700,10.5,10.5,7.98
10700,10.5,10.5,7.98
10700,10.5,10.5,7.97
10700,10.5,10.5,7.96
10700,10.5,10.5,7.95
10700,10.5,10.5,7.94
10700,10.6,10.6,7.94
10700,10.6,10.6,7.93
10600,10.6,10.6,7.92
10600,10.6,10.6,7.91
10600,10.6,10.6,7.90
10600,10.6,10.6,7.89
10600,10.6,10.6,7.89
10600,10.6,10.6,7.88
10600,10.6,10.6,7.87
10600,10.7,10.7,7.86
10600,10.7,10.7,7.85
10500,10.7,10.7,7.84
10500,10.7,10.7,7.83
10500,10.7,10.7,7.83
10500,10.7,10.7,7.82
10500,10.7,10.7,7.81
10500,10.7,10.7,7.80
10500,10.7,10.7,7.79
10500,10.8,10.8,7.78
10400,10.8,10.8,7.77
10400,10.8,10.8,7.76
10400,10.8,10.8,7.75
10400,10.8,10.8,7.74
10400,10.8,10.8,7.73
10400,10.8,10.8,7.72
10400,10.8,10.8,7.71
10400,10.8,10.8,7.70
10300,10.8,10.8,7.69
10300,10.9,10.9,7.68
10300,10.9,10.9,7.67
10300,10.9,10.9,7.66
10300,10.9,10.9,7.65
10300,10.9,10.9,7.64
10300,10.9,10.9,7.63
10200,10.9,10.9,7.62
10200,10.9,10.9,7.61
10200,10.9,10.9,7.60
10200,11.0,11.0,7.59
10200,11.0,11.0,7.58
10200,11.0,11.0,7.57
10200,11.0,11.0,7.55
10100,11.0,11.0,7.54
10100,11.0,11.0,7.53
10100,11.0,11.0,7.52
10100,11.0,11.0,7.51
10100,11.0,11.0,7.50
10100,11.1,11.1,7.49
10000,11.1,11.1,7.47
10000,11.1,11.1,7.46
10000,11.1,11.1,7.45
10000,11.1,11.1,7.44
9980,11.1,11.1,7.43
9970,11.1,11.1,7.41
9950,11.1,11.1,7.40
9930,11.1,11.1,7.39
9920,11.2,11.2,7.38
9900,11.2,11.2,7.36
9880,11.2,11.2,7.35
9860,11.2,11.2,7.34
9850,11.2,11.2,7.33
9830,11.2,11.2,7.31
9810,11.2,11.2,7.30
9800,11.2,11.2,7.29
9780,11.2,11.2,7.27
9760,11.2,11.2,7.26
9740,11.3,11.3,7.25
9730,11.3,11.3,7.24
9710,11.3,11.3,7.22
9690,11.3,11.3,7.21
9670,11.3,11.3,7.20
9650,11.3,11.3,7.18
9630,11.3,11.3,7.17
9620,11.3,11.3,7.16
9600,11.3,11.3,7.14
9580,11.4,11.4,7.13
9560,11.4,11.4,7.11
9540,11.4,11.4,7.10
9520,11.4,11.4,7.09
9500,11.4,11.4,7.07
9480,11.4,11.4,7.06
9470,11.4,11.4,7.04
9450,11.4,11.4,7.03
9430,11.4,11.4,7.01
9410,11.5,11.5,7.00
9390,11.5,11.5,6.99
9370,11.5,11.5,6.97
9350,11.5,11.5,6.96
9330,11.5,11.5,6.94
9310,11.5,11.5,6.93
9290,11.5,11.5,6.91
9270,11.5,11.5,6.90
9250,11.5,11.5,6.88
9230,11.6,11.6,6.86
9200,11.6,11.6,6.85
9180,11.6,11.6,6.83
9160,11.6,11.6,6.82
9140,11.6,11.6,6.80
9120,11.6,11.6,6.78
9100,11.6,11.6,6.77
9080,11.6,11.6,6.75
9050,11.6,11.6,6.74
9030,11.7,11.7,6.72
9010,11.7,11.7,6.70
8990,11.7,11.7,6.69
8970,11.7,11.7,6.67
8940,11.7,11.7,6.65
8920,11.7,11.7,6.64
8900,11.7,11.7,6.62
8880,11.7,11.7,6.60
8860,11.7,11.7,6.59
8830,11.7,11.7,6.57
8810,11.8,11.8,6.56
8790,11.8,11.8,6.54
8770,11.8,11.8,6.52
8740,11.8,11.8,6.50
8720,11.8,11.8,6.49
8700,11.8,11.8,6.47
8670,11.8,11.8,6.45
8650,11.8,11.8,6.43
8630,11.8,11.8,6.42
8600,11.9,11.9,6.40
8580,11.9,11.9,6.38
8560,11.9,11.9,6.37
8530,11.9,11.9,6.35
8510,11.9,11.9,6.33
8480,11.9,11.9,6.31
8460,11.9,11.9,6.29
8440,11.9,11.9,6.28
8410,11.9,11.9,6.26
8390,12.0,12.0,6.24
8360,12.0,12.0,6.22
8340,12.0,12.0,6.20
8320,12.0,12.0,6.19
8290,12.0,12.0,6.17
8270,12.0,12.0,6.15
8240,12.0,12.0,6.13
8220,12.0,12.0,6.12
8200,12.0,12.0,6.10
8170,12.1,12.1,6.08
8150,12.1,12.1,6.06
8120,12.1,12.1,6.04
8100,12.1,12.1,6.02
8070,12.1,12.1,6.01
8050,12.1,12.1,5.99
8020,12.1,12.1,5.97
8000,12.1,12.1,5.95
7970,12.1,12.1,5.93
7950,12.2,12.2,5.92
7920,12.2,12.2,5.90
7900,12.2,12.2,5.88
7880,12.2,12.2,5.86
7850,12.2,12.2,5.84
7830,12.2,12.2,5.82
7800,12.2,12.2,5.80
7780,12.2,12.2,5.78
7750,12.2,12.2,5.77
7730,12.2,12.2,5.75
7700,12.3,12.3,5.73
7680,12.3,12.3,5.71
7650,12.3,12.3,5.69
7630,12.3,12.3,5.67
7600,12.3,12.3,5.65
7580,12.3,12.3,5.64
7550,12.3,12.3,5.62
7530,12.3,12.3,5.60
7500,12.3,12.3,5.58
7480,12.4,12.4,5.56
7450,12.4,12.4,5.54
7430,12.4,12.4,5.53
7400,12.4,12.4,5.51
7380,12.4,12.4,5.49
7350,12.4,12.4,5.47
7330,12.4,12.4,5.45
7300,12.4,12.4,5.43
7280,12.4,12.4,5.42
7250,12.5,12.5,5.40
7230,12.5,12.5,5.38
7210,12.5,12.5,5.36
7180,12.5,12.5,5.34
7160,12.5,12.5,5.32
7130,12.5,12.5,5.31
7110,12.5,12.5,5.29
7090,12.5,12.5,5.27
7060,12.5,12.5,5.25
7040,12.6,12.6,5.24
7010,12.6,12.6,5.22
6990,12.6,12.6,5.20
6970,12.6,12.6,5.18
6940,12.6,12.6,5.17
6920,12.6,12.6,5.15
6900,12.6,12.6,5.13
6870,12.6,12.6,5.11
6850,12.6,12.6,5.10
6830,12.7,12.7,5.08
6800,12.7,12.7,5.06
6780,12.7,12.7,5.04
6760,12.7,12.7,5.03
6740,12.7,12.7,5.01
6710,12.7,12.7,4.99
6690,12.7,12.7,4.98
6670,12.7,12.7,4.96
6650,12.7,12.7,4.95
6630,12.7,12.7,4.93
6600,12.8,12.8,4.91
6580,12.8,12.8,4.90
6560,12.8,12.8,4.88
6540,12.8,12.8,4.86
6520,12.8,12.8,4.85
6500,12.8,12.8,4.83
6480,12.8,12.8,4.82
6450,12.8,12.8,4.80
6430,12.8,12.8,4.79
6410,12.9,12.9,4.77
6390,12.9,12.9,4.76
6370,12.9,12.9,4.74
6360,12.9,12.9,4.73
6340,12.9,12.9,4.72
6330,12.9,12.9,4.71
6330,12.9,12.9,4.71
6320,12.9,12.9,4.70
6310,12.9,12.9,4.70
6300,13.0,13.0,4.69
6300,13.0,13.0,4.69
6290,13.0,13.0,4.68
6290,13.0,13.0,4.68
6280,13.0,13.0,4.67
6280,13.0,13.0,4.67
6270,13.0,13.0,4.67
6270,13.0,13.0,4.66
6260,13.0,13.0,4.66
6260,13.1,13.1,4.66
6250,13.1,13.1,4.65
6250,13.1,13.1,4.65
6250,13.1,13.1,4.65
6240,13.1,13.1,4.64
6240,13.1,13.1,4.64
6240,13.1,13.1,4.64
6230,13.1,13.1,4.64
6230,13.1,13.1,4.63
6230,13.2,13.2,4.63
6220,13.2,13.2,4.63
6220,13.2,13.2,4.63
6220,13.2,13.2,4.62
6210,13.2,13.2,4.62
6210,13.2,13.2,4.62
6210,13.2,13.2,4.62
6200,13.2,13.2,4.61
6200,13.2,13.2,4.61
6200,13.2,13.2,4.61
6190,13.3,13.3,4.61
6190,13.3,13.3,4.61
6190,13.3,13.3,4.60
6190,13.3,13.3,4.60
6180,13.3,13.3,4.60
6180,13.3,13.3,4.60
6180,13.3,13.3,4.60
6180,13.3,13.3,4.59
6170,13.3,13.3,4.59
6170,13.4,13.4,4.59
6170,13.4,13.4,4.59
6170,13.4,13.4,4.59
6160,13.4,13.4,4.59
6160,13.4,13.4,4.58
6160,13.4,13.4,4.58
6160,13.4,13.4,4.58
6160,13.4,13.4,4.58
6150,13.4,13.4,4.58
6150,13.5,13.5,4.58
6150,13.5,13.5,4.58
6150,13.5,13.5,4.57
6150,13.5,13.5,4.57
6150,13.5,13.5,4.57
6150,13.5,13.5,4.57
6150,13.5,13.5,4.57
6150,13.5,13.5,4.57
6150,13.5,13.5,4.58
6150,13.6,13.6,4.58
6160,13.6,13.6,4.58
6160,13.6,13.6,4.58
6160,13.6,13.6,4.58
6170,13.6,13.6,4.59
6170,13.6,13.6,4.59
6180,13.6,13.6,4.60
6180,13.6,13.6,4.60
6180,13.6,13.6,4.60
6190,13.7,13.7,4.61
6200,13.7,13.7,4.61
6200,13.7,13.7,4.61
6210,13.7,13.7,4.62
6210,13.7,13.7,4.62
6220,13.7,13.7,4.62
6220,13.7,13.7,4.63
6230,13.7,13.7,4.63
6230,13.7,13.7,4.64
6240,13.7,13.7,4.64
6250,13.8,13.8,4.65
6250,13.8,13.8,4.65
6260,13.8,13.8,4.66
6270,13.8,13.8,4.66
6270,13.8,13.8,4.67
6280,13.8,13.8,4.67
6280,13.8,13.8,4.68
6290,13.8,13.8,4.68
6300,13.8,13.8,4.68
6300,13.9,13.9,4.69
6310,13.9,13.9,4.69
6310,13.9,13.9,4.70
6320,13.9,13.9,4.70
6320,13.9,13.9,4.71
6330,13.9,13.9,4.71
6330,13.9,13.9,4.71
6340,13.9,13.9,4.72
6350,13.9,13.9,4.72
6350,14.0,14.0,4.72
6360,14.0,14.0,4.73
6360,14.0,14.0,4.73
6370,14.0,14.0,4.74
6370,14.0,14.0,4.74
6380,14.0,14.0,4.74
6380,14.0,14.0,4.75
6390,14.0,14.0,4.75
6390,14.0,14.0,4.76
6400,14.1,14.1,4.76
6400,14.1,14.1,4.76
6410,14.1,14.1,4.77
6420,14.1,14.1,4.78
6430,14.1,14.1,4.78
6430,14.1,14.1,4.79
6440,14.1,14.1,4.79
6450,14.1,14.1,4.80
6460,14.1,14.1,4.80
6470,14.1,14.1,4.81
6480,14.2,14.2,4.82
6490,14.2,14.2,4.83
6500,14.2,14.2,4.84
6510,14.2,14.2,4.85
6530,14.2,14.2,4.86
6540,14.2,14.2,4.87
6560,14.2,14.2,4.88
6600,14.2,14.2,4.91
6630,14.2,14.2,4.93
6670,14.3,14.3,4.96
6700,14.3,14.3,4.99
6750,14.3,14.3,5.02
6790,14.3,14.3,5.05
6830,14.3,14.3,5.08
6870,14.3,14.3,5.11
6920,14.3,14.3,5.15
6970,14.3,14.3,5.19
7020,14.3,14.3,5.23
7080,14.4,14.4,5.27
7130,14.4,14.4,5.31
7190,14.4,14.4,5.35
7240,14.4,14.4,5.39
7300,14.4,14.4,5.43
7350,14.4,14.4,5.47
7410,14.4,14.4,5.51
7470,14.4,14.4,5.56
7530,14.4,14.4,5.60
7580,14.5,14.5,5.64
7640,14.5,14.5,5.68
7700,14.5,14.5,5.73
7750,14.5,14.5,5.77
7810,14.5,14.5,5.81
7860,14.5,14.5,5.85
7920,14.5,14.5,5.89
7970,14.5,14.5,5.93
8030,14.5,14.5,5.97
8080,14.6,14.6,6.01
8130,14.6,14.6,6.05
8190,14.6,14.6,6.09
8240,14.6,14.6,6.13
8290,14.6,14.6,6.17
8340,14.6,14.6,6.21
8390,14.6,14.6,6.25
8440,14.6,14.6,6.28
8500,14.6,14.6,6.32
8540,14.6,14.6,6.36
8590,14.7,14.7,6.39
8640,14.7,14.7,6.43
8690,14.7,14.7,6.47
8740,14.7,14.7,6.50
8790,14.7,14.7,6.54
8830,14.7,14.7,6.57
8880,14.7,14.7,6.61
8930,14.7,14.7,6.64
8970,14.7,14.7,6.67
9020,14.8,14.8,6.71
9060,14.8,14.8,6.74
9100,14.8,14.8,6.77
9150,14.8,14.8,6.81
9190,14.8,14.8,6.84
9240,14.8,14.8,6.87
9280,14.8,14.8,6.90
9320,14.8,14.8,6.94
9360,14.8,14.8,6.97
9400,14.9,14.9,7.00
9450,14.9,14.9,7.03
9490,14.9,14.9,7.06
9530,14.9,14.9,7.09
9570,14.9,14.9,7.12
9610,14.9,14.9,7.15
9650,14.9,14.9,7.18
9700,14.9,14.9,7.21
9730,14.9,14.9,7.24
9780,15.0,15.0,7.27
9820,15.0,15.0,7.31
9860,15.0,15.0,7.34
9910,15.0,15.0,7.37
9950,15.0,15.0,7.40
9990,15.0,15.0,7.43
10000,15.0,15.0,7.47
10100,15.0,15.0,7.50
10100,15.0,15.0,7.53
10200,15.1,15.1,7.57
10200,15.1,15.1,7.60
10300,15.1,15.1,7.64
10300,15.1,15.1,7.67
10400,15.1,15.1,7.70
10400,15.1,15.1,7.74
10400,15.1,15.1,7.77
10500,15.1,15.1,7.81
10500,15.1,15.1,7.84
10600,15.1,15.1,7.87
10600,15.2,15.2,7.91
10700,15.2,15.2,7.94
10700,15.2,15.2,7.97
10800,15.2,15.2,8.00
10800,15.2,15.2,8.03
10800,15.2,15.2,8.07
10900,15.2,15.2,8.10
10900,15.2,15.2,8.13
11000,15.2,15.2,8.16
11000,15.3,15.3,8.19
11000,15.3,15.3,8.22
11100,15.3,15.3,8.25
11100,15.3,15.3,8.28
11200,15.3,15.3,8.31
11200,15.3,15.3,8.34
11200,15.3,15.3,8.37
11300,15.3,15.3,8.40
11300,15.3,15.3,8.42
11400,15.4,15.4,8.45
11400,15.4,15.4,8.48
11400,15.4,15.4,8.51
11500,15.4,15.4,8.53
11500,15.4,15.4,8.56
11500,15.4,15.4,8.59
11600,15.4,15.4,8.62
11600,15.4,15.4,8.64
11600,15.4,15.4,8.67
11700,15.5,15.5,8.70
11700,15.5,15.5,8.72
11800,15.5,15.5,8.75
11800,15.5,15.5,8.77
11800,15.5,15.5,8.80
11900,15.5,15.5,8.83
11900,15.5,15.5,8.85
11900,15.5,15.5,8.88
12000,15.5,15.5,8.90
12000,15.6,15.6,8.93
12000,15.6,15.6,8.95
12100,15.6,15.6,8.98
12100,15.6,15.6,9.00
12100,15.6,15.6,9.03
12200,15.6,15.6,9.06
12200,15.6,15.6,9.08
12200,15.6,15.6,9.11
12300,15.6,15.6,9.13
12300,15.6,15.6,9.16
12300,15.7,15.7,9.18
12400,15.7,15.7,9.21
12400,15.7,15.7,9.24
12400,15.7,15.7,9.26
12500,15.7,15.7,9.29
12500,15.7,15.7,9.33
12600,15.7,15.7,9.36
12600,15.7,15.7,9.38
12700,15.8,15.8,9.41
12700,15.8,15.8,9.44
12700,15.8,15.8,9.47
12800,15.8,15.8,9.49
12800,15.8,15.8,9.52
12800,15.8,15.8,9.55
12900,15.8,15.8,9.58
12900,15.8,15.8,9.61
12900,15.8,15.8,9.63
13000,15.9,15.9,9.66
13000,15.9,15.9,9.69
13100,15.9,15.9,9.72
13100,15.9,15.9,9.74
13100,15.9,15.9,9.77
13200,15.9,15.9,9.80
13200,15.9,15.9,9.83
13300,15.9,15.9,9.86
13300,15.9,15.9,9.89
13300,16.0,16.0,9.92
13400,16.0,16.0,9.95
13400,16.0,16.0,9.98
13500,16.0,16.0,10.0
13500,16.0,16.0,10.0
13500,16.0,16.0,10.1
13600,16.0,16.0,10.1
13600,16.0,16.0,10.1
13700,16.0,16.0,10.2
13700,16.0,16.0,10.2
13700,16.1,16.1,10.2
13800,16.1,16.1,10.3
13800,16.1,16.1,10.3
13900,16.1,16.1,10.3
13900,16.1,16.1,10.4
14000,16.1,16.1,10.4
14000,16.1,16.1,10.4
14100,16.1,16.1,10.5
14100,16.1,16.1,10.5
14200,16.2,16.2,10.5
14200,16.2,16.2,10.6
14300,16.2,16.2,10.6
14000,16.2,16.2,10.5
13800,16.2,16.2,10.3
13600,16.2,16.2,10.1
13400,16.2,16.2,9.99

-0.833,0.00,0.00,-0.00207
2.50,0.00300,0.00300,0.00620
9.17,0.00800,0.00800,0.0227
14.2,0.0120,0.0120,0.0351
18.3,0.0160,0.0160,0.0455
21.7,0.0200,0.0200,0.0537
25.0,0.0240,0.0240,0.0620
28.3,0.0280,0.0280,0.0702
31.7,0.0320,0.0320,0.0785
34.2,0.0360,0.0360,0.0847
36.7,0.0400,0.0400,0.0909
39.2,0.0440,0.0440,0.0971
42.5,0.0480,0.0480,0.105
44.2,0.0520,0.0520,0.110
47.5,0.0560,0.0560,0.118
50.8,0.0600,0.0600,0.126
53.3,0.0640,0.0640,0.132
56.7,0.0680,0.0680,0.140
59.2,0.0720,0.0720,0.147
62.5,0.0760,0.0760,0.155
65.8,0.0800,0.0800,0.163
69.2,0.0840,0.0840,0.171
73.3,0.0880,0.0880,0.182
76.7,0.0920,0.0920,0.190
79.2,0.0960,0.0960,0.196
81.7,0.101,0.101,0.202
84.2,0.105,0.105,0.209
88.3,0.109,0.109,0.219
92.5,0.113,0.113,0.229
95.8,0.117,0.117,0.238
100,0.121,0.121,0.248
103,0.125,0.125,0.256
107,0.129,0.129,0.264
111,0.133,0.133,0.275
114,0.137,0.137,0.283
118,0.141,0.141,0.293
123,0.145,0.145,0.304
127,0.149,0.149,0.314
131,0.153,0.153,0.324
135,0.157,0.157,0.335
139,0.161,0.161,0.345
143,0.165,0.165,0.355
148,0.169,0.169,0.368
153,0.173,0.173,0.378
158,0.177,0.177,0.390
162,0.181,0.181,0.401
168,0.185,0.185,0.415
173,0.189,0.189,0.428
178,0.193,0.193,0.440
183,0.197,0.197,0.452
188,0.201,0.201,0.467
193,0.205,0.205,0.479
199,0.210,0.210,0.494
205,0.214,0.214,0.508
211,0.218,0.218,0.523
216,0.222,0.222,0.535
222,0.226,0.226,0.550
228,0.230,0.230,0.564
233,0.234,0.234,0.576
238,0.238,0.238,0.591
245,0.242,0.242,0.607
251,0.246,0.246,0.622
257,0.250,0.250,0.636
263,0.254,0.254,0.653
268,0.258,0.258,0.665
275,0.262,0.262,0.682
281,0.266,0.266,0.696
287,0.270,0.270,0.711
293,0.274,0.274,0.727
299,0.278,0.278,0.742
305,0.282,0.282,0.756
312,0.286,0.286,0.773
317,0.290,0.290,0.785
323,0.294,0.294,0.800
328,0.298,0.298,0.814
334,0.302,0.302,0.829
340,0.306,0.306,0.843
346,0.310,0.310,0.857
353,0.314,0.314,0.874
358,0.318,0.318,0.888
364,0.322,0.322,0.903
371,0.326,0.326,0.919
377,0.330,0.330,0.934
383,0.334,0.334,0.948
390,0.338,0.338,0.967
397,0.343,0.343,0.983
403,0.347,0.347,0.998
409,0.351,0.351,1.01
415,0.355,0.355,1.03
422,0.359,0.359,1.05
428,0.363,0.363,1.06
433,0.366,0.366,1.07
440,0.371,0.371,1.09
447,0.375,0.375,1.11
453,0.379,0.379,1.12
458,0.383,0.383,1.14
464,0.387,0.387,1.15
469,0.391,0.391,1.16
475,0.395,0.395,1.18
480,0.399,0.399,1.19
486,0.403,0.403,1.20
491,0.407,0.407,1.22
495,0.411,0.411,1.23
501,0.415,0.415,1.24
505,0.419,0.419,1.25
509,0.423,0.423,1.26
514,0.427,0.427,1.27
518,0.431,0.431,1.28
523,0.435,0.435,1.30
527,0.439,0.439,1.31
530,0.443,0.443,1.31
534,0.447,0.447,1.32
538,0.451,0.451,1.33
541,0.455,0.455,1.34
543,0.459,0.459,1.35
546,0.463,0.463,1.35
548,0.467,0.467,1.36
552,0.472,0.472,1.37
555,0.476,0.476,1.38
559,0.480,0.480,1.39
563,0.484,0.484,1.39
568,0.488,0.488,1.41
571,0.492,0.492,1.42
574,0.496,0.496,1.42
578,0.500,0.500,1.43
582,0.504,0.504,1.44
584,0.508,0.508,1.45
587,0.512,0.512,1.45
588,0.516,0.516,1.46
590,0.520,0.520,1.46
593,0.524,0.524,1.47
595,0.528,0.528,1.48
598,0.532,0.532,1.48
600,0.536,0.536,1.49
603,0.540,0.540,1.50
608,0.544,0.544,1.51
611,0.548,0.548,1.51
614,0.552,0.552,1.52
618,0.556,0.556,1.53
620,0.560,0.560,1.54
623,0.564,0.564,1.54
624,0.568,0.568,1.55
626,0.572,0.572,1.55
628,0.576,0.576,1.56
629,0.580,0.580,1.56
630,0.584,0.584,1.56
633,0.588,0.588,1.57
634,0.592,0.592,1.57
636,0.596,0.596,1.58
638,0.600,0.600,1.58
640,0.604,0.604,1.59
641,0.608,0.608,1.59
643,0.612,0.612,1.59
644,0.616,0.616,1.60
646,0.620,0.620,1.60
647,0.624,0.624,1.60
648,0.628,0.628,1.61
649,0.632,0.632,1.61
650,0.636,0.636,1.61
652,0.640,0.640,1.62
653,0.644,0.644,1.62
654,0.648,0.648,1.62
656,0.652,0.652,1.63
658,0.657,0.657,1.63
658,0.660,0.660,1.63
661,0.665,0.665,1.64
662,0.669,0.669,1.64
663,0.673,0.673,1.64
665,0.677,0.677,1.65
666,0.681,0.681,1.65
667,0.685,0.685,1.65
668,0.689,0.689,1.66
670,0.693,0.693,1.66
672,0.697,0.697,1.67
673,0.701,0.701,1.67
674,0.705,0.705,1.67
676,0.709,0.709,1.68
677,0.713,0.713,1.68
678,0.717,0.717,1.68
679,0.721,0.721,1.68
680,0.725,0.725,1.69
683,0.729,0.729,1.69
683,0.733,0.733,1.69
684,0.737,0.737,1.70
686,0.741,0.741,1.70
687,0.745,0.745,1.70
688,0.749,0.749,1.71
689,0.753,0.753,1.71
690,0.757,0.757,1.71
692,0.761,0.761,1.71
693,0.765,0.765,1.72
693,0.769,0.769,1.72
694,0.773,0.773,1.72
695,0.777,0.777,1.72
696,0.781,0.781,1.73
698,0.785,0.785,1.73
698,0.789,0.789,1.73
699,0.793,0.793,1.73
701,0.797,0.797,1.74
702,0.801,0.801,1.74
703,0.805,0.805,1.74
704,0.810,0.810,1.75
705,0.814,0.814,1.75
707,0.818,0.818,1.75
708,0.821,0.821,1.75
708,0.825,0.825,1.76
710,0.830,0.830,1.76
711,0.834,0.834,1.76
713,0.838,0.838,1.77
714,0.842,0.842,1.77
715,0.846,0.846,1.77
717,0.850,0.850,1.78
718,0.854,0.854,1.78
718,0.858,0.858,1.78
720,0.862,0.862,1.79
721,0.866,0.866,1.79
723,0.870,0.870,1.79
723,0.874,0.874,1.79
724,0.878,0.878,1.80
726,0.882,0.882,1.80
727,0.886,0.886,1.80
728,0.890,0.890,1.81
729,0.894,0.894,1.81
731,0.898,0.898,1.81
732,0.902,0.902,1.81
733,0.906,0.906,1.82
734,0.910,0.910,1.82
735,0.914,0.914,1.82
737,0.918,0.918,1.83
738,0.922,0.922,1.83
738,0.927,0.927,1.83
740,0.931,0.931,1.83
741,0.935,0.935,1.84
742,0.939,0.939,1.84
743,0.943,0.943,1.84
743,0.947,0.947,1.84
745,0.951,0.951,1.85
746,0.955,0.955,1.85
748,0.959,0.959,1.85
748,0.963,0.963,1.85
748,0.967,0.967,1.86
750,0.971,0.971,1.86
750,0.975,0.975,1.86
752,0.979,0.979,1.86
753,0.983,0.983,1.87
753,0.987,0.987,1.87
754,0.991,0.991,1.87
755,0.995,0.995,1.87
756,0.999,0.999,1.87
757,1.00,1.00,1.88
758,1.01,1.01,1.88
758,1.01,1.01,1.88
759,1.02,1.02,1.88
760,1.02,1.02,1.88
760,1.02,1.02,1.88
761,1.03,1.03,1.89
761,1.03,1.03,1.89
763,1.04,1.04,1.89
763,1.04,1.04,1.89
763,1.04,1.04,1.89
764,1.05,1.05,1.89
764,1.05,1.05,1.89
764,1.06,1.06,1.89
765,1.06,1.06,1.90
766,1.07,1.07,1.90
766,1.07,1.07,1.90
767,1.07,1.07,1.90
767,1.08,1.08,1.90
768,1.08,1.08,1.90
768,1.09,1.09,1.90
768,1.09,1.09,1.90
770,1.09,1.09,1.91
770,1.10,1.10,1.91
770,1.10,1.10,1.91
772,1.11,1.11,1.91
772,1.11,1.11,1.91
773,1.11,1.11,1.92
774,1.12,1.12,1.92
774,1.12,1.12,1.92
775,1.13,1.13,1.92
776,1.13,1.13,1.92
776,1.13,1.13,1.92
777,1.14,1.14,1.93
778,1.14,1.14,1.93
778,1.15,1.15,1.93
779,1.15,1.15,1.93
780,1.16,1.16,1.93
781,1.16,1.16,1.94
782,1.16,1.16,1.94
782,1.17,1.17,1.94
783,1.17,1.17,1.94
783,1.18,1.18,1.94
783,1.18,1.18,1.94
784,1.18,1.18,1.94
785,1.19,1.19,1.95
786,1.19,1.19,1.95
787,1.20,1.20,1.95
787,1.20,1.20,1.95
788,1.20,1.20,1.95
788,1.21,1.21,1.95
789,1.21,1.21,1.96
790,1.22,1.22,1.96
791,1.22,1.22,1.96
792,1.22,1.22,1.96
793,1.23,1.23,1.97
793,1.23,1.23,1.97
794,1.24,1.24,1.97
795,1.24,1.24,1.97
796,1.25,1.25,1.97
796,1.25,1.25,1.97
798,1.25,1.25,1.98
798,1.26,1.26,1.98
799,1.26,1.26,1.98
800,1.27,1.27,1.98
800,1.27,1.27,1.98
801,1.27,1.27,1.99
802,1.28,1.28,1.99
803,1.28,1.28,1.99
803,1.29,1.29,1.99
804,1.29,1.29,1.99
805,1.29,1.29,2.00
806,1.30,1.30,2.00
806,1.30,1.30,2.00
808,1.31,1.31,2.00
808,1.31,1.31,2.00
808,1.31,1.31,2.00
810,1.32,1.32,2.01
811,1.32,1.32,2.01
811,1.33,1.33,2.01
812,1.33,1.33,2.01
813,1.34,1.34,2.01
813,1.34,1.34,2.02
814,1.34,1.34,2.02
815,1.35,1.35,2.02
816,1.35,1.35,2.02
816,1.36,1.36,2.02
817,1.36,1.36,2.02
818,1.36,1.36,2.03
818,1.37,1.37,2.03
818,1.37,1.37,2.03
820,1.38,1.38,2.03
820,1.38,1.38,2.03
821,1.38,1.38,2.04
823,1.39,1.39,2.04
823,1.39,1.39,2.04
823,1.40,1.40,2.04
824,1.40,1.40,2.04
825,1.40,1.40,2.05
826,1.41,1.41,2.05
826,1.41,1.41,2.05
828,1.42,1.42,2.05
828,1.42,1.42,2.05
828,1.43,1.43,2.05
829,1.43,1.43,2.06
830,1.43,1.43,2.06
831,1.44,1.44,2.06
832,1.44,1.44,2.06
833,1.45,1.45,2.06
833,1.45,1.45,2.06
834,1.45,1.45,2.07
835,1.46,1.46,2.07
835,1.46,1.46,2.07
837,1.47,1.47,2.07
837,1.47,1.47,2.07
838,1.47,1.47,2.08
838,1.48,1.48,2.08
839,1.48,1.48,2.08
840,1.49,1.49,2.08
841,1.49,1.49,2.08
841,1.49,1.49,2.08
843,1.50,1.50,2.09
843,1.50,1.50,2.09
843,1.51,1.51,2.09
844,1.51,1.51,2.09
844,1.51,1.51,2.09
846,1.52,1.52,2.10
846,1.52,1.52,2.10
846,1.53,1.53,2.10
848,1.53,1.53,2.10
848,1.53,1.53,2.10
848,1.54,1.54,2.10
849,1.54,1.54,2.11
849,1.55,1.55,2.11
851,1.55,1.55,2.11
851,1.55,1.55,2.11
852,1.56,1.56,2.11
853,1.56,1.56,2.11
853,1.57,1.57,2.12
854,1.57,1.57,2.12
854,1.57,1.57,2.12
855,1.58,1.58,2.12
856,1.58,1.58,2.12
856,1.59,1.59,2.12
857,1.59,1.59,2.12
858,1.59,1.59,2.13
858,1.60,1.60,2.13
858,1.60,1.60,2.13
859,1.61,1.61,2.13
859,1.61,1.61,2.13
860,1.61,1.61,2.13
862,1.62,1.62,2.14
862,1.62,1.62,2.14
863,1.63,1.63,2.14
863,1.63,1.63,2.14
864,1.63,1.63,2.14
865,1.64,1.64,2.14
865,1.64,1.64,2.14
866,1.65,1.65,2.15
867,1.65,1.65,2.15
867,1.66,1.66,2.15
868,1.66,1.66,2.15
868,1.66,1.66,2.15
869,1.67,1.67,2.15
870,1.67,1.67,2.16
871,1.68,1.68,2.16
872,1.68,1.68,2.16
872,1.68,1.68,2.16
873,1.69,1.69,2.16
873,1.69,1.69,2.17
874,1.70,1.70,2.17
875,1.70,1.70,2.17
876,1.70,1.70,2.17
877,1.71,1.71,2.17
878,1.71,1.71,2.18
878,1.72,1.72,2.18
878,1.72,1.72,2.18
880,1.72,1.72,2.18
880,1.73,1.73,2.18
881,1.73,1.73,2.18
882,1.74,1.74,2.19
[...]
11800,3.70,3.70,8.79
11800,3.71,3.71,8.79
11800,3.72,3.72,8.79
11800,3.74,3.74,8.78
11800,3.75,3.75,8.78
11800,3.76,3.76,8.78
11800,3.78,3.78,8.78
11800,3.79,3.79,8.78
11800,3.80,3.80,8.78
11800,3.82,3.82,8.78
11800,3.83,3.83,8.78
11800,3.84,3.84,8.77
11800,3.85,3.85,8.77
11800,3.87,3.87,8.77
11800,3.88,3.88,8.77
11800,3.89,3.89,8.77
11800,3.91,3.91,8.77
11800,3.92,3.92,8.77
11800,3.93,3.93,8.77
11800,3.95,3.95,8.77
11800,3.96,3.96,8.76
11800,3.97,3.97,8.76
11800,3.98,3.98,8.76
11800,4.00,4.00,8.76
11800,4.01,4.01,8.76
11800,4.02,4.02,8.76
11800,4.04,4.04,8.76
11800,4.05,4.05,8.76
11800,4.06,4.06,8.76
11800,4.07,4.07,8.75
11800,4.09,4.09,8.75
11800,4.10,4.10,8.75
11800,4.11,4.11,8.75
11800,4.13,4.13,8.75
11800,4.14,4.14,8.75
11800,4.15,4.15,8.75
11800,4.16,4.16,8.75
11800,4.18,4.18,8.75
11800,4.19,4.19,8.75
11800,4.20,4.20,8.75
11800,4.22,4.22,8.75
11800,4.23,4.23,8.75
11800,4.24,4.24,8.75
11800,4.26,4.26,8.75
11800,4.27,4.27,8.75
11800,4.28,4.28,8.74
11800,4.30,4.30,8.74
11800,4.31,4.31,8.74
11800,4.32,4.32,8.74
11800,4.33,4.33,8.74
11800,4.35,4.35,8.75
11800,4.36,4.36,8.74
11800,4.37,4.37,8.74
11800,4.39,4.39,8.74
11700,4.40,4.40,8.74
11800,4.41,4.41,8.74
11700,4.43,4.43,8.74
11700,4.44,4.44,8.74
11700,4.45,4.45,8.74
11700,4.46,4.46,8.74
11700,4.48,4.48,8.74
11700,4.49,4.49,8.74
11700,4.50,4.50,8.74
11700,4.52,4.52,8.74
11700,4.53,4.53,8.74
11700,4.54,4.54,8.74
11700,4.56,4.56,8.74
11700,4.57,4.57,8.74
11700,4.58,4.58,8.74
11700,4.59,4.59,8.74
11700,4.61,4.61,8.74
11700,4.62,4.62,8.74
11700,4.63,4.63,8.74
11700,4.65,4.65,8.74
11700,4.66,4.66,8.74
11700,4.67,4.67,8.74
11700,4.68,4.68,8.74
11700,4.70,4.70,8.74
11800,4.71,4.71,8.74
11800,4.72,4.72,8.74
11800,4.74,4.74,8.74
11800,4.75,4.75,8.75
11800,4.76,4.76,8.75
11800,4.78,4.78,8.75
11800,4.79,4.79,8.75
11800,4.80,4.80,8.74
11800,4.81,4.81,8.75
11800,4.83,4.83,8.74
11800,4.84,4.84,8.75
11800,4.85,4.85,8.75
11800,4.87,4.87,8.75
11800,4.88,4.88,8.75
11800,4.89,4.89,8.75
11800,4.91,4.91,8.75
11800,4.92,4.92,8.75
11800,4.93,4.93,8.75
11800,4.94,4.94,8.75
11800,4.96,4.96,8.75
11800,4.97,4.97,8.75
11800,4.98,4.98,8.75
11800,5.00,5.00,8.75
11800,5.01,5.01,8.75
11800,5.02,5.02,8.75
11800,5.04,5.04,8.75
11800,5.05,5.05,8.75
11800,5.06,5.06,8.75
11800,5.07,5.07,8.75
11800,5.09,5.09,8.75
11800,5.10,5.10,8.75
11800,5.11,5.11,8.75
11800,5.13,5.13,8.75
11800,5.14,5.14,8.75
11800,5.15,5.15,8.76
11800,5.17,5.17,8.75
11800,5.18,5.18,8.76
11800,5.19,5.19,8.76
11800,5.20,5.20,8.75
11800,5.22,5.22,8.75
11800,5.23,5.23,8.75
11800,5.24,5.24,8.76
11800,5.26,5.26,8.75
11800,5.27,5.27,8.75
11800,5.28,5.28,8.75
11800,5.29,5.29,8.76
11800,5.31,5.31,8.76
11800,5.32,5.32,8.76
11800,5.33,5.33,8.76
11800,5.35,5.35,8.76
11800,5.36,5.36,8.76
11800,5.37,5.37,8.76
11800,5.39,5.39,8.76
11800,5.40,5.40,8.76
11800,5.41,5.41,8.76
11800,5.42,5.42,8.76
11800,5.44,5.44,8.76
11800,5.45,5.45,8.76
11800,5.46,5.46,8.76
11800,5.48,5.48,8.76
11800,5.49,5.49,8.76
11800,5.50,5.50,8.76
11800,5.52,5.52,8.76
11800,5.53,5.53,8.76
11800,5.54,5.54,8.76
11800,5.55,5.55,8.77
11800,5.57,5.57,8.77
11800,5.58,5.58,8.77
11800,5.59,5.59,8.77
11800,5.61,5.61,8.77
11800,5.62,5.62,8.77
11800,5.63,5.63,8.77
11800,5.65,5.65,8.77
11800,5.66,5.66,8.77
11800,5.67,5.67,8.77
11800,5.68,5.68,8.77
11800,5.70,5.70,8.77
11800,5.71,5.71,8.77
11800,5.72,5.72,8.77
11800,5.74,5.74,8.77
11800,5.75,5.75,8.77
11800,5.76,5.76,8.77
11800,5.78,5.78,8.77
11800,5.79,5.79,8.77
11800,5.80,5.80,8.77
11800,5.81,5.81,8.77
11800,5.83,5.83,8.77
11800,5.84,5.84,8.78
11800,5.85,5.85,8.78
11800,5.87,5.87,8.78
11800,5.88,5.88,8.78
11800,5.89,5.89,8.78
11800,5.90,5.90,8.78
11800,5.92,5.92,8.78
11800,5.93,5.93,8.78
11800,5.94,5.94,8.78
11800,5.96,5.96,8.78
11800,5.97,5.97,8.78
11800,5.98,5.98,8.78
11800,6.00,6.00,8.78
11800,6.01,6.01,8.78
11800,6.02,6.02,8.78
11800,6.03,6.03,8.78
11800,6.05,6.05,8.78
11800,6.06,6.06,8.79
11800,6.07,6.07,8.79
11800,6.09,6.09,8.79
11800,6.10,6.10,8.79
11800,6.11,6.11,8.79
11800,6.13,6.13,8.79
11800,6.14,6.14,8.79
11800,6.15,6.15,8.79
11800,6.16,6.16,8.79
11800,6.18,6.18,8.79
11800,6.19,6.19,8.79
11800,6.20,6.20,8.79
11800,6.22,6.22,8.79
11800,6.23,6.23,8.79
11800,6.24,6.24,8.79
11800,6.26,6.26,8.79
11800,6.27,6.27,8.79
11800,6.28,6.28,8.79
11800,6.29,6.29,8.79
11800,6.31,6.31,8.79
11800,6.32,6.32,8.79
11800,6.33,6.33,8.80
11800,6.35,6.35,8.79
11800,6.36,6.36,8.80
11800,6.37,6.37,8.80
11800,6.39,6.39,8.80
11800,6.40,6.40,8.80
11800,6.41,6.41,8.80
11800,6.42,6.42,8.80
11800,6.44,6.44,8.80
11800,6.45,6.45,8.80
11800,6.46,6.46,8.80
11800,6.48,6.48,8.80
11800,6.49,6.49,8.80
11800,6.50,6.50,8.80
11800,6.52,6.52,8.80
11800,6.53,6.53,8.80
11800,6.54,6.54,8.80
11800,6.55,6.55,8.80
11800,6.57,6.57,8.81
11800,6.58,6.58,8.80
11800,6.59,6.59,8.80
11800,6.61,6.61,8.80
11800,6.62,6.62,8.80
11800,6.63,6.63,8.80
11800,6.64,6.64,8.80
11800,6.66,6.66,8.80
11800,6.67,6.67,8.80
11800,6.68,6.68,8.81
11800,6.70,6.70,8.81
11800,6.71,6.71,8.81
11800,6.72,6.72,8.81
11800,6.74,6.74,8.81
11800,6.75,6.75,8.81
11800,6.76,6.76,8.81
11800,6.77,6.77,8.81
11800,6.79,6.79,8.81
11800,6.80,6.80,8.81
11800,6.81,6.81,8.81
11800,6.83,6.83,8.81
11800,6.84,6.84,8.81
11800,6.85,6.85,8.81
11800,6.87,6.87,8.81
11800,6.88,6.88,8.81
11800,6.89,6.89,8.81
11800,6.90,6.90,8.81
11800,6.92,6.92,8.81
11800,6.93,6.93,8.81
11800,6.94,6.94,8.81
11800,6.96,6.96,8.81
11800,6.97,6.97,8.81
11800,6.98,6.98,8.81
11800,7.00,7.00,8.81
11800,7.01,7.01,8.81
11800,7.02,7.02,8.81
11800,7.03,7.03,8.81
11800,7.05,7.05,8.81
11800,7.06,7.06,8.81
11800,7.07,7.07,8.81
11800,7.09,7.09,8.81
11800,7.10,7.10,8.81
11800,7.11,7.11,8.81
11800,7.13,7.13,8.81
11800,7.14,7.14,8.81
11800,7.15,7.15,8.81
11800,7.16,7.16,8.81
11800,7.18,7.18,8.81
11800,7.19,7.19,8.81
11800,7.20,7.20,8.81
11800,7.22,7.22,8.81
11800,7.23,7.23,8.81
11800,7.24,7.24,8.81
11800,7.25,7.25,8.81
11800,7.27,7.27,8.81
11800,7.28,7.28,8.81
11800,7.29,7.29,8.81
11800,7.31,7.31,8.81
11800,7.32,7.32,8.81
11800,7.33,7.33,8.81
11800,7.35,7.35,8.81
11800,7.36,7.36,8.81
11800,7.37,7.37,8.81
11800,7.38,7.38,8.81
11800,7.40,7.40,8.81
11800,7.41,7.41,8.80
11800,7.42,7.42,8.80
11800,7.44,7.44,8.80
11800,7.45,7.45,8.80
11800,7.46,7.46,8.80
11800,7.48,7.48,8.80
11800,7.49,7.49,8.80
11800,7.50,7.50,8.80
11800,7.51,7.51,8.80
11800,7.53,7.53,8.80
11800,7.54,7.54,8.80
11800,7.55,7.55,8.80
11800,7.57,7.57,8.80
11800,7.58,7.58,8.80
11800,7.59,7.59,8.80
11800,7.61,7.61,8.80
11800,7.62,7.62,8.80
11800,7.63,7.63,8.80
11800,7.64,7.64,8.80
11800,7.66,7.66,8.79
11800,7.67,7.67,8.79
11800,7.68,7.68,8.79
11800,7.70,7.70,8.79
11800,7.71,7.71,8.79
11800,7.72,7.72,8.79
11800,7.74,7.74,8.79
11800,7.75,7.75,8.79
11800,7.76,7.76,8.79
11800,7.77,7.77,8.79
11800,7.79,7.79,8.79
11800,7.80,7.80,8.79
11800,7.81,7.81,8.78
11800,7.83,7.83,8.78
11800,7.84,7.84,8.78
11800,7.85,7.85,8.78
11800,7.86,7.86,8.78
11800,7.88,7.88,8.78
11800,7.89,7.89,8.78
11800,7.90,7.90,8.78
11800,7.92,7.92,8.78
11800,7.93,7.93,8.78
11800,7.94,7.94,8.78
11800,7.96,7.96,8.77
11800,7.97,7.97,8.77
11800,7.98,7.98,8.77
11800,7.99,7.99,8.77
11800,8.01,8.01,8.77
11800,8.02,8.02,8.77
11800,8.03,8.03,8.77
11800,8.05,8.05,8.77
11800,8.06,8.06,8.77
11800,8.07,8.07,8.76
11800,8.09,8.09,8.76
11800,8.10,8.10,8.76
11800,8.11,8.11,8.76
11800,8.12,8.12,8.76
11800,8.14,8.14,8.76
11800,8.15,8.15,8.76
11800,8.16,8.16,8.76
11800,8.18,8.18,8.75
11800,8.19,8.19,8.75
11800,8.20,8.20,8.75
11800,8.22,8.22,8.75
11800,8.23,8.23,8.75
11800,8.24,8.24,8.75
11800,8.25,8.25,8.75
11800,8.27,8.27,8.74
11800,8.28,8.28,8.74
11700,8.29,8.29,8.74
11700,8.31,8.31,8.74
11700,8.32,8.32,8.74
11700,8.33,8.33,8.74
11700,8.35,8.35,8.74
11700,8.36,8.36,8.73
11700,8.37,8.37,8.73
11700,8.38,8.38,8.73
11700,8.40,8.40,8.73
11700,8.41,8.41,8.73
11700,8.42,8.42,8.73
11700,8.44,8.44,8.72
11700,8.45,8.45,8.72
11700,8.46,8.46,8.72
11700,8.48,8.48,8.72
11700,8.49,8.49,8.72
11700,8.50,8.50,8.72
11700,8.51,8.51,8.71
11700,8.53,8.53,8.71
11700,8.54,8.54,8.71
11700,8.55,8.55,8.71
11700,8.57,8.57,8.71
11700,8.58,8.58,8.70
11700,8.59,8.59,8.70
11700,8.60,8.60,8.70
11700,8.62,8.62,8.70
11700,8.63,8.63,8.70
11700,8.64,8.64,8.69
11700,8.66,8.66,8.69
11700,8.67,8.67,8.69
11700,8.68,8.68,8.69
11700,8.70,8.70,8.69
11700,8.71,8.71,8.68
11700,8.72,8.72,8.68
11700,8.73,8.73,8.68
11700,8.75,8.75,8.68
11700,8.76,8.76,8.67
11700,8.77,8.77,8.67
11700,8.79,8.79,8.67
11600,8.80,8.80,8.67
11600,8.81,8.81,8.66
11600,8.83,8.83,8.66
11600,8.84,8.84,8.66
11600,8.85,8.85,8.66
11600,8.86,8.86,8.65
11600,8.88,8.88,8.65
11600,8.89,8.89,8.65
11600,8.90,8.90,8.65
11600,8.92,8.92,8.64
11600,8.93,8.93,8.64
11600,8.94,8.94,8.64
11600,8.96,8.96,8.64
11600,8.97,8.97,8.63
11600,8.98,8.98,8.63
11600,8.99,8.99,8.63
11600,9.01,9.01,8.62
11600,9.02,9.02,8.62
11600,9.03,9.03,8.62
11600,9.05,9.05,8.61
11600,9.06,9.06,8.61
11600,9.07,9.07,8.61
11600,9.09,9.09,8.61
11600,9.10,9.10,8.60
11600,9.11,9.11,8.60
11600,9.12,9.12,8.59
11500,9.14,9.14,8.59
11500,9.15,9.15,8.59
11500,9.16,9.16,8.59
11500,9.18,9.18,8.58
11500,9.19,9.19,8.58
11500,9.20,9.20,8.57
11500,9.22,9.22,8.57
11500,9.23,9.23,8.57
11500,9.24,9.24,8.57
11500,9.25,9.25,8.56
11500,9.27,9.27,8.56
11500,9.28,9.28,8.55
11500,9.29,9.29,8.55
11500,9.31,9.31,8.55
11500,9.32,9.32,8.54
11500,9.33,9.33,8.54
11500,9.34,9.34,8.53
11500,9.36,9.36,8.53
11500,9.37,9.37,8.52
11500,9.38,9.38,8.52
11400,9.40,9.40,8.52
11400,9.41,9.41,8.51
11400,9.42,9.42,8.51
11400,9.44,9.44,8.51
11400,9.45,9.45,8.51
11400,9.46,9.46,8.50
11400,9.47,9.47,8.50
11400,9.49,9.49,8.49
11400,9.50,9.50,8.49
11400,9.51,9.51,8.48
11400,9.53,9.53,8.48
11400,9.54,9.54,8.47
11400,9.55,9.55,8.47
11400,9.57,9.57,8.46
11400,9.58,9.58,8.46
11400,9.59,9.59,8.45
11400,9.60,9.60,8.45
11400,9.62,9.62,8.44
11300,9.63,9.63,8.44
11300,9.64,9.64,8.43
11300,9.66,9.66,8.43
11300,9.67,9.67,8.42
11300,9.68,9.68,8.42
11300,9.70,9.70,8.41
11300,9.71,9.71,8.41
11300,9.72,9.72,8.40
11300,9.73,9.73,8.40
11300,9.75,9.75,8.39
11300,9.76,9.76,8.39
11300,9.77,9.77,8.38
11300,9.79,9.79,8.37
11200,9.80,9.80,8.37
11200,9.81,9.81,8.36
11200,9.83,9.83,8.36
11200,9.84,9.84,8.35
11200,9.85,9.85,8.35
11200,9.86,9.86,8.34
11200,9.88,9.88,8.34
11200,9.89,9.89,8.33
11200,9.90,9.90,8.32
11200,9.92,9.92,8.32
11200,9.93,9.93,8.31
11200,9.94,9.94,8.30
11200,9.95,9.95,8.30
11100,9.97,9.97,8.29
11100,9.98,9.98,8.28
11100,9.99,9.99,8.28
11100,10.0,10.0,8.27
11100,10.0,10.0,8.26
11100,10.0,10.0,8.26
11100,10.0,10.0,8.25
11100,10.1,10.1,8.25
11100,10.1,10.1,8.24
11100,10.1,10.1,8.23
11100,10.1,10.1,8.22
11000,10.1,10.1,8.22
11000,10.1,10.1,8.21
11000,10.1,10.1,8.20
11000,10.1,10.1,8.19
11000,10.2,10.2,8.19
11000,10.2,10.2,8.18
11000,10.2,10.2,8.17
11000,10.2,10.2,8.16
11000,10.2,10.2,8.16
11000,10.2,10.2,8.15
10900,10.2,10.2,8.14
10900,10.3,10.3,8.13
10900,10.3,10.3,8.13
10900,10.3,10.3,8.12
10900,10.3,10.3,8.11
10900,10.3,10.3,8.10
10900,10.3,10.3,8.10
10900,10.3,10.3,8.09
10900,10.3,10.3,8.08
10800,10.4,10.4,8.07
10800,10.4,10.4,8.06
10800,10.4,10.4,8.05
10800,10.4,10.4,8.05
10800,10.4,10.4,8.04
10800,10.4,10.4,8.03
10800,10.4,10.4,8.02
10800,10.4,10.4,8.01
10800,10.5,10.5,8.00
10700,10.5,10.5,7.99
10700,10.5,10.5,7.98
10700,10.5,10.5,7.98
10700,10.5,10.5,7.97
10700,10.5,10.5,7.96
10700,10.5,10.5,7.95
10700,10.6,10.6,7.94
10700,10.6,10.6,7.93
10600,10.6,10.6,7.92
10600,10.6,10.6,7.91
10600,10.6,10.6,7.90
10600,10.6,10.6,7.89
10600,10.6,10.6,7.88
10600,10.6,10.6,7.87
10600,10.7,10.7,7.86
10500,10.7,10.7,7.85
10500,10.7,10.7,7.84
10500,10.7,10.7,7.83
10500,10.7,10.7,7.82
10500,10.7,10.7,7.81
10500,10.7,10.7,7.79
10500,10.7,10.7,7.78
10400,10.8,10.8,7.77
10400,10.8,10.8,7.76
10400,10.8,10.8,7.75
10400,10.8,10.8,7.74
10400,10.8,10.8,7.73
10400,10.8,10.8,7.71
10400,10.8,10.8,7.70
10300,10.9,10.9,7.69
10300,10.9,10.9,7.68
10300,10.9,10.9,7.67
10300,10.9,10.9,7.65
10300,10.9,10.9,7.64
10300,10.9,10.9,7.63
10200,10.9,10.9,7.62
10200,10.9,10.9,7.60
10200,11.0,11.0,7.59
10200,11.0,11.0,7.58
10200,11.0,11.0,7.56
10100,11.0,11.0,7.55
10100,11.0,11.0,7.54
10100,11.0,11.0,7.52
10100,11.0,11.0,7.51
10100,11.0,11.0,7.50
10100,11.1,11.1,7.48
10000,11.1,11.1,7.47
10000,11.1,11.1,7.45
10000,11.1,11.1,7.44
9980,11.1,11.1,7.42
9960,11.1,11.1,7.41
9940,11.1,11.1,7.40
9920,11.1,11.1,7.38
9900,11.2,11.2,7.37
9880,11.2,11.2,7.35
9860,11.2,11.2,7.34
9840,11.2,11.2,7.32
9820,11.2,11.2,7.30
9800,11.2,11.2,7.29
9780,11.2,11.2,7.27
9760,11.3,11.3,7.26
9730,11.3,11.3,7.24
9710,11.3,11.3,7.23
9690,11.3,11.3,7.21
9670,11.3,11.3,7.19
9650,11.3,11.3,7.18
9630,11.3,11.3,7.16
9610,11.3,11.3,7.15
9580,11.4,11.4,7.13
9560,11.4,11.4,7.11
9540,11.4,11.4,7.10
9520,11.4,11.4,7.08
9490,11.4,11.4,7.06
9470,11.4,11.4,7.05
9450,11.4,11.4,7.03
9420,11.4,11.4,7.01
9400,11.5,11.5,6.99
9370,11.5,11.5,6.98
9350,11.5,11.5,6.96
9330,11.5,11.5,6.94
9300,11.5,11.5,6.92
9280,11.5,11.5,6.90
9260,11.5,11.5,6.89
9230,11.6,11.6,6.87
9200,11.6,11.6,6.85
9180,11.6,11.6,6.83
9150,11.6,11.6,6.81
9130,11.6,11.6,6.79
9100,11.6,11.6,6.77
9080,11.6,11.6,6.75
9050,11.6,11.6,6.73
9020,11.7,11.7,6.71
9000,11.7,11.7,6.69
8970,11.7,11.7,6.68
8950,11.7,11.7,6.66
8920,11.7,11.7,6.64
8890,11.7,11.7,6.62
8870,11.7,11.7,6.60
8840,11.7,11.7,6.58
8810,11.8,11.8,6.56
8790,11.8,11.8,6.54
8760,11.8,11.8,6.52
8730,11.8,11.8,6.50
8700,11.8,11.8,6.47
8670,11.8,11.8,6.45
8650,11.8,11.8,6.43
8620,11.8,11.8,6.41
8590,11.9,11.9,6.39
8560,11.9,11.9,6.37
8530,11.9,11.9,6.35
8510,11.9,11.9,6.33
8480,11.9,11.9,6.31
8450,11.9,11.9,6.29
8420,11.9,11.9,6.27
8390,12.0,12.0,6.24
8360,12.0,12.0,6.22
8330,12.0,12.0,6.20
8310,12.0,12.0,6.18
8280,12.0,12.0,6.16
8250,12.0,12.0,6.14
8220,12.0,12.0,6.11
8190,12.0,12.0,6.09
8160,12.1,12.1,6.07
8130,12.1,12.1,6.05
8100,12.1,12.1,6.03
8070,12.1,12.1,6.01
8040,12.1,12.1,5.98
8010,12.1,12.1,5.96
7980,12.1,12.1,5.94
7950,12.1,12.1,5.92
7920,12.2,12.2,5.90
7900,12.2,12.2,5.87
7860,12.2,12.2,5.85
7830,12.2,12.2,5.83
7810,12.2,12.2,5.81
7780,12.2,12.2,5.79
7750,12.2,12.2,5.76
7720,12.3,12.3,5.74
7690,12.3,12.3,5.72
7660,12.3,12.3,5.70
7630,12.3,12.3,5.67
7600,12.3,12.3,5.65
7570,12.3,12.3,5.63
7540,12.3,12.3,5.61
7510,12.3,12.3,5.59
7480,12.4,12.4,5.56
7450,12.4,12.4,5.54
7420,12.4,12.4,5.52
7390,12.4,12.4,5.50
7360,12.4,12.4,5.48
7330,12.4,12.4,5.45
7300,12.4,12.4,5.43
7270,12.4,12.4,5.41
7240,12.5,12.5,5.39
7210,12.5,12.5,5.37
7180,12.5,12.5,5.35
7160,12.5,12.5,5.32
7130,12.5,12.5,5.30
7100,12.5,12.5,5.28
7070,12.5,12.5,5.26
7040,12.6,12.6,5.24
7010,12.6,12.6,5.22
6980,12.6,12.6,5.20
6960,12.6,12.6,5.18
6930,12.6,12.6,5.15
6900,12.6,12.6,5.13
6870,12.6,12.6,5.11
6850,12.6,12.6,5.09
6820,12.7,12.7,5.07
6790,12.7,12.7,5.05
6760,12.7,12.7,5.03
6740,12.7,12.7,5.01
6710,12.7,12.7,4.99
6680,12.7,12.7,4.97
6660,12.7,12.7,4.95
6630,12.7,12.7,4.93
6600,12.8,12.8,4.91
6580,12.8,12.8,4.89
6550,12.8,12.8,4.87
6530,12.8,12.8,4.86
6500,12.8,12.8,4.84
6480,12.8,12.8,4.82
6450,12.8,12.8,4.80
6430,12.8,12.8,4.78
6400,12.9,12.9,4.76
6380,12.9,12.9,4.75
6360,12.9,12.9,4.73
6340,12.9,12.9,4.72
6330,12.9,12.9,4.71
6320,12.9,12.9,4.70
6310,12.9,12.9,4.70
6310,13.0,13.0,4.69
6300,13.0,13.0,4.69
6290,13.0,13.0,4.68
6280,13.0,13.0,4.68
6280,13.0,13.0,4.67
6270,13.0,13.0,4.67
6270,13.0,13.0,4.66
6260,13.0,13.0,4.66
6260,13.1,13.1,4.65
6250,13.1,13.1,4.65
6250,13.1,13.1,4.65
6240,13.1,13.1,4.64
6240,13.1,13.1,4.64
6230,13.1,13.1,4.64
6230,13.1,13.1,4.64
6230,13.1,13.1,4.63
6220,13.2,13.2,4.63
6220,13.2,13.2,4.63
6210,13.2,13.2,4.62
6210,13.2,13.2,4.62
6210,13.2,13.2,4.62
6200,13.2,13.2,4.61
6200,13.2,13.2,4.61
6200,13.3,13.3,4.61
6190,13.3,13.3,4.61
6190,13.3,13.3,4.60
6190,13.3,13.3,4.60
6180,13.3,13.3,4.60
6180,13.3,13.3,4.60
6180,13.3,13.3,4.60
6170,13.3,13.3,4.59
6170,13.4,13.4,4.59
6170,13.4,13.4,4.59
6170,13.4,13.4,4.59
6160,13.4,13.4,4.59
6160,13.4,13.4,4.58
6160,13.4,13.4,4.58
6150,13.4,13.4,4.58
6150,13.4,13.4,4.58
6150,13.5,13.5,4.58
6150,13.5,13.5,4.58
6150,13.5,13.5,4.57
6150,13.5,13.5,4.57
6150,13.5,13.5,4.57
6150,13.5,13.5,4.57
6150,13.5,13.5,4.57
6150,13.6,13.6,4.58
6160,13.6,13.6,4.58
6160,13.6,13.6,4.58
6160,13.6,13.6,4.59
6170,13.6,13.6,4.59
6170,13.6,13.6,4.59
6180,13.6,13.6,4.60
6190,13.6,13.6,4.60
6190,13.7,13.7,4.61
6200,13.7,13.7,4.61
6200,13.7,13.7,4.62
6210,13.7,13.7,4.62
6220,13.7,13.7,4.63
6230,13.7,13.7,4.63
6230,13.7,13.7,4.64
6240,13.7,13.7,4.64
6250,13.8,13.8,4.65
6250,13.8,13.8,4.65
6260,13.8,13.8,4.66
6270,13.8,13.8,4.66
6280,13.8,13.8,4.67
6280,13.8,13.8,4.68
6290,13.8,13.8,4.68
6300,13.8,13.8,4.69
6300,13.9,13.9,4.69
6310,13.9,13.9,4.70
6320,13.9,13.9,4.70
6320,13.9,13.9,4.71
6330,13.9,13.9,4.71
6340,13.9,13.9,4.72
6340,13.9,13.9,4.72
6350,14.0,14.0,4.72
6360,14.0,14.0,4.73
6360,14.0,14.0,4.73
6370,14.0,14.0,4.74
6370,14.0,14.0,4.74
6380,14.0,14.0,4.75
6390,14.0,14.0,4.75
6390,14.0,14.0,4.76
6400,14.1,14.1,4.76
6410,14.1,14.1,4.77
6420,14.1,14.1,4.77
6430,14.1,14.1,4.78
6430,14.1,14.1,4.79
6440,14.1,14.1,4.79
6450,14.1,14.1,4.80
6470,14.1,14.1,4.81
6480,14.2,14.2,4.82
6490,14.2,14.2,4.83
6510,14.2,14.2,4.84
6520,14.2,14.2,4.85
6540,14.2,14.2,4.87
6560,14.2,14.2,4.88
6600,14.2,14.2,4.91
6640,14.3,14.3,4.94
6690,14.3,14.3,4.97
6730,14.3,14.3,5.01
6780,14.3,14.3,5.05
6840,14.3,14.3,5.09
6890,14.3,14.3,5.13
6950,14.3,14.3,5.17
7010,14.3,14.3,5.22
7070,14.4,14.4,5.26
7140,14.4,14.4,5.31
7200,14.4,14.4,5.36
7270,14.4,14.4,5.41
7340,14.4,14.4,5.46
7400,14.4,14.4,5.51
7470,14.4,14.4,5.56
7540,14.4,14.4,5.61
7610,14.5,14.5,5.66
7680,14.5,14.5,5.71
7740,14.5,14.5,5.76
7810,14.5,14.5,5.81
7880,14.5,14.5,5.86
7940,14.5,14.5,5.91
8010,14.5,14.5,5.96
8070,14.5,14.5,6.01
8140,14.6,14.6,6.05
8200,14.6,14.6,6.10
8260,14.6,14.6,6.15
8320,14.6,14.6,6.19
8380,14.6,14.6,6.24
8440,14.6,14.6,6.28
8500,14.6,14.6,6.33
8560,14.7,14.7,6.37
8620,14.7,14.7,6.41
8680,14.7,14.7,6.46
8740,14.7,14.7,6.50
8800,14.7,14.7,6.54
8850,14.7,14.7,6.59
8910,14.7,14.7,6.63
8960,14.7,14.7,6.67
9020,14.8,14.8,6.71
9070,14.8,14.8,6.75
9120,14.8,14.8,6.79
9170,14.8,14.8,6.83
9220,14.8,14.8,6.86
9270,14.8,14.8,6.90
9330,14.8,14.8,6.94
9380,14.8,14.8,6.98
9430,14.9,14.9,7.01
9480,14.9,14.9,7.05
9520,14.9,14.9,7.09
9570,14.9,14.9,7.12
9620,14.9,14.9,7.16
9670,14.9,14.9,7.20
9720,14.9,14.9,7.23
9770,15.0,15.0,7.27
9820,15.0,15.0,7.31
9870,15.0,15.0,7.35
9930,15.0,15.0,7.39
9980,15.0,15.0,7.42
10000,15.0,15.0,7.46
10100,15.0,15.0,7.50
10100,15.0,15.0,7.54
10200,15.1,15.1,7.58
10200,15.1,15.1,7.62
10300,15.1,15.1,7.66
10400,15.1,15.1,7.70
10400,15.1,15.1,7.74
10500,15.1,15.1,7.79
10500,15.1,15.1,7.83
10600,15.1,15.1,7.86
10600,15.2,15.2,7.90
10700,15.2,15.2,7.94
10700,15.2,15.2,7.98
10800,15.2,15.2,8.02
10800,15.2,15.2,8.06
10900,15.2,15.2,8.10
10900,15.2,15.2,8.13
11000,15.3,15.3,8.17
11000,15.3,15.3,8.20
11100,15.3,15.3,8.24
11100,15.3,15.3,8.27
11200,15.3,15.3,8.31
11200,15.3,15.3,8.35
11300,15.3,15.3,8.38
11300,15.3,15.3,8.42
11400,15.4,15.4,8.45
11400,15.4,15.4,8.48
11400,15.4,15.4,8.51
11500,15.4,15.4,8.55
11500,15.4,15.4,8.58
11600,15.4,15.4,8.61
11600,15.4,15.4,8.65
11700,15.4,15.4,8.67
11700,15.5,15.5,8.71
11700,15.5,15.5,8.74
11800,15.5,15.5,8.77
11800,15.5,15.5,8.80
11900,15.5,15.5,8.83
11900,15.5,15.5,8.86
12000,15.5,15.5,8.89
12000,15.5,15.5,8.92
12000,15.6,15.6,8.95
12100,15.6,15.6,8.98
12100,15.6,15.6,9.01
12200,15.6,15.6,9.05
12200,15.6,15.6,9.07
12200,15.6,15.6,9.11
12300,15.6,15.6,9.14
12300,15.7,15.7,9.17
12400,15.7,15.7,9.20
12400,15.7,15.7,9.23
12400,15.7,15.7,9.26
12500,15.7,15.7,9.29
12500,15.7,15.7,9.32
12600,15.7,15.7,9.36
12600,15.7,15.7,9.39
12700,15.8,15.8,9.42
12700,15.8,15.8,9.45
12700,15.8,15.8,9.48
12800,15.8,15.8,9.52
12800,15.8,15.8,9.55
12900,15.8,15.8,9.58
12900,15.8,15.8,9.62
13000,15.8,15.8,9.65
13000,15.9,15.9,9.68
13100,15.9,15.9,9.72
13100,15.9,15.9,9.75
13100,15.9,15.9,9.78
13200,15.9,15.9,9.82
13200,15.9,15.9,9.85
13300,15.9,15.9,9.89
13300,16.0,16.0,9.92
13400,16.0,16.0,9.96
13400,16.0,16.0,9.99
13500,16.0,16.0,10.0
13500,16.0,16.0,10.1
13600,16.0,16.0,10.1
13600,16.0,16.0,10.1
13700,16.0,16.0,10.2
13700,16.1,16.1,10.2
13800,16.1,16.1,10.3
13800,16.1,16.1,10.3
13900,16.1,16.1,10.3
13900,16.1,16.1,10.4
14000,16.1,16.1,10.4
14100,16.1,16.1,10.5
14100,16.1,16.1,10.5
14200,16.2,16.2,10.5
14200,16.2,16.2,10.6
14200,16.2,16.2,10.6
13900,16.2,16.2,10.3
13600,16.2,16.2,10.2
13400,16.2,16.2,9.99