File: Acadmics/4 semester/DESIGN LAB/UTM csv/wbc comp.csv
Force (N),Position (mm),Strain (%),Stress (MPa)
-2.50,0.00,0.00,-0.00620
0.833,0.00200,0.00200,0.00207
9.17,0.00700,0.00700,0.0227
15.0,0.0110,0.0110,0.0372
20.8,0.0150,0.0150,0.0517
25.0,0.0190,0.0190,0.0620
30.0,0.0230,0.0230,0.0744
35.8,0.0270,0.0270,0.0888
40.8,0.0310,0.0310,0.101
45.0,0.0350,0.0350,0.112
50.0,0.0390,0.0390,0.124
54.2,0.0430,0.0430,0.134
59.2,0.0470,0.0470,0.147
62.5,0.0520,0.0520,0.155
66.7,0.0550,0.0550,0.165
70.8,0.0600,0.0600,0.176
75.0,0.0640,0.0640,0.186
80.0,0.0670,0.0670,0.198
84.2,0.0720,0.0720,0.209
88.3,0.0760,0.0760,0.219
93.3,0.0800,0.0800,0.231
97.5,0.0840,0.0840,0.242
103,0.0880,0.0880,0.254
105,0.0920,0.0920,0.260
109,0.0960,0.0960,0.271
114,0.100,0.100,0.283
118,0.104,0.104,0.293
123,0.108,0.108,0.306
129,0.112,0.112,0.320
133,0.116,0.116,0.331
139,0.120,0.120,0.345
144,0.124,0.124,0.357
149,0.128,0.128,0.370
155,0.132,0.132,0.384
160,0.136,0.136,0.397
166,0.140,0.140,0.411
172,0.144,0.144,0.426
177,0.148,0.148,0.438
183,0.152,0.152,0.452
189,0.156,0.156,0.469
195,0.160,0.160,0.483
201,0.164,0.164,0.498
207,0.168,0.168,0.512
212,0.172,0.172,0.525
218,0.176,0.176,0.541
224,0.180,0.180,0.556
230,0.184,0.184,0.570
237,0.188,0.188,0.587
242,0.192,0.192,0.599
248,0.196,0.196,0.616
255,0.201,0.201,0.632
261,0.205,0.205,0.647
268,0.209,0.209,0.665
274,0.213,0.213,0.680
279,0.217,0.217,0.692
286,0.221,0.221,0.709
293,0.225,0.225,0.725
298,0.229,0.229,0.740
305,0.233,0.233,0.756
311,0.237,0.237,0.771
317,0.241,0.241,0.785
323,0.245,0.245,0.802
330,0.249,0.249,0.818
337,0.253,0.253,0.835
343,0.257,0.257,0.849
349,0.261,0.261,0.866
356,0.265,0.265,0.882
363,0.269,0.269,0.899
369,0.273,0.273,0.915
376,0.277,0.277,0.932
382,0.281,0.281,0.946
388,0.285,0.285,0.961
394,0.289,0.289,0.977
400,0.293,0.293,0.992
408,0.298,0.298,1.01
413,0.302,0.302,1.02
420,0.306,0.306,1.04
426,0.310,0.310,1.06
433,0.313,0.313,1.07
439,0.317,0.317,1.09
445,0.322,0.322,1.10
450,0.326,0.326,1.12
457,0.330,0.330,1.13
463,0.334,0.334,1.15
468,0.338,0.338,1.16
475,0.342,0.342,1.18
480,0.346,0.346,1.19
486,0.350,0.350,1.20
492,0.354,0.354,1.22
497,0.358,0.358,1.23
502,0.362,0.362,1.25
507,0.366,0.366,1.26
511,0.370,0.370,1.27
516,0.374,0.374,1.28
523,0.378,0.378,1.30
529,0.382,0.382,1.31
536,0.386,0.386,1.33
542,0.390,0.390,1.34
549,0.394,0.394,1.36
554,0.398,0.398,1.37
559,0.402,0.402,1.39
563,0.406,0.406,1.39
566,0.410,0.410,1.40
568,0.414,0.414,1.41
570,0.418,0.418,1.41
575,0.422,0.422,1.43
583,0.426,0.426,1.44
590,0.430,0.430,1.46
598,0.434,0.434,1.48
604,0.438,0.438,1.50
610,0.442,0.442,1.51
617,0.446,0.446,1.53
622,0.450,0.450,1.54
626,0.454,0.454,1.55
630,0.458,0.458,1.56
634,0.463,0.463,1.57
637,0.466,0.466,1.58
640,0.471,0.471,1.59
642,0.475,0.475,1.59
643,0.479,0.479,1.59
644,0.483,0.483,1.60
644,0.487,0.487,1.60
645,0.491,0.491,1.60
647,0.495,0.495,1.60
648,0.499,0.499,1.61
651,0.503,0.503,1.61
653,0.507,0.507,1.62
656,0.511,0.511,1.63
659,0.515,0.515,1.63
662,0.519,0.519,1.64
664,0.523,0.523,1.65
668,0.527,0.527,1.65
670,0.531,0.531,1.66
673,0.535,0.535,1.67
676,0.539,0.539,1.68
678,0.543,0.543,1.68
682,0.547,0.547,1.69
685,0.551,0.551,1.70
688,0.555,0.555,1.71
691,0.559,0.559,1.71
693,0.563,0.563,1.72
696,0.567,0.567,1.73
698,0.571,0.571,1.73
701,0.575,0.575,1.74
703,0.579,0.579,1.74
706,0.583,0.583,1.75
708,0.587,0.587,1.76
711,0.591,0.591,1.76
713,0.595,0.595,1.77
715,0.599,0.599,1.77
718,0.603,0.603,1.78
719,0.607,0.607,1.78
722,0.611,0.611,1.79
723,0.615,0.615,1.79
726,0.619,0.619,1.80
728,0.623,0.623,1.81
729,0.627,0.627,1.81
731,0.631,0.631,1.81
733,0.635,0.635,1.82
734,0.639,0.639,1.82
736,0.643,0.643,1.82
738,0.647,0.647,1.83
739,0.652,0.652,1.83
741,0.656,0.656,1.84
742,0.660,0.660,1.84
744,0.664,0.664,1.85
745,0.668,0.668,1.85
747,0.672,0.672,1.85
748,0.676,0.676,1.86
750,0.680,0.680,1.86
752,0.684,0.684,1.86
753,0.688,0.688,1.87
753,0.692,0.692,1.87
755,0.696,0.696,1.87
756,0.700,0.700,1.87
757,0.704,0.704,1.88
758,0.708,0.708,1.88
759,0.712,0.712,1.88
759,0.716,0.716,1.88
761,0.720,0.720,1.89
762,0.724,0.724,1.89
763,0.728,0.728,1.89
763,0.732,0.732,1.89
764,0.736,0.736,1.89
765,0.740,0.740,1.90
766,0.744,0.744,1.90
766,0.748,0.748,1.90
768,0.752,0.752,1.90
768,0.756,0.756,1.90
768,0.760,0.760,1.90
769,0.764,0.764,1.91
770,0.768,0.768,1.91
771,0.772,0.772,1.91
772,0.776,0.776,1.91
772,0.780,0.780,1.91
773,0.784,0.784,1.92
773,0.788,0.788,1.92
774,0.792,0.792,1.92
775,0.796,0.796,1.92
775,0.800,0.800,1.92
776,0.804,0.804,1.92
777,0.808,0.808,1.93
778,0.812,0.812,1.93
778,0.816,0.816,1.93
779,0.821,0.821,1.93
779,0.824,0.824,1.93
780,0.828,0.828,1.93
779,0.832,0.832,1.93
781,0.837,0.837,1.94
781,0.841,0.841,1.94
781,0.845,0.845,1.94
782,0.849,0.849,1.94
782,0.853,0.853,1.94
782,0.857,0.857,1.94
783,0.861,0.861,1.94
783,0.865,0.865,1.94
783,0.869,0.869,1.94
783,0.873,0.873,1.94
784,0.877,0.877,1.94
785,0.881,0.881,1.95
785,0.885,0.885,1.95
786,0.889,0.889,1.95
787,0.893,0.893,1.95
788,0.897,0.897,1.95
788,0.901,0.901,1.95
789,0.905,0.905,1.96
789,0.909,0.909,1.96
791,0.913,0.913,1.96
791,0.917,0.917,1.96
792,0.921,0.921,1.96
792,0.925,0.925,1.96
793,0.929,0.929,1.96
793,0.933,0.933,1.96
793,0.937,0.937,1.97
794,0.941,0.941,1.97
794,0.945,0.945,1.97
795,0.949,0.949,1.97
795,0.953,0.953,1.97
796,0.957,0.957,1.97
797,0.961,0.961,1.98
796,0.965,0.965,1.97
797,0.969,0.969,1.98
797,0.973,0.973,1.98
797,0.977,0.977,1.98
798,0.981,0.981,1.98
798,0.985,0.985,1.98
798,0.989,0.989,1.98
798,0.993,0.993,1.98
798,0.997,0.997,1.98
799,1.00,1.00,1.98
798,1.00,1.00,1.98
799,1.01,1.01,1.98
800,1.01,1.01,1.98
799,1.02,1.02,1.98
800,1.02,1.02,1.98
801,1.03,1.03,1.99
801,1.03,1.03,1.99
801,1.03,1.03,1.99
802,1.04,1.04,1.99
802,1.04,1.04,1.99
803,1.05,1.05,1.99
802,1.05,1.05,1.99
803,1.05,1.05,1.99
803,1.06,1.06,1.99
803,1.06,1.06,1.99
804,1.07,1.07,1.99
804,1.07,1.07,1.99
804,1.07,1.07,1.99
805,1.08,1.08,2.00
806,1.08,1.08,2.00
806,1.09,1.09,2.00
807,1.09,1.09,2.00
807,1.09,1.09,2.00
807,1.10,1.10,2.00
808,1.10,1.10,2.00
808,1.11,1.11,2.00
809,1.11,1.11,2.01
808,1.11,1.11,2.00
809,1.12,1.12,2.01
810,1.12,1.12,2.01
810,1.13,1.13,2.01
811,1.13,1.13,2.01
811,1.13,1.13,2.01
811,1.14,1.14,2.01
812,1.14,1.14,2.01
812,1.15,1.15,2.01
813,1.15,1.15,2.01
813,1.15,1.15,2.02
813,1.16,1.16,2.01
814,1.16,1.16,2.02
813,1.17,1.17,2.02
814,1.17,1.17,2.02
815,1.17,1.17,2.02
815,1.18,1.18,2.02
816,1.18,1.18,2.02
817,1.19,1.19,2.02
817,1.19,1.19,2.02
818,1.20,1.20,2.03
818,1.20,1.20,2.03
818,1.20,1.20,2.03
819,1.21,1.21,2.03
819,1.21,1.21,2.03
820,1.22,1.22,2.03
821,1.22,1.22,2.04
821,1.22,1.22,2.04
822,1.23,1.23,2.04
822,1.23,1.23,2.04
823,1.24,1.24,2.04
823,1.24,1.24,2.04
823,1.24,1.24,2.04
823,1.25,1.25,2.04
824,1.25,1.25,2.04
824,1.26,1.26,2.04
824,1.26,1.26,2.04
825,1.26,1.26,2.05
825,1.27,1.27,2.05
826,1.27,1.27,2.05
826,1.28,1.28,2.05
826,1.28,1.28,2.05
827,1.28,1.28,2.05
828,1.29,1.29,2.05
828,1.29,1.29,2.05
828,1.30,1.30,2.05
829,1.30,1.30,2.06
829,1.30,1.30,2.06
829,1.31,1.31,2.06
831,1.31,1.31,2.06
831,1.32,1.32,2.06
831,1.32,1.32,2.06
832,1.32,1.32,2.06
832,1.33,1.33,2.06
832,1.33,1.33,2.06
833,1.34,1.34,2.06
833,1.34,1.34,2.06
833,1.34,1.34,2.06
833,1.35,1.35,2.07
833,1.35,1.35,2.07
834,1.36,1.36,2.07
835,1.36,1.36,2.07
835,1.36,1.36,2.07
836,1.37,1.37,2.07
836,1.37,1.37,2.07
837,1.38,1.38,2.07
837,1.38,1.38,2.07
838,1.38,1.38,2.08
838,1.39,1.39,2.08
838,1.39,1.39,2.08
838,1.40,1.40,2.08
839,1.40,1.40,2.08
839,1.40,1.40,2.08
840,1.41,1.41,2.08
842,1.41,1.41,2.09
841,1.42,1.42,2.08
842,1.42,1.42,2.09
843,1.42,1.42,2.09
843,1.43,1.43,2.09
843,1.43,1.43,2.09
844,1.44,1.44,2.09
844,1.44,1.44,2.09
845,1.44,1.44,2.10
845,1.45,1.45,2.10
846,1.45,1.45,2.10
847,1.46,1.46,2.10
848,1.46,1.46,2.10
848,1.46,1.46,2.10
848,1.47,1.47,2.10
848,1.47,1.47,2.10
849,1.48,1.48,2.11
849,1.48,1.48,2.11
849,1.48,1.48,2.11
851,1.49,1.49,2.11
851,1.49,1.49,2.11
851,1.50,1.50,2.11
852,1.50,1.50,2.11
852,1.50,1.50,2.11
853,1.51,1.51,2.11
853,1.51,1.51,2.11
853,1.52,1.52,2.11
853,1.52,1.52,2.12
853,1.53,1.53,2.12
854,1.53,1.53,2.12
855,1.53,1.53,2.12
855,1.54,1.54,2.12
856,1.54,1.54,2.12
857,1.55,1.55,2.12
857,1.55,1.55,2.12
858,1.55,1.55,2.13
858,1.56,1.56,2.13
858,1.56,1.56,2.13
859,1.57,1.57,2.13
859,1.57,1.57,2.13
860,1.57,1.57,2.13
860,1.58,1.58,2.13
861,1.58,1.58,2.13
862,1.59,1.59,2.14
862,1.59,1.59,2.14
863,1.59,1.59,2.14
863,1.60,1.60,2.14
864,1.60,1.60,2.14
864,1.61,1.61,2.14
865,1.61,1.61,2.14
866,1.61,1.61,2.15
867,1.62,1.62,2.15
867,1.62,1.62,2.15
868,1.63,1.63,2.15
868,1.63,1.63,2.15
869,1.63,1.63,2.15
869,1.64,1.64,2.15
870,1.64,1.64,2.16
870,1.65,1.65,2.16
871,1.65,1.65,2.16
872,1.65,1.65,2.16
873,1.66,1.66,2.16
873,1.66,1.66,2.17
873,1.67,1.67,2.17
874,1.67,1.67,2.17
875,1.67,1.67,2.17
876,1.68,1.68,2.17
877,1.68,1.68,2.17
877,1.69,1.69,2.17
878,1.69,1.69,2.18
878,1.69,1.69,2.18
878,1.70,1.70,2.18
879,1.70,1.70,2.18
880,1.71,1.71,2.18
880,1.71,1.71,2.18
881,1.71,1.71,2.18
881,1.72,1.72,2.18
883,1.72,1.72,2.19
883,1.73,1.73,2.19
883,1.73,1.73,2.19
883,1.73,1.73,2.19
884,1.74,1.74,2.19
885,1.74,1.74,2.19
885,1.75,1.75,2.19
886,1.75,1.75,2.20
886,1.75,1.75,2.20
887,1.76,1.76,2.20
888,1.76,1.76,2.20
888,1.77,1.77,2.20
888,1.77,1.77,2.20
889,1.77,1.77,2.20
890,1.78,1.78,2.21
890,1.78,1.78,2.21
891,1.79,1.79,2.21
892,1.79,1.79,2.21
892,1.79,1.79,2.21
893,1.80,1.80,2.21
893,1.80,1.80,2.21
893,1.81,1.81,2.21
893,1.81,1.81,2.21
894,1.81,1.81,2.22
895,1.82,1.82,2.22
896,1.82,1.82,2.22
896,1.83,1.83,2.22
897,1.83,1.83,2.22
898,1.84,1.84,2.23
898,1.84,1.84,2.23
898,1.84,1.84,2.23
899,1.85,1.85,2.23
899,1.85,1.85,2.23
900,1.86,1.86,2.23
901,1.86,1.86,2.23
902,1.86,1.86,2.24
902,1.87,1.87,2.24
903,1.87,1.87,2.24
903,1.88,1.88,2.24
903,1.88,1.88,2.24
904,1.88,1.88,2.24
905,1.89,1.89,2.24
906,1.89,1.89,2.25
906,1.90,1.90,2.25
907,1.90,1.90,2.25
907,1.90,1.90,2.25
908,1.91,1.91,2.25
908,1.91,1.91,2.25
908,1.92,1.92,2.25
909,1.92,1.92,2.25
909,1.92,1.92,2.25
910,1.93,1.93,2.26
911,1.93,1.93,2.26
911,1.94,1.94,2.26
912,1.94,1.94,2.26
912,1.94,1.94,2.26
912,1.95,1.95,2.26
913,1.95,1.95,2.26
913,1.96,1.96,2.26
913,1.96,1.96,2.26
914,1.96,1.96,2.27
914,1.97,1.97,2.27
915,1.97,1.97,2.27
915,1.98,1.98,2.27
915,1.98,1.98,2.27
916,1.98,1.98,2.27
916,1.99,1.99,2.27
917,1.99,1.99,2.27
918,2.00,2.00,2.27
918,2.00,2.00,2.27
918,2.00,2.00,2.28
918,2.01,2.01,2.28
918,2.01,2.01,2.28
920,2.02,2.02,2.28
920,2.02,2.02,2.28
920,2.02,2.02,2.28
921,2.03,2.03,2.28
921,2.03,2.03,2.28
922,2.04,2.04,2.29
922,2.04,2.04,2.29
923,2.04,2.04,2.29
923,2.05,2.05,2.29
923,2.05,2.05,2.29
924,2.06,2.06,2.29
925,2.06,2.06,2.29
925,2.06,2.06,2.29
926,2.07,2.07,2.30
927,2.07,2.07,2.30
927,2.08,2.08,2.30
928,2.08,2.08,2.30
928,2.08,2.08,2.30
928,2.09,2.09,2.30
929,2.09,2.09,2.30
929,2.10,2.10,2.30
930,2.10,2.10,2.31
931,2.11,2.11,2.31
931,2.11,2.11,2.31
932,2.11,2.11,2.31
933,2.12,2.12,2.31
933,2.12,2.12,2.31
934,2.13,2.13,2.32
934,2.13,2.13,2.32
935,2.13,2.13,2.32
937,2.14,2.14,2.32
937,2.14,2.14,2.32
937,2.15,2.15,2.32
938,2.15,2.15,2.33
938,2.15,2.15,2.33
939,2.16,2.16,2.33
940,2.16,2.16,2.33
941,2.17,2.17,2.33
942,2.17,2.17,2.33
943,2.17,2.17,2.34
943,2.18,2.18,2.34
944,2.18,2.18,2.34
944,2.19,2.19,2.34
945,2.19,2.19,2.34
946,2.19,2.19,2.35
947,2.20,2.20,2.35
948,2.20,2.20,2.35
948,2.21,2.21,2.35
948,2.21,2.21,2.35
949,2.21,2.21,2.35
949,2.22,2.22,2.35
952,2.22,2.22,2.36
952,2.23,2.23,2.36
953,2.23,2.23,2.36
953,2.23,2.23,2.36
954,2.24,2.24,2.37
955,2.24,2.24,2.37
955,2.25,2.25,2.37
956,2.25,2.25,2.37
957,2.25,2.25,2.37
958,2.26,2.26,2.37
958,2.26,2.26,2.38
959,2.27,2.27,2.38
959,2.27,2.27,2.38
960,2.27,2.27,2.38
961,2.28,2.28,2.38
961,2.28,2.28,2.38
962,2.29,2.29,2.38
963,2.29,2.29,2.39
963,2.29,2.29,2.39
964,2.30,2.30,2.39
964,2.30,2.30,2.39
965,2.31,2.31,2.39
966,2.31,2.31,2.39
966,2.31,2.31,2.39
967,2.32,2.32,2.40
968,2.32,2.32,2.40
968,2.33,2.33,2.40
969,2.33,2.33,2.40
970,2.33,2.33,2.40
970,2.34,2.34,2.40
972,2.34,2.34,2.41
972,2.35,2.35,2.41
972,2.35,2.35,2.41
973,2.35,2.35,2.41
973,2.36,2.36,2.41
973,2.36,2.36,2.41
974,2.37,2.37,2.42
974,2.37,2.37,2.42
975,2.37,2.37,2.42
976,2.38,2.38,2.42
976,2.38,2.38,2.42
977,2.39,2.39,2.42
977,2.39,2.39,2.42
978,2.39,2.39,2.43
978,2.40,2.40,2.43
979,2.40,2.40,2.43
980,2.41,2.41,2.43
980,2.41,2.41,2.43
981,2.41,2.41,2.43
982,2.42,2.42,2.43
982,2.42,2.42,2.43
983,2.43,2.43,2.44
983,2.43,2.43,2.44
984,2.44,2.44,2.44
985,2.44,2.44,2.44
986,2.44,2.44,2.44
986,2.45,2.45,2.44
988,2.45,2.45,2.45
988,2.46,2.46,2.45
988,2.46,2.46,2.45
988,2.46,2.46,2.45
989,2.47,2.47,2.45
990,2.47,2.47,2.45
991,2.48,2.48,2.46
991,2.48,2.48,2.46
993,2.48,2.48,2.46
993,2.49,2.49,2.46
993,2.49,2.49,2.46
994,2.50,2.50,2.46
995,2.50,2.50,2.47
997,2.50,2.50,2.47
997,2.51,2.51,2.47
998,2.51,2.51,2.47
998,2.52,2.52,2.48
998,2.52,2.52,2.48
1000,2.52,2.52,2.48
1000,2.53,2.53,2.48
1000,2.53,2.53,2.48
1000,2.54,2.54,2.48
1000,2.54,2.54,2.48
1000,2.54,2.54,2.49
1000,2.55,2.55,2.49
1000,2.55,2.55,2.49
1010,2.56,2.56,2.49
1010,2.56,2.56,2.49
1010,2.56,2.56,2.50
1010,2.57,2.57,2.50
1010,2.57,2.57,2.50
1010,2.58,2.58,2.50
1010,2.58,2.58,2.50
1010,2.58,2.58,2.50
1010,2.59,2.59,2.50
1010,2.59,2.59,2.51
1010,2.60,2.60,2.51
1010,2.60,2.60,2.51
1010,2.60,2.60,2.51
1010,2.61,2.61,2.51
1020,2.61,2.61,2.52
1020,2.62,2.62,2.52
1020,2.62,2.62,2.52
1020,2.62,2.62,2.52
1020,2.63,2.63,2.52
1020,2.63,2.63,2.52
1020,2.64,2.64,2.52
1020,2.64,2.64,2.52
1020,2.64,2.64,2.53
1020,2.65,2.65,2.53
1020,2.65,2.65,2.53
1020,2.66,2.66,2.54
1020,2.66,2.66,2.54
1020,2.66,2.66,2.54
1030,2.67,2.67,2.54
1030,2.67,2.67,2.54
1030,2.68,2.68,2.54
1030,2.68,2.68,2.55
1030,2.68,2.68,2.55
1030,2.69,2.69,2.55
1030,2.69,2.69,2.55
1030,2.70,2.70,2.55
1030,2.70,2.70,2.55
1030,2.70,2.70,2.56
1030,2.71,2.71,2.56
1030,2.71,2.71,2.56
1030,2.72,2.72,2.56
1030,2.72,2.72,2.56
1030,2.72,2.72,2.56
1040,2.73,2.73,2.57
1040,2.73,2.73,2.57
1040,2.74,2.74,2.57
1040,2.74,2.74,2.57
1040,2.75,2.75,2.57
1040,2.75,2.75,2.57
1040,2.75,2.75,2.58
1040,2.76,2.76,2.58
1040,2.76,2.76,2.58
1040,2.77,2.77,2.58
1040,2.77,2.77,2.58
1040,2.77,2.77,2.58
1040,2.78,2.78,2.59
1040,2.78,2.78,2.59
1050,2.79,2.79,2.59
1050,2.79,2.79,2.59
1050,2.79,2.79,2.59
1050,2.80,2.80,2.60
1050,2.80,2.80,2.60
1050,2.81,2.81,2.60
1050,2.81,2.81,2.60
1050,2.81,2.81,2.60
1050,2.82,2.82,2.60
1050,2.82,2.82,2.60
1050,2.83,2.83,2.61
1050,2.83,2.83,2.61
1050,2.83,2.83,2.61
1050,2.84,2.84,2.61
1050,2.84,2.84,2.61
1050,2.85,2.85,2.61
1060,2.85,2.85,2.62
1060,2.85,2.85,2.62
1060,2.86,2.86,2.62
1060,2.86,2.86,2.62
1060,2.87,2.87,2.62
1060,2.87,2.87,2.62
1060,2.87,2.87,2.62
1060,2.88,2.88,2.62
1060,2.88,2.88,2.63
1060,2.89,2.89,2.63
1060,2.89,2.89,2.63
1060,2.89,2.89,2.63
1060,2.90,2.90,2.63
1060,2.90,2.90,2.63
1060,2.91,2.91,2.64
1060,2.91,2.91,2.64
1060,2.91,2.91,2.64
1060,2.92,2.92,2.64
1070,2.92,2.92,2.64
1070,2.93,2.93,2.64
1070,2.93,2.93,2.64
1070,2.93,2.93,2.65
1070,2.94,2.94,2.65
1070,2.94,2.94,2.65
1070,2.95,2.95,2.65
1070,2.95,2.95,2.65
1070,2.95,2.95,2.65
1070,2.96,2.96,2.66
1070,2.96,2.96,2.66
1070,2.97,2.97,2.66
1070,2.97,2.97,2.66
1070,2.97,2.97,2.66
1080,2.98,2.98,2.67
1080,2.98,2.98,2.67
1080,2.99,2.99,2.67
1080,2.99,2.99,2.67
1080,2.99,2.99,2.67
1080,3.00,3.00,2.67
1080,3.00,3.00,2.68
1080,3.01,3.01,2.68
1080,3.01,3.01,2.68
1080,3.01,3.01,2.68
1080,3.02,3.02,2.68
1080,3.02,3.02,2.68
1080,3.03,3.03,2.69
1080,3.03,3.03,2.69
1090,3.04,3.04,2.69
1090,3.04,3.04,2.69
1090,3.04,3.04,2.69
1090,3.05,3.05,2.70
1090,3.05,3.05,2.70
1090,3.06,3.06,2.70
1090,3.06,3.06,2.70
1090,3.06,3.06,2.70
1090,3.07,3.07,2.70
1090,3.07,3.07,2.70
1090,3.08,3.08,2.71
1090,3.08,3.08,2.71
1090,3.08,3.08,2.71
1090,3.09,3.09,2.71
1090,3.09,3.09,2.71
1090,3.10,3.10,2.71
1100,3.10,3.10,2.71
1100,3.10,3.10,2.72
1100,3.11,3.11,2.72
1100,3.11,3.11,2.72
1100,3.12,3.12,2.72
1100,3.12,3.12,2.72
1100,3.12,3.12,2.72
1100,3.13,3.13,2.72
1100,3.13,3.13,2.73
1100,3.14,3.14,2.73
1100,3.14,3.14,2.73
1100,3.14,3.14,2.73
1100,3.15,3.15,2.73
1100,3.15,3.15,2.73
1100,3.16,3.16,2.74
1100,3.16,3.16,2.73
1100,3.16,3.16,2.74
1100,3.17,3.17,2.74
1110,3.17,3.17,2.74
1110,3.18,3.18,2.74
1110,3.18,3.18,2.74
1110,3.18,3.18,2.74
1110,3.19,3.19,2.74
1110,3.19,3.19,2.74
1110,3.20,3.20,2.75
1110,3.20,3.20,2.75
1110,3.20,3.20,2.75
1110,3.21,3.21,2.75
1110,3.21,3.21,2.75
1110,3.22,3.22,2.75
1110,3.22,3.22,2.75
1110,3.22,3.22,2.75
1110,3.23,3.23,2.76
1110,3.23,3.23,2.76
1110,3.24,3.24,2.76
1110,3.24,3.24,2.76
1110,3.24,3.24,2.76
1110,3.25,3.25,2.76
1110,3.25,3.25,2.76
1110,3.26,3.26,2.76
1110,3.26,3.26,2.76
1110,3.26,3.26,2.76
1120,3.27,3.27,2.76
1120,3.27,3.27,2.77
1120,3.28,3.28,2.77
1120,3.28,3.28,2.77
1120,3.28,3.28,2.77
1120,3.29,3.29,2.77
1120,3.29,3.29,2.77
1120,3.30,3.30,2.77
1120,3.30,3.30,2.77
1120,3.30,3.30,2.78
1120,3.31,3.31,2.77
1120,3.31,3.31,2.78
1120,3.32,3.32,2.78
1120,3.32,3.32,2.78
1120,3.32,3.32,2.78
1120,3.33,3.33,2.78
1120,3.33,3.33,2.78
1120,3.34,3.34,2.79
1120,3.34,3.34,2.79
1120,3.34,3.34,2.79
1120,3.35,3.35,2.79
1120,3.35,3.35,2.79
1130,3.36,3.36,2.79
1130,3.36,3.36,2.79
1130,3.36,3.36,2.79
1130,3.37,3.37,2.79
1130,3.37,3.37,2.79
1130,3.38,3.38,2.79
1130,3.38,3.38,2.80
1130,3.38,3.38,2.80
1130,3.39,3.39,2.80
1130,3.39,3.39,2.80
1130,3.40,3.40,2.80
1130,3.40,3.40,2.80
1130,3.41,3.41,2.80
1130,3.41,3.41,2.80
1130,3.41,3.41,2.80
1130,3.42,3.42,2.80
1130,3.42,3.42,2.80
1130,3.43,3.43,2.80
1130,3.43,3.43,2.80
1130,3.43,3.43,2.81
1130,3.44,3.44,2.81
1130,3.44,3.44,2.81
1130,3.45,3.45,2.81
1130,3.45,3.45,2.81
1130,3.45,3.45,2.81
1130,3.46,3.46,2.81
1130,3.46,3.46,2.81
1130,3.47,3.47,2.81
1130,3.47,3.47,2.81
1140,3.47,3.47,2.81
1140,3.48,3.48,2.82
1140,3.48,3.48,2.82
1140,3.49,3.49,2.82
1140,3.49,3.49,2.82
1140,3.49,3.49,2.82
1140,3.50,3.50,2.82
1140,3.50,3.50,2.82
1140,3.51,3.51,2.82
1140,3.51,3.51,2.82
1140,3.51,3.51,2.82
1140,3.52,3.52,2.82
1140,3.52,3.52,2.82
1140,3.53,3.53,2.82
1140,3.53,3.53,2.83
1140,3.53,3.53,2.83
1140,3.54,3.54,2.83
1140,3.54,3.54,2.83
1140,3.55,3.55,2.83
1140,3.55,3.55,2.83
1140,3.55,3.55,2.83
1140,3.56,3.56,2.83
1140,3.56,3.56,2.83
1140,3.57,3.57,2.83
1140,3.57,3.57,2.83
1150,3.57,3.57,2.84
1150,3.58,3.58,2.84
1150,3.58,3.58,2.84
1150,3.59,3.59,2.85
1150,3.59,3.59,2.85
1150,3.59,3.59,2.85
1150,3.60,3.60,2.85
1150,3.60,3.60,2.85
1150,3.61,3.61,2.86
1150,3.61,3.61,2.86
1150,3.61,3.61,2.86
1150,3.62,3.62,2.86
1160,3.62,3.62,2.86
1160,3.63,3.63,2.87
1160,3.63,3.63,2.87
1160,3.63,3.63,2.87
1160,3.64,3.64,2.87
1160,3.64,3.64,2.87
1160,3.65,3.65,2.88
1160,3.65,3.65,2.88
1160,3.65,3.65,2.88
1160,3.66,3.66,2.88
1160,3.66,3.66,2.89
1170,3.67,3.67,2.89
1170,3.67,3.67,2.89
1170,3.67,3.67,2.89
1170,3.68,3.68,2.89
1170,3.68,3.68,2.90
1170,3.69,3.69,2.90
1170,3.69,3.69,2.90
1170,3.69,3.69,2.91
1170,3.70,3.70,2.91
1170,3.70,3.70,2.91
1180,3.71,3.71,2.91
1180,3.71,3.71,2.92
1180,3.72,3.72,2.92
1180,3.72,3.72,2.92
1180,3.72,3.72,2.92
1180,3.73,3.73,2.93
1180,3.73,3.73,2.93
1180,3.74,3.74,2.93
1180,3.74,3.74,2.93
1180,3.74,3.74,2.94
1190,3.75,3.75,2.94
1190,3.75,3.75,2.94
1190,3.76,3.76,2.94
1190,3.76,3.76,2.95
1190,3.76,3.76,2.95
1190,3.77,3.77,2.95
1190,3.77,3.77,2.95
1190,3.78,3.78,2.96
1190,3.78,3.78,2.96
1200,3.78,3.78,2.96
1200,3.79,3.79,2.96
1200,3.79,3.79,2.97
1200,3.80,3.80,2.97
1200,3.80,3.80,2.97
1200,3.80,3.80,2.98
1200,3.81,3.81,2.98
1200,3.81,3.81,2.98
1200,3.82,3.82,2.98
1200,3.82,3.82,2.98
1210,3.82,3.82,2.99
1210,3.83,3.83,2.99
1210,3.83,3.83,2.99
1210,3.84,3.84,2.99
1210,3.84,3.84,2.99
1210,3.84,3.84,3.00
1210,3.85,3.85,3.00
1210,3.85,3.85,3.00
1210,3.86,3.86,3.01
1210,3.86,3.86,3.01
1210,3.86,3.86,3.01
1220,3.87,3.87,3.01
1220,3.87,3.87,3.01
1220,3.88,3.88,3.02
1220,3.88,3.88,3.02
1220,3.88,3.88,3.02
1220,3.89,3.89,3.03
1220,3.89,3.89,3.03
1220,3.90,3.90,3.03
1220,3.90,3.90,3.03
1220,3.90,3.90,3.04
1230,3.91,3.91,3.04
1230,3.91,3.91,3.04
1230,3.92,3.92,3.04
1230,3.92,3.92,3.05
1230,3.92,3.92,3.05
1230,3.93,3.93,3.05
1230,3.93,3.93,3.05
1230,3.94,3.94,3.06
1230,3.94,3.94,3.06
1230,3.94,3.94,3.06
1240,3.95,3.95,3.06
1240,3.95,3.95,3.07
1240,3.96,3.96,3.07
1240,3.96,3.96,3.07
1240,3.96,3.96,3.07
1240,3.97,3.97,3.07
1240,3.97,3.97,3.08
1240,3.98,3.98,3.08
1240,3.98,3.98,3.08
1250,3.98,3.98,3.09
1250,3.99,3.99,3.09
1250,3.99,3.99,3.09
1250,4.00,4.00,3.09
1250,4.00,4.00,3.10
1250,4.01,4.01,3.10
1250,4.01,4.01,3.10
1250,4.01,4.01,3.10
1250,4.02,4.02,3.11
1250,4.02,4.02,3.11
1250,4.03,4.03,3.11
1260,4.03,4.03,3.11
1260,4.03,4.03,3.12
1260,4.04,4.04,3.12
1260,4.04,4.04,3.12
1260,4.05,4.05,3.13
1260,4.05,4.05,3.13
1260,4.05,4.05,3.13
1260,4.06,4.06,3.13
1270,4.06,4.06,3.14
1270,4.07,4.07,3.14
1270,4.07,4.07,3.14
1270,4.07,4.07,3.15
1270,4.08,4.08,3.15
1270,4.08,4.08,3.15
1270,4.09,4.09,3.16
1270,4.09,4.09,3.16
1280,4.09,4.09,3.16
1280,4.10,4.10,3.16
1280,4.10,4.10,3.17
1280,4.11,4.11,3.17
1280,4.11,4.11,3.17
1280,4.11,4.11,3.18
1280,4.12,4.12,3.18
1280,4.12,4.12,3.18
1290,4.13,4.13,3.19
1290,4.13,4.13,3.19
1290,4.13,4.13,3.19
1290,4.14,4.14,3.20
1290,4.14,4.14,3.20
1290,4.15,4.15,3.20
1290,4.15,4.15,3.21
1290,4.15,4.15,3.21
1300,4.16,4.16,3.21
1300,4.16,4.16,3.22
1300,4.17,4.17,3.22
1300,4.17,4.17,3.22
1300,4.17,4.17,3.23
1300,4.18,4.18,3.23
1300,4.18,4.18,3.23
1310,4.19,4.19,3.24
1310,4.19,4.19,3.24
1310,4.19,4.19,3.24
1310,4.20,4.20,3.25
1310,4.20,4.20,3.25
1310,4.21,4.21,3.25
1310,4.21,4.21,3.26
1320,4.22,4.22,3.26
1320,4.22,4.22,3.26
1320,4.22,4.22,3.27
1320,4.23,4.23,3.27
1320,4.23,4.23,3.27
1320,4.24,4.24,3.28
1320,4.24,4.24,3.28
1320,4.24,4.24,3.28
1330,4.25,4.25,3.29
1330,4.25,4.25,3.29
1330,4.26,4.26,3.30
1330,4.26,4.26,3.30
1330,4.26,4.26,3.30
1330,4.27,4.27,3.31
1330,4.27,4.27,3.31
1340,4.28,4.28,3.31
1340,4.28,4.28,3.32
1340,4.28,4.28,3.32
1340,4.29,4.29,3.32
1340,4.29,4.29,3.33
1340,4.30,4.30,3.33
1340,4.30,4.30,3.33
1350,4.30,4.30,3.34
1350,4.31,4.31,3.34
1350,4.31,4.31,3.34
1350,4.32,4.32,3.35
1350,4.32,4.32,3.35
1350,4.32,4.32,3.35
1350,4.33,4.33,3.36
1360,4.33,4.33,3.36
1360,4.34,4.34,3.36
1360,4.34,4.34,3.37
1360,4.34,4.34,3.37
1360,4.35,4.35,3.37
1360,4.35,4.35,3.38
1360,4.36,4.36,3.38
1360,4.36,4.36,3.38
1370,4.36,4.36,3.39
1370,4.37,4.37,3.39
1370,4.37,4.37,3.39
1370,4.38,4.38,3.40
1370,4.38,4.38,3.40
1370,4.38,4.38,3.40
1380,4.39,4.39,3.41
1380,4.39,4.39,3.41
1380,4.39,4.39,3.41
1380,4.40,4.40,3.42
1380,4.40,4.40,3.42
1380,4.41,4.41,3.42
1380,4.41,4.41,3.43
1380,4.42,4.42,3.43
1390,4.42,4.42,3.43
1390,4.42,4.42,3.44
1390,4.43,4.43,3.44
1390,4.43,4.43,3.44
1390,4.44,4.44,3.45
1390,4.44,4.44,3.45
1390,4.44,4.44,3.45
1390,4.45,4.45,3.46
1400,4.45,4.45,3.46
1400,4.46,4.46,3.46
1400,4.46,4.46,3.47
1400,4.46,4.46,3.47
1400,4.47,4.47,3.47
1400,4.47,4.47,3.48
1400,4.48,4.48,3.48
1410,4.48,4.48,3.48
1410,4.48,4.48,3.49
1410,4.49,4.49,3.49
1410,4.49,4.49,3.49
1410,4.50,4.50,3.50
1410,4.50,4.50,3.50
1410,4.50,4.50,3.50
1410,4.51,4.51,3.51
1420,4.51,4.51,3.51
1420,4.52,4.52,3.51
1420,4.52,4.52,3.52
1420,4.52,4.52,3.52
1420,4.53,4.53,3.53
1420,4.53,4.53,3.53
1420,4.54,4.54,3.53
1430,4.54,4.54,3.54
1430,4.55,4.55,3.54
1430,4.55,4.55,3.54
1430,4.55,4.55,3.54
1430,4.56,4.56,3.55
1430,4.56,4.56,3.55
1430,4.57,4.57,3.55
1440,4.57,4.57,3.56
1440,4.57,4.57,3.56
1440,4.58,4.58,3.57
1440,4.58,4.58,3.57
1440,4.59,4.59,3.57
1440,4.59,4.59,3.58
1440,4.59,4.59,3.58
1450,4.60,4.60,3.58
1450,4.60,4.60,3.59
1450,4.61,4.61,3.59
1450,4.61,4.61,3.60
1450,4.61,4.61,3.60
1450,4.62,4.62,3.60
1450,4.62,4.62,3.61
1460,4.63,4.63,3.61
1460,4.63,4.63,3.61
1460,4.63,4.63,3.62
1460,4.64,4.64,3.62
1460,4.64,4.64,3.62
1460,4.65,4.65,3.63
1470,4.65,4.65,3.63
1470,4.65,4.65,3.64
1470,4.66,4.66,3.64
1470,4.66,4.66,3.64
1470,4.67,4.67,3.65
1470,4.67,4.67,3.65
1470,4.67,4.67,3.65
1480,4.68,4.68,3.66
1480,4.68,4.68,3.67
1480,4.69,4.69,3.67
1480,4.69,4.69,3.67
1480,4.69,4.69,3.68
1490,4.70,4.70,3.68
1490,4.70,4.70,3.69
1490,4.71,4.71,3.69
1490,4.71,4.71,3.69
1490,4.71,4.71,3.70
1490,4.72,4.72,3.70
1490,4.72,4.72,3.70
1500,4.73,4.73,3.71
1500,4.73,4.73,3.71
1500,4.73,4.73,3.72
1500,4.74,4.74,3.72
1500,4.74,4.74,3.72
1500,4.75,4.75,3.73
1510,4.75,4.75,3.73
1510,4.75,4.75,3.74
1510,4.76,4.76,3.74
1510,4.76,4.76,3.74
1510,4.77,4.77,3.75
1510,4.77,4.77,3.75
1520,4.77,4.77,3.76
1520,4.78,4.78,3.76
1520,4.78,4.78,3.76
1520,4.79,4.79,3.77
1520,4.79,4.79,3.77
1520,4.79,4.79,3.78
1530,4.80,4.80,3.78
1530,4.80,4.80,3.79
1530,4.81,4.81,3.79
1530,4.81,4.81,3.80
1530,4.81,4.81,3.80
1530,4.82,4.82,3.80
1540,4.82,4.82,3.81
1540,4.83,4.83,3.81
1540,4.83,4.83,3.82
1540,4.84,4.84,3.82
1540,4.84,4.84,3.82
1550,4.84,4.84,3.83
1550,4.85,4.85,3.83
1550,4.85,4.85,3.84
1550,4.86,4.86,3.84
1550,4.86,4.86,3.85
1550,4.86,4.86,3.85
1550,4.87,4.87,3.85
1560,4.87,4.87,3.86
1560,4.88,4.88,3.86
1560,4.88,4.88,3.87
1560,4.88,4.88,3.87
1570,4.89,4.89,3.88
1570,4.89,4.89,3.88
1570,4.90,4.90,3.89
1570,4.90,4.90,3.89
1570,4.90,4.90,3.90
1570,4.91,4.91,3.90
1580,4.91,4.91,3.90
1580,4.92,4.92,3.91
1580,4.92,4.92,3.92
1580,4.92,4.92,3.92
1580,4.93,4.93,3.92
1580,4.93,4.93,3.93
1590,4.94,4.94,3.93
1590,4.94,4.94,3.94
1590,4.94,4.94,3.94
1590,4.95,4.95,3.95
1590,4.95,4.95,3.95
1600,4.96,4.96,3.95
1600,4.96,4.96,3.96
1600,4.96,4.96,3.96
1600,4.97,4.97,3.97
1600,4.97,4.97,3.97
1600,4.98,4.98,3.98
1610,4.98,4.98,3.98
1610,4.98,4.98,3.99
1610,4.99,4.99,3.99
1610,4.99,4.99,4.00
1620,5.00,5.00,4.00
1620,5.00,5.00,4.01
1620,5.00,5.00,4.01
1620,5.01,5.01,4.01
1620,5.01,5.01,4.02
1620,5.02,5.02,4.02
1630,5.02,5.02,4.03
1630,5.02,5.02,4.03
1630,5.03,5.03,4.04
1630,5.03,5.03,4.04
1630,5.04,5.04,4.05
1630,5.04,5.04,4.05
1640,5.04,5.04,4.06
1640,5.05,5.05,4.07
1640,5.05,5.05,4.07
1640,5.06,5.06,4.07
1650,5.06,5.06,4.08
1650,5.06,5.06,4.08
1650,5.07,5.07,4.09
1650,5.07,5.07,4.09
1650,5.08,5.08,4.10
1650,5.08,5.08,4.10
1660,5.08,5.08,4.11
1660,5.09,5.09,4.11
1660,5.09,5.09,4.12
1660,5.10,5.10,4.12
1660,5.10,5.10,4.13
1670,5.10,5.10,4.13
1670,5.11,5.11,4.13
1670,5.11,5.11,4.14
1670,5.12,5.12,4.15
1670,5.12,5.12,4.15
1680,5.12,5.12,4.16
1680,5.13,5.13,4.16
1680,5.13,5.13,4.17
1680,5.14,5.14,4.17
1680,5.14,5.14,4.18
1690,5.15,5.15,4.18
1690,5.15,5.15,4.19
1690,5.15,5.15,4.19
1690,5.16,5.16,4.20
1690,5.16,5.16,4.20
1700,5.17,5.17,4.21
1700,5.17,5.17,4.21
1700,5.17,5.17,4.22
1700,5.18,5.18,4.22
1710,5.18,5.18,4.23
1710,5.19,5.19,4.23
1710,5.19,5.19,4.24
1710,5.19,5.19,4.24
1710,5.20,5.20,4.25
1720,5.20,5.20,4.25
1720,5.21,5.21,4.26
1720,5.21,5.21,4.26
1720,5.21,5.21,4.27
1720,5.22,5.22,4.27
1730,5.22,5.22,4.28
1730,5.23,5.23,4.29
1730,5.23,5.23,4.29
1730,5.23,5.23,4.30
1740,5.24,5.24,4.30
1740,5.24,5.24,4.31
1740,5.25,5.25,4.31
1740,5.25,5.25,4.32
1740,5.25,5.25,4.32
1750,5.26,5.26,4.33
1750,5.26,5.26,4.33
1750,5.27,5.27,4.34
1750,5.27,5.27,4.35
1750,5.27,5.27,4.35
1760,5.28,5.28,4.36
1760,5.28,5.28,4.36
1760,5.29,5.29,4.37
1760,5.29,5.29,4.37
1770,5.29,5.29,4.38
1770,5.30,5.30,4.39
1770,5.30,5.30,4.39
1770,5.31,5.31,4.40
1780,5.31,5.31,4.40
1780,5.31,5.31,4.40
1780,5.32,5.32,4.41
1780,5.32,5.32,4.42
1780,5.33,5.33,4.42
1790,5.33,5.33,4.43
1790,5.33,5.33,4.43
1790,5.34,5.34,4.44
1790,5.34,5.34,4.44
1800,5.35,5.35,4.45
1800,5.35,5.35,4.46
1800,5.35,5.35,4.46
1800,5.36,5.36,4.47
1810,5.36,5.36,4.48
1810,5.37,5.37,4.48
1810,5.37,5.37,4.48
1810,5.37,5.37,4.49
1810,5.38,5.38,4.50
1820,5.38,5.38,4.50
1820,5.39,5.39,4.51
1820,5.39,5.39,4.51
1820,5.39,5.39,4.52
1830,5.40,5.40,4.52
1830,5.40,5.40,4.53
1830,5.41,5.41,4.54
1830,5.41,5.41,4.54
1840,5.41,5.41,4.55
1840,5.42,5.42,4.56
1840,5.42,5.42,4.56
1840,5.43,5.43,4.57
1840,5.43,5.43,4.57
1850,5.43,5.43,4.58
1850,5.44,5.44,4.59
1850,5.44,5.44,4.59
1850,5.45,5.45,4.60
1860,5.45,5.45,4.60
1860,5.45,5.45,4.61
1860,5.46,5.46,4.62
1860,5.46,5.46,4.62
1870,5.47,5.47,4.63
1870,5.47,5.47,4.64
1870,5.47,5.47,4.64
1870,5.48,5.48,4.65
1880,5.48,5.48,4.65
1880,5.49,5.49,4.66
1880,5.49,5.49,4.67
1880,5.50,5.50,4.67
1890,5.50,5.50,4.68
1890,5.50,5.50,4.68
1890,5.51,5.51,4.69
1900,5.51,5.51,4.70
1900,5.52,5.52,4.70
1900,5.52,5.52,4.71
1900,5.52,5.52,4.72
1910,5.53,5.53,4.72
1910,5.53,5.53,4.73
1910,5.54,5.54,4.74
1910,5.54,5.54,4.74
1920,5.54,5.54,4.75
1920,5.55,5.55,4.75
1920,5.55,5.55,4.76
1920,5.56,5.56,4.77
1930,5.56,5.56,4.77
1930,5.56,5.56,4.78
1930,5.57,5.57,4.79
1930,5.57,5.57,4.79
1940,5.58,5.58,4.80
1940,5.58,5.58,4.81
1940,5.58,5.58,4.81
1950,5.59,5.59,4.82
1950,5.59,5.59,4.83
1950,5.60,5.60,4.83
1950,5.60,5.60,4.84
1950,5.60,5.60,4.85
1960,5.61,5.61,4.86
1960,5.61,5.61,4.86
1960,5.62,5.62,4.87
1970,5.62,5.62,4.87
1970,5.62,5.62,4.88
1970,5.63,5.63,4.89
1980,5.63,5.63,4.90
1980,5.64,5.64,4.90
1980,5.64,5.64,4.91
1980,5.64,5.64,4.92
1990,5.65,5.65,4.92
1990,5.65,5.65,4.93
1990,5.66,5.66,4.94
1990,5.66,5.66,4.94
2000,5.66,5.66,4.95
2000,5.67,5.67,4.96
2000,5.67,5.67,4.97
2010,5.68,5.68,4.97
2010,5.68,5.68,4.98
2010,5.68,5.68,4.99
2020,5.69,5.69,5.00
2020,5.69,5.69,5.00
2020,5.70,5.70,5.01
2020,5.70,5.70,5.02
2030,5.70,5.70,5.02
2030,5.71,5.71,5.03
2030,5.71,5.71,5.04
2040,5.72,5.72,5.05
2040,5.72,5.72,5.05
2040,5.72,5.72,5.06
2050,5.73,5.73,5.07
2050,5.73,5.73,5.07
2050,5.74,5.74,5.08
2050,5.74,5.74,5.09
2060,5.74,5.74,5.10
2060,5.75,5.75,5.10
2060,5.75,5.75,5.11
2070,5.76,5.76,5.12
2070,5.76,5.76,5.13
2070,5.76,5.76,5.13
2070,5.77,5.77,5.14
2080,5.77,5.77,5.15
2080,5.78,5.78,5.16
2080,5.78,5.78,5.17
2090,5.78,5.78,5.17
2090,5.79,5.79,5.18
2090,5.79,5.79,5.19
2100,5.80,5.80,5.20
2100,5.80,5.80,5.20
2100,5.80,5.80,5.21
2110,5.81,5.81,5.22
2110,5.81,5.81,5.23
2110,5.82,5.82,5.23
2120,5.82,5.82,5.24
2120,5.83,5.83,5.25
2120,5.83,5.83,5.26
2130,5.83,5.83,5.27
2130,5.84,5.84,5.28
2130,5.84,5.84,5.28
2140,5.85,5.85,5.29
2140,5.85,5.85,5.30
2140,5.85,5.85,5.31
2150,5.86,5.86,5.32
2150,5.86,5.86,5.32
2150,5.87,5.87,5.33
2150,5.87,5.87,5.34
2160,5.87,5.87,5.34
2160,5.88,5.88,5.36
2160,5.88,5.88,5.36
2170,5.89,5.89,5.37
2170,5.89,5.89,5.38
2170,5.89,5.89,5.39
2180,5.90,5.90,5.40
2180,5.90,5.90,5.40
2180,5.91,5.91,5.41
2190,5.91,5.91,5.42
2190,5.91,5.91,5.43
2190,5.92,5.92,5.44
2200,5.92,5.92,5.45
2200,5.93,5.93,5.45
2200,5.93,5.93,5.46
2210,5.93,5.93,5.47
2210,5.94,5.94,5.48
2210,5.94,5.94,5.49
2220,5.95,5.95,5.50
2220,5.95,5.95,5.50
2220,5.95,5.95,5.51
2230,5.96,5.96,5.52
2230,5.96,5.96,5.53
2230,5.97,5.97,5.54
2240,5.97,5.97,5.55
2240,5.97,5.97,5.56
2240,5.98,5.98,5.56
2250,5.98,5.98,5.57
2250,5.99,5.99,5.58
2260,5.99,5.99,5.59
2260,5.99,5.99,5.60
2260,6.00,6.00,5.61
2260,6.00,6.00,5.61

-2.50,0.00,0.00,-0.00620
2.28,0.00300,0.00300,0.00565
10.4,0.00800,0.00800,0.0257
17.5,0.0130,0.0130,0.0434
23.3,0.0173,0.0173,0.0579
29.2,0.0220,0.0220,0.0723
35.8,0.0270,0.0270,0.0888
41.7,0.0320,0.0320,0.103
46.7,0.0370,0.0370,0.116
52.5,0.0420,0.0420,0.130
57.5,0.0462,0.0462,0.143
62.5,0.0510,0.0510,0.155
67.5,0.0560,0.0560,0.167
72.5,0.0610,0.0610,0.180
77.5,0.0660,0.0660,0.192
82.5,0.0700,0.0700,0.205
88.3,0.0750,0.0750,0.219
94.2,0.0800,0.0800,0.233
99.2,0.0850,0.0850,0.246
103,0.0895,0.0895,0.255
108,0.0940,0.0940,0.267
113,0.0990,0.0990,0.281
119,0.104,0.104,0.295
125,0.109,0.109,0.310
131,0.114,0.114,0.325
138,0.118,0.118,0.341
143,0.123,0.123,0.355
150,0.128,0.128,0.372
156,0.133,0.133,0.386
163,0.138,0.138,0.405
169,0.142,0.142,0.420
176,0.147,0.147,0.436
183,0.152,0.152,0.452
190,0.157,0.157,0.470
197,0.162,0.162,0.488
204,0.166,0.166,0.505
211,0.171,0.171,0.523
218,0.176,0.176,0.541
225,0.181,0.181,0.558
233,0.186,0.186,0.576
239,0.190,0.190,0.593
247,0.195,0.195,0.612
254,0.200,0.200,0.630
261,0.205,0.205,0.647
269,0.210,0.210,0.667
277,0.214,0.214,0.686
284,0.219,0.219,0.704
291,0.224,0.224,0.720
298,0.229,0.229,0.740
306,0.234,0.234,0.758
313,0.238,0.238,0.775
320,0.243,0.243,0.793
328,0.248,0.248,0.812
336,0.253,0.253,0.833
343,0.258,0.258,0.851
351,0.262,0.262,0.871
359,0.267,0.267,0.890
367,0.272,0.272,0.909
375,0.277,0.277,0.929
382,0.282,0.282,0.948
390,0.286,0.286,0.966
397,0.291,0.291,0.985
405,0.296,0.296,1.00
413,0.301,0.301,1.02
420,0.306,0.306,1.04
428,0.310,0.310,1.06
435,0.315,0.315,1.08
443,0.320,0.320,1.10
449,0.325,0.325,1.11
457,0.330,0.330,1.13
464,0.334,0.334,1.15
471,0.339,0.339,1.17
478,0.344,0.344,1.18
484,0.349,0.349,1.20
491,0.354,0.354,1.22
498,0.358,0.358,1.23
503,0.363,0.363,1.25
509,0.368,0.368,1.26
514,0.373,0.373,1.27
522,0.378,0.378,1.29
530,0.382,0.382,1.31
538,0.387,0.387,1.33
545,0.392,0.392,1.35
553,0.397,0.397,1.37
558,0.402,0.402,1.38
563,0.406,0.406,1.40
566,0.411,0.411,1.40
568,0.416,0.416,1.41
572,0.421,0.421,1.42
581,0.426,0.426,1.44
591,0.431,0.431,1.46
599,0.435,0.435,1.49
607,0.440,0.440,1.50
615,0.445,0.445,1.52
621,0.450,0.450,1.54
626,0.454,0.454,1.55
631,0.459,0.459,1.56
635,0.464,0.464,1.57
638,0.469,0.469,1.58
641,0.474,0.474,1.59
643,0.478,0.478,1.59
644,0.483,0.483,1.60
644,0.488,0.488,1.60
646,0.493,0.493,1.60
648,0.498,0.498,1.61
651,0.503,0.503,1.61
653,0.507,0.507,1.62
657,0.512,0.512,1.63
660,0.517,0.517,1.64
664,0.522,0.522,1.65
667,0.526,0.526,1.65
670,0.531,0.531,1.66
674,0.536,0.536,1.67
678,0.541,0.541,1.68
681,0.546,0.546,1.69
684,0.550,0.550,1.70
688,0.555,0.555,1.71
692,0.560,0.560,1.71
694,0.565,0.565,1.72
698,0.570,0.570,1.73
701,0.575,0.575,1.74
704,0.579,0.579,1.75
707,0.584,0.584,1.75
709,0.589,0.589,1.76
712,0.594,0.594,1.76
715,0.599,0.599,1.77
718,0.603,0.603,1.78
720,0.608,0.608,1.79
723,0.613,0.613,1.79
725,0.618,0.618,1.80
728,0.623,0.623,1.80
729,0.627,0.627,1.81
731,0.632,0.632,1.81
733,0.637,0.637,1.82
735,0.642,0.642,1.82
737,0.647,0.647,1.83
739,0.651,0.651,1.83
741,0.656,0.656,1.84
743,0.661,0.661,1.84
744,0.666,0.666,1.85
747,0.670,0.670,1.85
748,0.675,0.675,1.86
750,0.680,0.680,1.86
752,0.685,0.685,1.86
753,0.690,0.690,1.87
755,0.695,0.695,1.87
756,0.699,0.699,1.87
757,0.704,0.704,1.88
758,0.709,0.709,1.88
760,0.714,0.714,1.88
760,0.719,0.719,1.89
761,0.723,0.723,1.89
763,0.728,0.728,1.89
763,0.733,0.733,1.89
764,0.738,0.738,1.89
765,0.742,0.742,1.90
766,0.747,0.747,1.90
768,0.752,0.752,1.90
768,0.757,0.757,1.90
768,0.762,0.762,1.90
769,0.767,0.767,1.91
771,0.771,0.771,1.91
772,0.776,0.776,1.91
773,0.781,0.781,1.92
773,0.786,0.786,1.92
774,0.791,0.791,1.92
775,0.795,0.795,1.92
775,0.800,0.800,1.92
776,0.805,0.805,1.92
777,0.810,0.810,1.93
778,0.815,0.815,1.93
778,0.819,0.819,1.93
779,0.824,0.824,1.93
780,0.829,0.829,1.93
780,0.834,0.834,1.93
781,0.839,0.839,1.94
781,0.843,0.843,1.94
783,0.848,0.848,1.94
782,0.853,0.853,1.94
782,0.858,0.858,1.94
782,0.863,0.863,1.94
783,0.867,0.867,1.94
783,0.872,0.872,1.94
784,0.877,0.877,1.94
785,0.882,0.882,1.95
786,0.887,0.887,1.95
787,0.891,0.891,1.95
788,0.896,0.896,1.95
788,0.901,0.901,1.95
790,0.906,0.906,1.96
790,0.911,0.911,1.96
791,0.915,0.915,1.96
792,0.920,0.920,1.96
792,0.925,0.925,1.96
793,0.930,0.930,1.96
793,0.935,0.935,1.97
794,0.939,0.939,1.97
794,0.944,0.944,1.97
795,0.949,0.949,1.97
796,0.954,0.954,1.97
796,0.959,0.959,1.97
797,0.963,0.963,1.97
797,0.968,0.968,1.98
797,0.973,0.973,1.98
797,0.978,0.978,1.98
798,0.983,0.983,1.98
798,0.988,0.988,1.98
798,0.992,0.992,1.98
798,0.997,0.997,1.98
799,1.00,1.00,1.98
799,1.01,1.01,1.98
799,1.01,1.01,1.98
799,1.02,1.02,1.98
801,1.02,1.02,1.99
801,1.03,1.03,1.99
801,1.03,1.03,1.99
801,1.04,1.04,1.99
802,1.04,1.04,1.99
802,1.05,1.05,1.99
802,1.05,1.05,1.99
803,1.05,1.05,1.99
803,1.06,1.06,1.99
803,1.06,1.06,1.99
803,1.07,1.07,1.99
804,1.07,1.07,1.99
805,1.08,1.08,2.00
806,1.08,1.08,2.00
806,1.09,1.09,2.00
807,1.09,1.09,2.00
807,1.10,1.10,2.00
808,1.10,1.10,2.00
808,1.11,1.11,2.00
808,1.11,1.11,2.00
809,1.12,1.12,2.01
810,1.12,1.12,2.01
810,1.13,1.13,2.01
811,1.13,1.13,2.01
812,1.14,1.14,2.01
812,1.14,1.14,2.01
812,1.15,1.15,2.01
813,1.15,1.15,2.01
813,1.16,1.16,2.02
813,1.16,1.16,2.02
813,1.17,1.17,2.02
814,1.17,1.17,2.02
815,1.18,1.18,2.02
815,1.18,1.18,2.02
816,1.18,1.18,2.02
817,1.19,1.19,2.02
818,1.19,1.19,2.03
818,1.20,1.20,2.03
818,1.20,1.20,2.03
819,1.21,1.21,2.03
820,1.21,1.21,2.03
820,1.22,1.22,2.03
821,1.22,1.22,2.04
822,1.23,1.23,2.04
822,1.23,1.23,2.04
823,1.24,1.24,2.04
823,1.24,1.24,2.04
823,1.25,1.25,2.04
824,1.25,1.25,2.04
825,1.26,1.26,2.05
825,1.26,1.26,2.05
826,1.27,1.27,2.05
826,1.27,1.27,2.05
826,1.28,1.28,2.05
826,1.28,1.28,2.05
827,1.29,1.29,2.05
828,1.29,1.29,2.05
828,1.30,1.30,2.05
829,1.30,1.30,2.06
829,1.30,1.30,2.06
831,1.31,1.31,2.06
830,1.31,1.31,2.06
831,1.32,1.32,2.06
832,1.32,1.32,2.06
832,1.33,1.33,2.06
832,1.33,1.33,2.06
832,1.34,1.34,2.06
833,1.34,1.34,2.06
833,1.35,1.35,2.07
834,1.35,1.35,2.07
834,1.36,1.36,2.07
835,1.36,1.36,2.07
836,1.37,1.37,2.07
836,1.37,1.37,2.07
837,1.38,1.38,2.07
837,1.38,1.38,2.07
838,1.39,1.39,2.08
838,1.39,1.39,2.08
838,1.40,1.40,2.08
839,1.40,1.40,2.08
840,1.41,1.41,2.08
841,1.41,1.41,2.08
841,1.42,1.42,2.08
842,1.42,1.42,2.09
843,1.42,1.42,2.09
843,1.43,1.43,2.09
843,1.43,1.43,2.09
844,1.44,1.44,2.09
845,1.44,1.44,2.10
845,1.45,1.45,2.10
846,1.45,1.45,2.10
847,1.46,1.46,2.10
848,1.46,1.46,2.10
848,1.47,1.47,2.10
848,1.47,1.47,2.10
849,1.48,1.48,2.11
850,1.48,1.48,2.11
850,1.49,1.49,2.11
850,1.49,1.49,2.11
851,1.50,1.50,2.11
852,1.50,1.50,2.11
852,1.51,1.51,2.11
852,1.51,1.51,2.11
853,1.52,1.52,2.12
853,1.52,1.52,2.12
853,1.53,1.53,2.12
854,1.53,1.53,2.12
855,1.54,1.54,2.12
856,1.54,1.54,2.12
856,1.54,1.54,2.12
857,1.55,1.55,2.12
858,1.55,1.55,2.13
858,1.56,1.56,2.13
858,1.56,1.56,2.13
859,1.57,1.57,2.13
860,1.57,1.57,2.13
861,1.58,1.58,2.13
862,1.58,1.58,2.14
862,1.59,1.59,2.14
863,1.59,1.59,2.14
863,1.60,1.60,2.14
864,1.60,1.60,2.14
864,1.61,1.61,2.14
866,1.61,1.61,2.15
867,1.62,1.62,2.15
867,1.62,1.62,2.15
868,1.63,1.63,2.15
868,1.63,1.63,2.15
869,1.64,1.64,2.15
870,1.64,1.64,2.16
870,1.65,1.65,2.16
871,1.65,1.65,2.16
873,1.66,1.66,2.16
873,1.66,1.66,2.16
873,1.66,1.66,2.17
874,1.67,1.67,2.17
875,1.67,1.67,2.17
876,1.68,1.68,2.17
877,1.68,1.68,2.17
878,1.69,1.69,2.18
878,1.69,1.69,2.18
878,1.70,1.70,2.18
879,1.70,1.70,2.18
880,1.71,1.71,2.18
881,1.71,1.71,2.18
881,1.72,1.72,2.18
882,1.72,1.72,2.19
883,1.73,1.73,2.19
883,1.73,1.73,2.19
884,1.74,1.74,2.19
885,1.74,1.74,2.19
885,1.75,1.75,2.19
886,1.75,1.75,2.20
887,1.76,1.76,2.20
888,1.76,1.76,2.20
888,1.77,1.77,2.20
888,1.77,1.77,2.20
888,1.78,1.78,2.20
890,1.78,1.78,2.21
891,1.78,1.78,2.21
892,1.79,1.79,2.21
892,1.79,1.79,2.21
892,1.80,1.80,2.21
893,1.80,1.80,2.21
893,1.81,1.81,2.21
893,1.81,1.81,2.21
895,1.82,1.82,2.22
896,1.82,1.82,2.22
897,1.83,1.83,2.22
897,1.83,1.83,2.22
898,1.84,1.84,2.23
898,1.84,1.84,2.23
899,1.85,1.85,2.23
899,1.85,1.85,2.23
901,1.86,1.86,2.23
902,1.86,1.86,2.24
902,1.87,1.87,2.24
902,1.87,1.87,2.24
903,1.88,1.88,2.24
904,1.88,1.88,2.24
905,1.89,1.89,2.24
905,1.89,1.89,2.24
906,1.90,1.90,2.25
907,1.90,1.90,2.25
907,1.90,1.90,2.25
908,1.91,1.91,2.25
908,1.91,1.91,2.25
909,1.92,1.92,2.25
909,1.92,1.92,2.25
910,1.93,1.93,2.26
911,1.93,1.93,2.26
912,1.94,1.94,2.26
912,1.94,1.94,2.26
912,1.95,1.95,2.26
913,1.95,1.95,2.26
913,1.96,1.96,2.26
914,1.96,1.96,2.27
914,1.97,1.97,2.27
915,1.97,1.97,2.27
915,1.98,1.98,2.27
915,1.98,1.98,2.27
916,1.99,1.99,2.27
917,1.99,1.99,2.27
918,2.00,2.00,2.27
918,2.00,2.00,2.27
918,2.01,2.01,2.28
919,2.01,2.01,2.28
919,2.02,2.02,2.28
920,2.02,2.02,2.28
920,2.02,2.02,2.28
921,2.03,2.03,2.28
922,2.03,2.03,2.29
922,2.04,2.04,2.29
923,2.04,2.04,2.29
923,2.05,2.05,2.29
923,2.05,2.05,2.29
924,2.06,2.06,2.29
925,2.06,2.06,2.29
926,2.07,2.07,2.30
927,2.07,2.07,2.30
927,2.08,2.08,2.30
927,2.08,2.08,2.30
928,2.09,2.09,2.30
929,2.09,2.09,2.30
929,2.10,2.10,2.30
930,2.10,2.10,2.31
931,2.11,2.11,2.31
932,2.11,2.11,2.31
932,2.12,2.12,2.31
933,2.12,2.12,2.31
934,2.13,2.13,2.32
935,2.13,2.13,2.32
936,2.13,2.13,2.32
937,2.14,2.14,2.32
937,2.14,2.14,2.32
938,2.15,2.15,2.33
939,2.15,2.15,2.33
940,2.16,2.16,2.33
941,2.16,2.16,2.33
942,2.17,2.17,2.33
943,2.17,2.17,2.34
943,2.18,2.18,2.34
944,2.18,2.18,2.34
946,2.19,2.19,2.35
946,2.19,2.19,2.35
947,2.20,2.20,2.35
948,2.20,2.20,2.35
948,2.21,2.21,2.35
949,2.21,2.21,2.35
950,2.22,2.22,2.36
952,2.22,2.22,2.36
953,2.23,2.23,2.36
953,2.23,2.23,2.36
953,2.24,2.24,2.36
955,2.24,2.24,2.37
955,2.25,2.25,2.37
956,2.25,2.25,2.37
957,2.26,2.26,2.37
958,2.26,2.26,2.38
959,2.26,2.26,2.38
959,2.27,2.27,2.38
960,2.27,2.27,2.38
961,2.28,2.28,2.38
961,2.28,2.28,2.38
962,2.29,2.29,2.39
963,2.29,2.29,2.39
964,2.30,2.30,2.39
965,2.30,2.30,2.39
965,2.31,2.31,2.39
966,2.31,2.31,2.39
968,2.32,2.32,2.40
968,2.32,2.32,2.40
968,2.33,2.33,2.40
969,2.33,2.33,2.40
970,2.34,2.34,2.40
972,2.34,2.34,2.41
971,2.35,2.35,2.41
972,2.35,2.35,2.41
973,2.36,2.36,2.41
973,2.36,2.36,2.41
974,2.37,2.37,2.41
974,2.37,2.37,2.42
976,2.38,2.38,2.42
976,2.38,2.38,2.42
976,2.38,2.38,2.42
978,2.39,2.39,2.42
978,2.39,2.39,2.43
978,2.40,2.40,2.43
979,2.40,2.40,2.43
980,2.41,2.41,2.43
981,2.41,2.41,2.43
982,2.42,2.42,2.43
983,2.42,2.42,2.44
983,2.43,2.43,2.44
984,2.43,2.43,2.44
984,2.44,2.44,2.44
986,2.44,2.44,2.44
986,2.45,2.45,2.44
988,2.45,2.45,2.45
988,2.46,2.46,2.45
988,2.46,2.46,2.45
989,2.47,2.47,2.45
990,2.47,2.47,2.45
991,2.48,2.48,2.46
992,2.48,2.48,2.46
993,2.49,2.49,2.46
994,2.49,2.49,2.46
994,2.50,2.50,2.46
995,2.50,2.50,2.47
997,2.50,2.50,2.47
998,2.51,2.51,2.47
998,2.51,2.51,2.48
998,2.52,2.52,2.48
1000,2.52,2.52,2.48
1000,2.53,2.53,2.48
1000,2.53,2.53,2.48
1000,2.54,2.54,2.48
1000,2.54,2.54,2.49
1000,2.55,2.55,2.49
1010,2.55,2.55,2.49
1010,2.56,2.56,2.49
1010,2.56,2.56,2.49
1010,2.57,2.57,2.50
1010,2.57,2.57,2.50
1010,2.58,2.58,2.50
1010,2.58,2.58,2.50
1010,2.59,2.59,2.50
1010,2.59,2.59,2.51
1010,2.60,2.60,2.51
1010,2.60,2.60,2.51
1010,2.61,2.61,2.51
1010,2.61,2.61,2.51
1010,2.62,2.62,2.51
1020,2.62,2.62,2.52
1020,2.62,2.62,2.52
1020,2.63,2.63,2.52
1020,2.63,2.63,2.52
1020,2.64,2.64,2.53
1020,2.64,2.64,2.53
1020,2.65,2.65,2.53
1020,2.65,2.65,2.53
1020,2.66,2.66,2.54
1020,2.66,2.66,2.54
1020,2.67,2.67,2.54
1030,2.67,2.67,2.54
1030,2.68,2.68,2.54
1030,2.68,2.68,2.55
1030,2.69,2.69,2.55
1030,2.69,2.69,2.55
1030,2.70,2.70,2.55
1030,2.70,2.70,2.56
1030,2.71,2.71,2.56
1030,2.71,2.71,2.56
1030,2.72,2.72,2.56
1030,2.72,2.72,2.56
1040,2.73,2.73,2.57
1040,2.73,2.73,2.57
1040,2.74,2.74,2.57
1040,2.74,2.74,2.57
1040,2.75,2.75,2.57
1040,2.75,2.75,2.57
1040,2.75,2.75,2.58
1040,2.76,2.76,2.58
1040,2.76,2.76,2.58
1040,2.77,2.77,2.58
1040,2.77,2.77,2.58
1040,2.78,2.78,2.59
1040,2.78,2.78,2.59
1050,2.79,2.79,2.59
1050,2.79,2.79,2.59
1050,2.80,2.80,2.60
1050,2.80,2.80,2.60
1050,2.81,2.81,2.60
1050,2.81,2.81,2.60
1050,2.82,2.82,2.60
1050,2.82,2.82,2.60
1050,2.83,2.83,2.61
1050,2.83,2.83,2.61
1050,2.84,2.84,2.61
1050,2.84,2.84,2.61
1050,2.85,2.85,2.61
1050,2.85,2.85,2.61
1060,2.86,2.86,2.62
1060,2.86,2.86,2.62
1060,2.87,2.87,2.62
1060,2.87,2.87,2.62
1060,2.87,2.87,2.62
1060,2.88,2.88,2.63
1060,2.88,2.88,2.63
1060,2.89,2.89,2.63
1060,2.89,2.89,2.63
1060,2.90,2.90,2.63
1060,2.90,2.90,2.63
1060,2.91,2.91,2.64
1070,2.91,2.91,2.64
1060,2.92,2.92,2.64
1070,2.92,2.92,2.64
1070,2.93,2.93,2.64
1070,2.93,2.93,2.65
1070,2.94,2.94,2.65
1070,2.94,2.94,2.65
1070,2.95,2.95,2.65
1070,2.95,2.95,2.65
1070,2.96,2.96,2.66
1070,2.96,2.96,2.66
1070,2.97,2.97,2.66
1070,2.97,2.97,2.66
1070,2.98,2.98,2.66
1070,2.98,2.98,2.66
1080,2.99,2.99,2.67
1080,2.99,2.99,2.67
1080,2.99,2.99,2.67
1080,3.00,3.00,2.67
1080,3.00,3.00,2.68
1080,3.01,3.01,2.68
1080,3.01,3.01,2.68
1080,3.02,3.02,2.68
1080,3.02,3.02,2.68
1080,3.03,3.03,2.69
1080,3.03,3.03,2.69
1090,3.04,3.04,2.69
1090,3.04,3.04,2.69
1090,3.05,3.05,2.70
1090,3.05,3.05,2.70
1090,3.06,3.06,2.70
1090,3.06,3.06,2.70
1090,3.07,3.07,2.70
1090,3.07,3.07,2.70
1090,3.08,3.08,2.71
1090,3.08,3.08,2.71
1090,3.09,3.09,2.71
1090,3.09,3.09,2.71
1090,3.10,3.10,2.71
1100,3.10,3.10,2.71
1100,3.11,3.11,2.72
1100,3.11,3.11,2.72
1100,3.11,3.11,2.72
1100,3.12,3.12,2.72
1100,3.12,3.12,2.72
1100,3.13,3.13,2.73
1100,3.13,3.13,2.73
1100,3.14,3.14,2.73
1100,3.14,3.14,2.73
1100,3.15,3.15,2.73
1100,3.15,3.15,2.73
1100,3.16,3.16,2.73
1100,3.16,3.16,2.74
1100,3.17,3.17,2.74
1110,3.17,3.17,2.74
1110,3.18,3.18,2.74
1110,3.18,3.18,2.74
1110,3.19,3.19,2.74
1110,3.19,3.19,2.74
1110,3.20,3.20,2.75
1110,3.20,3.20,2.75
1110,3.21,3.21,2.75
1110,3.21,3.21,2.75
1110,3.22,3.22,2.75
1110,3.22,3.22,2.75
1110,3.23,3.23,2.75
1110,3.23,3.23,2.76
1110,3.23,3.23,2.76
1110,3.24,3.24,2.76
1110,3.24,3.24,2.76
1110,3.25,3.25,2.76
1110,3.25,3.25,2.76
1110,3.26,3.26,2.76
1110,3.26,3.26,2.76
1120,3.27,3.27,2.76
1120,3.27,3.27,2.77
1120,3.28,3.28,2.77
1120,3.28,3.28,2.77
1120,3.29,3.29,2.77
1120,3.29,3.29,2.77
1120,3.30,3.30,2.77
1120,3.30,3.30,2.77
1120,3.31,3.31,2.78
1120,3.31,3.31,2.78
1120,3.32,3.32,2.78
1120,3.32,3.32,2.78
1120,3.33,3.33,2.78
1120,3.33,3.33,2.78
1120,3.34,3.34,2.79
1120,3.34,3.34,2.79
1120,3.35,3.35,2.79
1120,3.35,3.35,2.79
1130,3.35,3.35,2.79
1130,3.36,3.36,2.79
1130,3.36,3.36,2.79
1130,3.37,3.37,2.79
1130,3.37,3.37,2.79
1130,3.38,3.38,2.79
1130,3.38,3.38,2.80
1130,3.39,3.39,2.80
1130,3.39,3.39,2.80
1130,3.40,3.40,2.80
1130,3.40,3.40,2.80
1130,3.41,3.41,2.80
1130,3.41,3.41,2.80
1130,3.42,3.42,2.80
1130,3.42,3.42,2.80
1130,3.43,3.43,2.81
1130,3.43,3.43,2.81
1130,3.44,3.44,2.81
1130,3.44,3.44,2.81
1130,3.45,3.45,2.81
1130,3.45,3.45,2.81
1130,3.46,3.46,2.81
1130,3.46,3.46,2.81
1130,3.47,3.47,2.81
1140,3.47,3.47,2.81
1140,3.47,3.47,2.81
1140,3.48,3.48,2.82
1140,3.48,3.48,2.82
1140,3.49,3.49,2.82
1140,3.49,3.49,2.82
1140,3.50,3.50,2.82
1140,3.50,3.50,2.82
1140,3.51,3.51,2.82
1140,3.51,3.51,2.82
1140,3.52,3.52,2.82
1140,3.52,3.52,2.82
1140,3.53,3.53,2.83
1140,3.53,3.53,2.83
1140,3.54,3.54,2.83
1140,3.54,3.54,2.83
1140,3.55,3.55,2.83
1140,3.55,3.55,2.83
1140,3.56,3.56,2.83
1140,3.56,3.56,2.83
1140,3.57,3.57,2.83
1140,3.57,3.57,2.83
1150,3.58,3.58,2.84
1150,3.58,3.58,2.84
1150,3.59,3.59,2.84
1150,3.59,3.59,2.85
1150,3.59,3.59,2.85
1150,3.60,3.60,2.85
1150,3.60,3.60,2.85
1150,3.61,3.61,2.86
1150,3.61,3.61,2.86
1150,3.62,3.62,2.86
1160,3.62,3.62,2.86
1160,3.63,3.63,2.87
1160,3.63,3.63,2.87
1160,3.64,3.64,2.87
1160,3.64,3.64,2.88
1160,3.65,3.65,2.88
1160,3.65,3.65,2.88
1160,3.66,3.66,2.88
1160,3.66,3.66,2.89
1170,3.67,3.67,2.89
1170,3.67,3.67,2.89
1170,3.68,3.68,2.89
1170,3.68,3.68,2.90
1170,3.69,3.69,2.90
1170,3.69,3.69,2.90
1170,3.70,3.70,2.91
1170,3.70,3.70,2.91
1180,3.71,3.71,2.91
1180,3.71,3.71,2.92
1180,3.71,3.71,2.92
1180,3.72,3.72,2.92
1180,3.72,3.72,2.92
1180,3.73,3.73,2.93
1180,3.73,3.73,2.93
1180,3.74,3.74,2.93
1180,3.74,3.74,2.94
1190,3.75,3.75,2.94
1190,3.75,3.75,2.94
1190,3.76,3.76,2.95
1190,3.76,3.76,2.95
1190,3.77,3.77,2.95
1190,3.77,3.77,2.96
1190,3.78,3.78,2.96
1190,3.78,3.78,2.96
1200,3.79,3.79,2.96
1200,3.79,3.79,2.97
1200,3.80,3.80,2.97
1200,3.80,3.80,2.97
1200,3.81,3.81,2.98
1200,3.81,3.81,2.98
1200,3.82,3.82,2.98
1200,3.82,3.82,2.98
1210,3.83,3.83,2.99
1210,3.83,3.83,2.99
1210,3.83,3.83,2.99
1210,3.84,3.84,2.99
1210,3.84,3.84,3.00
1210,3.85,3.85,3.00
1210,3.85,3.85,3.00
1210,3.86,3.86,3.01
1210,3.86,3.86,3.01
1220,3.87,3.87,3.01
1220,3.87,3.87,3.01
1220,3.88,3.88,3.02
1220,3.88,3.88,3.02
1220,3.89,3.89,3.02
1220,3.89,3.89,3.03
1220,3.90,3.90,3.03
1220,3.90,3.90,3.04
1230,3.91,3.91,3.04
1230,3.91,3.91,3.04
1230,3.92,3.92,3.04
1230,3.92,3.92,3.05
1230,3.93,3.93,3.05
1230,3.93,3.93,3.05
1230,3.94,3.94,3.05
1230,3.94,3.94,3.06
1230,3.95,3.95,3.06
1240,3.95,3.95,3.06
1240,3.95,3.95,3.07
1240,3.96,3.96,3.07
1240,3.96,3.96,3.07
1240,3.97,3.97,3.07
1240,3.97,3.97,3.08
1240,3.98,3.98,3.08
1240,3.98,3.98,3.08
1250,3.99,3.99,3.09
1250,3.99,3.99,3.09
1250,4.00,4.00,3.09
1250,4.00,4.00,3.10
1250,4.01,4.01,3.10
1250,4.01,4.01,3.10
1250,4.02,4.02,3.11
1250,4.02,4.02,3.11
1260,4.03,4.03,3.11
1260,4.03,4.03,3.11
1260,4.04,4.04,3.12
1260,4.04,4.04,3.12
1260,4.05,4.05,3.13
1260,4.05,4.05,3.13
1260,4.06,4.06,3.13
1270,4.06,4.06,3.14
1270,4.07,4.07,3.14
1270,4.07,4.07,3.14
1270,4.08,4.08,3.15
1270,4.08,4.08,3.15
1270,4.08,4.08,3.15
1270,4.09,4.09,3.16
1280,4.09,4.09,3.16
1280,4.10,4.10,3.17
1280,4.10,4.10,3.17
1280,4.11,4.11,3.17
1280,4.11,4.11,3.18
1280,4.12,4.12,3.18
1290,4.12,4.12,3.19
1290,4.13,4.13,3.19
1290,4.13,4.13,3.19
1290,4.14,4.14,3.20
1290,4.14,4.14,3.20
1290,4.15,4.15,3.20
1290,4.15,4.15,3.21
1300,4.16,4.16,3.21
1300,4.16,4.16,3.21
1300,4.17,4.17,3.22
1300,4.17,4.17,3.22
1300,4.18,4.18,3.23
1300,4.18,4.18,3.23
1300,4.19,4.19,3.23
1310,4.19,4.19,3.24
1310,4.19,4.19,3.24
1310,4.20,4.20,3.25
1310,4.20,4.20,3.25
1310,4.21,4.21,3.25
1320,4.21,4.21,3.26
1320,4.22,4.22,3.26
1320,4.22,4.22,3.27
1320,4.23,4.23,3.27
1320,4.23,4.23,3.27
1320,4.24,4.24,3.28
1320,4.24,4.24,3.28
1330,4.25,4.25,3.29
1330,4.25,4.25,3.29
1330,4.26,4.26,3.30
1330,4.26,4.26,3.30
1330,4.27,4.27,3.30
1330,4.27,4.27,3.31
1340,4.28,4.28,3.31
1340,4.28,4.28,3.32
1340,4.29,4.29,3.32
1340,4.29,4.29,3.33
1340,4.30,4.30,3.33
1340,4.30,4.30,3.33
1350,4.31,4.31,3.34
1350,4.31,4.31,3.34
1350,4.31,4.31,3.35
1350,4.32,4.32,3.35
1350,4.32,4.32,3.36
1360,4.33,4.33,3.36
1360,4.33,4.33,3.36
1360,4.34,4.34,3.37
1360,4.34,4.34,3.37
1360,4.35,4.35,3.37
1360,4.35,4.35,3.38
1360,4.36,4.36,3.38
1370,4.36,4.36,3.39
1370,4.37,4.37,3.39
1370,4.37,4.37,3.39
1370,4.38,4.38,3.40
1370,4.38,4.38,3.40
1370,4.39,4.39,3.41
1380,4.39,4.39,3.41
1380,4.40,4.40,3.41
1380,4.40,4.40,3.42
1380,4.41,4.41,3.42
1380,4.41,4.41,3.43
1380,4.42,4.42,3.43
1390,4.42,4.42,3.43
1390,4.43,4.43,3.44
1390,4.43,4.43,3.44
1390,4.44,4.44,3.45
1390,4.44,4.44,3.45
1390,4.44,4.44,3.45
1400,4.45,4.45,3.46
1400,4.45,4.45,3.46
1400,4.46,4.46,3.47
1400,4.46,4.46,3.47
1400,4.47,4.47,3.47
1400,4.47,4.47,3.48
1410,4.48,4.48,3.48
1410,4.48,4.48,3.49
1410,4.49,4.49,3.49
1410,4.49,4.49,3.49
1410,4.50,4.50,3.50
1410,4.50,4.50,3.50
1410,4.51,4.51,3.50
1420,4.51,4.51,3.51
1420,4.52,4.52,3.51
1420,4.52,4.52,3.52
1420,4.53,4.53,3.52
1420,4.53,4.53,3.52
1420,4.54,4.54,3.53
1430,4.54,4.54,3.53
1430,4.55,4.55,3.54
1430,4.55,4.55,3.54
1430,4.56,4.56,3.55
1430,4.56,4.56,3.55
1430,4.56,4.56,3.55
1440,4.57,4.57,3.56
1440,4.57,4.57,3.56
1440,4.58,4.58,3.57
1440,4.58,4.58,3.57
1440,4.59,4.59,3.58
1440,4.59,4.59,3.58
1450,4.60,4.60,3.58
1450,4.60,4.60,3.59
1450,4.61,4.61,3.59
1450,4.61,4.61,3.60
1450,4.62,4.62,3.60
1450,4.62,4.62,3.61
1460,4.63,4.63,3.61
1460,4.63,4.63,3.62
1460,4.64,4.64,3.62
1460,4.64,4.64,3.62
1460,4.65,4.65,3.63
1470,4.65,4.65,3.64
1470,4.66,4.66,3.64
1470,4.66,4.66,3.64
1470,4.67,4.67,3.65
1470,4.67,4.67,3.65
1480,4.68,4.68,3.66
1480,4.68,4.68,3.66
1480,4.68,4.68,3.67
1480,4.69,4.69,3.67
1480,4.69,4.69,3.68
1490,4.70,4.70,3.68
1490,4.70,4.70,3.69
1490,4.71,4.71,3.69
1490,4.71,4.71,3.69
1490,4.72,4.72,3.70
1490,4.72,4.72,3.70
1500,4.73,4.73,3.71
1500,4.73,4.73,3.71
1500,4.74,4.74,3.72
1500,4.74,4.74,3.72
1500,4.75,4.75,3.73
1510,4.75,4.75,3.73
1510,4.76,4.76,3.74
1510,4.76,4.76,3.74
1510,4.77,4.77,3.75
1510,4.77,4.77,3.75
1520,4.78,4.78,3.76
1520,4.78,4.78,3.76
1520,4.79,4.79,3.77
1520,4.79,4.79,3.77
1520,4.80,4.80,3.78
1530,4.80,4.80,3.78
1530,4.80,4.80,3.79
1530,4.81,4.81,3.79
1530,4.81,4.81,3.80
1530,4.82,4.82,3.80
1540,4.82,4.82,3.81
1540,4.83,4.83,3.81
1540,4.83,4.83,3.82
1540,4.84,4.84,3.82
1550,4.84,4.84,3.83
1550,4.85,4.85,3.83
1550,4.85,4.85,3.84
1550,4.86,4.86,3.84
1550,4.86,4.86,3.85
1550,4.87,4.87,3.85
1560,4.87,4.87,3.86
1560,4.88,4.88,3.86
1560,4.88,4.88,3.87
1560,4.89,4.89,3.88
1570,4.89,4.89,3.88
1570,4.90,4.90,3.89
1570,4.90,4.90,3.89
1570,4.91,4.91,3.90
1570,4.91,4.91,3.90
1580,4.92,4.92,3.91
1580,4.92,4.92,3.92
1580,4.92,4.92,3.92
1580,4.93,4.93,3.92
1590,4.93,4.93,3.93
1590,4.94,4.94,3.94
1590,4.94,4.94,3.94
1590,4.95,4.95,3.95
1590,4.95,4.95,3.95
1600,4.96,4.96,3.96
1600,4.96,4.96,3.96
1600,4.97,4.97,3.97
1600,4.97,4.97,3.98
1610,4.98,4.98,3.98
1610,4.98,4.98,3.99
1610,4.99,4.99,3.99
1610,4.99,4.99,4.00
1620,5.00,5.00,4.00
1620,5.00,5.00,4.01
1620,5.01,5.01,4.01
1620,5.01,5.01,4.02
1620,5.02,5.02,4.02
1630,5.02,5.02,4.03
1630,5.03,5.03,4.04
1630,5.03,5.03,4.04
1630,5.04,5.04,4.05
1630,5.04,5.04,4.05
1640,5.04,5.04,4.06
1640,5.05,5.05,4.07
1640,5.05,5.05,4.07
1640,5.06,5.06,4.08
1650,5.06,5.06,4.08
1650,5.07,5.07,4.09
1650,5.07,5.07,4.09
1650,5.08,5.08,4.10
1660,5.08,5.08,4.10
1660,5.09,5.09,4.11
1660,5.09,5.09,4.12
1660,5.10,5.10,4.12
1660,5.10,5.10,4.13
1670,5.11,5.11,4.13
1670,5.11,5.11,4.14
1670,5.12,5.12,4.15
1670,5.12,5.12,4.15
1680,5.13,5.13,4.16
1680,5.13,5.13,4.17
1680,5.14,5.14,4.17
1680,5.14,5.14,4.18
1690,5.15,5.15,4.18
1690,5.15,5.15,4.19
1690,5.16,5.16,4.19
1690,5.16,5.16,4.20
1700,5.16,5.16,4.21
1700,5.17,5.17,4.21
1700,5.17,5.17,4.22
1700,5.18,5.18,4.22
1710,5.18,5.18,4.23
1710,5.19,5.19,4.24
1710,5.19,5.19,4.24
1710,5.20,5.20,4.25
1720,5.20,5.20,4.26
1720,5.21,5.21,4.26
1720,5.21,5.21,4.27
1720,5.22,5.22,4.27
1730,5.22,5.22,4.28
1730,5.23,5.23,4.29
1730,5.23,5.23,4.29
1730,5.24,5.24,4.30
1740,5.24,5.24,4.31
1740,5.25,5.25,4.31
1740,5.25,5.25,4.32
1750,5.26,5.26,4.33
1750,5.26,5.26,4.33
1750,5.27,5.27,4.34
1750,5.27,5.27,4.35
1760,5.28,5.28,4.35
1760,5.28,5.28,4.36
1760,5.28,5.28,4.37
1760,5.29,5.29,4.37
1770,5.29,5.29,4.38
1770,5.30,5.30,4.39
1770,5.30,5.30,4.39
1770,5.31,5.31,4.40
1780,5.31,5.31,4.40
1780,5.32,5.32,4.41
1780,5.32,5.32,4.42
1790,5.33,5.33,4.43
1790,5.33,5.33,4.43
1790,5.34,5.34,4.44
1790,5.34,5.34,4.44
1800,5.35,5.35,4.45
1800,5.35,5.35,4.46
1800,5.36,5.36,4.47
1800,5.36,5.36,4.47
1810,5.37,5.37,4.48
1810,5.37,5.37,4.49
1810,5.38,5.38,4.49
1820,5.38,5.38,4.50
1820,5.39,5.39,4.51
1820,5.39,5.39,4.51
1820,5.40,5.40,4.52
1830,5.40,5.40,4.53
1830,5.40,5.40,4.54
1830,5.41,5.41,4.54
1840,5.41,5.41,4.55
1840,5.42,5.42,4.56
1840,5.42,5.42,4.56
1840,5.43,5.43,4.57
1850,5.43,5.43,4.58
1850,5.44,5.44,4.58
1850,5.44,5.44,4.59
1860,5.45,5.45,4.60
1860,5.45,5.45,4.61
1860,5.46,5.46,4.61
1860,5.46,5.46,4.62
1870,5.47,5.47,4.63
1870,5.47,5.47,4.64
1870,5.48,5.48,4.64
1880,5.48,5.48,4.65
1880,5.49,5.49,4.66
1880,5.49,5.49,4.67
1880,5.50,5.50,4.67
1890,5.50,5.50,4.68
1890,5.51,5.51,4.69
1890,5.51,5.51,4.70
1900,5.52,5.52,4.70
1900,5.52,5.52,4.71
1900,5.52,5.52,4.72
1910,5.53,5.53,4.73
1910,5.53,5.53,4.74
1910,5.54,5.54,4.74
1920,5.54,5.54,4.75
1920,5.55,5.55,4.76
1920,5.55,5.55,4.77
1930,5.56,5.56,4.77
1930,5.56,5.56,4.78
1930,5.57,5.57,4.79
1940,5.57,5.57,4.80
1940,5.58,5.58,4.80
1940,5.58,5.58,4.81
1950,5.59,5.59,4.82
1950,5.59,5.59,4.83
1950,5.60,5.60,4.84
1950,5.60,5.60,4.85
1960,5.61,5.61,4.85
1960,5.61,5.61,4.86
1960,5.62,5.62,4.87
1970,5.62,5.62,4.88
1970,5.63,5.63,4.89
1970,5.63,5.63,4.89
1980,5.64,5.64,4.90
1980,5.64,5.64,4.91
1980,5.64,5.64,4.92
1990,5.65,5.65,4.93
1990,5.65,5.65,4.94
1990,5.66,5.66,4.94
2000,5.66,5.66,4.95
2000,5.67,5.67,4.96
2000,5.67,5.67,4.97
2010,5.68,5.68,4.98
2010,5.68,5.68,4.99
2020,5.69,5.69,5.00
2020,5.69,5.69,5.00
2020,5.70,5.70,5.01
2030,5.70,5.70,5.02
2030,5.71,5.71,5.03
2030,5.71,5.71,5.04
2040,5.72,5.72,5.05
2040,5.72,5.72,5.06
2040,5.73,5.73,5.06
2050,5.73,5.73,5.07
2050,5.74,5.74,5.08
2050,5.74,5.74,5.09
2060,5.75,5.75,5.10
2060,5.75,5.75,5.11
2060,5.76,5.76,5.12
2070,5.76,5.76,5.12
2070,5.76,5.76,5.13
2070,5.77,5.77,5.14
2080,5.77,5.77,5.15
2080,5.78,5.78,5.16
2090,5.78,5.78,5.17
2090,5.79,5.79,5.18
2090,5.79,5.79,5.19
2100,5.80,5.80,5.20
2100,5.80,5.80,5.21
2100,5.81,5.81,5.22
2110,5.81,5.81,5.23
2110,5.82,5.82,5.24
2120,5.82,5.82,5.25
2120,5.83,5.83,5.26
2120,5.83,5.83,5.27
2130,5.84,5.84,5.28
2130,5.84,5.84,5.28
2140,5.85,5.85,5.29
2140,5.85,5.85,5.30
2140,5.86,5.86,5.31
2150,5.86,5.86,5.32
2150,5.87,5.87,5.33
2150,5.87,5.87,5.34
2160,5.88,5.88,5.35
2160,5.88,5.88,5.36
2170,5.88,5.88,5.37
2170,5.89,5.89,5.38
2170,5.89,5.89,5.39
2180,5.90,5.90,5.40
2180,5.90,5.90,5.41
2190,5.91,5.91,5.42
2190,5.91,5.91,5.43
2190,5.92,5.92,5.44
2200,5.92,5.92,5.45
2200,5.93,5.93,5.46
2210,5.93,5.93,5.47
2210,5.94,5.94,5.48
2210,5.94,5.94,5.49
2220,5.95,5.95,5.50
2220,5.95,5.95,5.51
2230,5.96,5.96,5.52
2230,5.96,5.96,5.53
2230,5.97,5.97,5.54
2240,5.97,5.97,5.55
2240,5.98,5.98,5.56
2250,5.98,5.98,5.57
2250,5.99,5.99,5.58
2260,5.99,5.99,5.59
2260,6.00,6.00,5.60
2260,6.00,6.00,5.61